Workbook

Sheet Inicio
A1: Organizador del Hogar y Tareas
A2: Dejá de llevar toda la casa en la cabeza. Cada tarea que se repite, quién la hace y cuándo toca de nuevo, calculado solo. Funciona en Excel y Google Sheets.
A4: EMPEZÁ ACÁ (3 MINUTOS)
A5: 1. Ajustes: escribí el día en que empezás y los nombres de quienes viven en la casa (hasta 6). Podés editar la lista de ambientes.
A6: 2. Tareas: ya vienen cargadas unas 80 tareas comunes, agrupadas por ambiente, con su frecuencia (cada N días, semanas, meses o años) y los minutos que lleva cada una. Cambialas, borralas o agregá las tuyas. Las de mascotas vienen en No; pasalas a Sí si corresponde.
A7: 3. Elegí quién hace cada tarea en la columna Quién (opcional). Las tareas que nunca registraste se reparten a propósito a lo largo de su primer ciclo, para que el primer día no sea una montaña.
A8: 4. Hoy: tu lista de pendientes, ordenada por urgencia: atrasadas, hoy y próximos 7 días. Elegí una persona arriba para ver solo sus tareas.
A9: 5. Cuando terminás una tarea, anotá la fecha en la columna 'Última vez' de Tareas (Ctrl + ; inserta la de hoy). La próxima fecha se corre sola. El vínculo 'Marcar hecha' de Hoy te lleva a la celda correcta.
A11: IMPRIMILA
A12: Semana es una lista lista para imprimir con los próximos 7 días, una columna por día, casilleros para tildar, cantidad de tareas y minutos de trabajo por día. Está pensada para una hoja A4 / Carta horizontal.
A14: REPARTAN LA CARGA
A15: Hogar: minutos de trabajo por semana de cada persona, porcentaje del total, quién está por encima o por debajo de un reparto parejo, tareas atrasadas por persona y por ambiente, y quién tiene hoy la carga más liviana. Sirve para hablar con calma y con datos, sin pelear.
... A24: Herramienta de organización del hogar. No guarda nada fuera de tu archivo ni envía datos a ningún lado. Solo para uso personal; no se permite su reventa ni redistribución.

Sheet Hoy
A1: Hoy
A2: Lo que hay que hacer ahora, lo más urgente primero.
A3: Mostrar tareas de: | B3: Todos
B5: Atrasadas | C5: =SUMPRODUCT(('Tareas'!$L$6:$L$155="Atrasada")*((('Tareas'!$F$6:$F$155=$B$3)+($B$3='Ajustes'!$D$5))>0))
B6: Para hoy | C6: =SUMPRODUCT(('Tareas'!$L$6:$L$155="Hoy")*((('Tareas'!$F$6:$F$155=$B$3)+($B$3='Ajustes'!$D$5))>0))
B7: Próximas (7 días) | C7: =SUMPRODUCT(('Tareas'!$L$6:$L$155="Esta semana")*((('Tareas'!$F$6:$F$155=$B$3)+($B$3='Ajustes'!$D$5))>0))
B8: Minutos de trabajo hoy (atrasadas + hoy) | C8: =SUMPRODUCT((('Tareas'!$L$6:$L$155="Atrasada")+('Tareas'!$L$6:$L$155="Hoy"))*((('Tareas'!$F$6:$F$155=$B$3)+($B$3='Ajustes'!$D$5))>0)*'Tareas'!$E$6:$E$155)
B9: =IF(COUNT('Tareas'!$M$6:$M$155)=0,"Todo al día. Nada atrasado y nada para los próximos 7 días.","")
A10: Estado | B10: Tarea | C10: Ambiente | D10: Quién | E10: Min | F10: Vence | G10: Atraso / faltan | H10: Marcar hecha
A11: =IF($J11="","",INDEX('Tareas'!$L$6:$L$155,$J11)) | B11: =IF($J11="","",INDEX('Tareas'!$A$6:$A$155,$J11)) | C11: =IF($J11="","",INDEX('Tareas'!$B$6:$B$155,$J11)) | D11: =IF($J11="","",INDEX('Tareas'!$F$6:$F$155,$J11)&"") | E11: =IF($J11="","",INDEX('Tareas'!$E$6:$E$155,$J11)) | F11: =IF($J11="","",INDEX('Tareas'!$J$6:$J$155,$J11)) | G11: =IF($J11="","",IF(INDEX('Tareas'!$K$6:$K$155,$J11)<0,-INDEX('Tareas'!$K$6:$K$155,$J11)&" d de atraso",IF(INDEX('Tareas'!$K$6:$K$155,$J11)=0,"–",INDEX('Tareas'!$K$6:$K$155,$J11)&" d"))) | H11: =IF($J11="","",HYPERLINK("#'Tareas'!G"&($J11+5),"Marcar hecha ›")) | J11: =IFERROR(MATCH(SMALL('Tareas'!$M$6:$M$155,1),'Tareas'!$M$6:$M$155,0),"")
A12: =IF($J12="","",INDEX('Tareas'!$L$6:$L$155,$J12)) | B12: =IF($J12="","",INDEX('Tareas'!$A$6:$A$155,$J12)) | C12: =IF($J12="","",INDEX('Tareas'!$B$6:$B$155,$J12)) | D12: =IF($J12="","",INDEX('Tareas'!$F$6:$F$155,$J12)&"") | E12: =IF($J12="","",INDEX('Tareas'!$E$6:$E$155,$J12)) | F12: =IF($J12="","",INDEX('Tareas'!$J$6:$J$155,$J12)) | G12: =IF($J12="","",IF(INDEX('Tareas'!$K$6:$K$155,$J12)<0,-INDEX('Tareas'!$K$6:$K$155,$J12)&" d de atraso",IF(INDEX('Tareas'!$K$6:$K$155,$J12)=0,"–",INDEX('Tareas'!$K$6:$K$155,$J12)&" d"))) | H12: =IF($J12="","",HYPERLINK("#'Tareas'!G"&($J12+5),"Marcar hecha ›")) | J12: =IFERROR(MATCH(SMALL('Tareas'!$M$6:$M$155,2),'Tareas'!$M$6:$M$155,0),"")
A13: =IF($J13="","",INDEX('Tareas'!$L$6:$L$155,$J13)) | B13: =IF($J13="","",INDEX('Tareas'!$A$6:$A$155,$J13)) | C13: =IF($J13="","",INDEX('Tareas'!$B$6:$B$155,$J13)) | D13: =IF($J13="","",INDEX('Tareas'!$F$6:$F$155,$J13)&"") | E13: =IF($J13="","",INDEX('Tareas'!$E$6:$E$155,$J13)) | F13: =IF($J13="","",INDEX('Tareas'!$J$6:$J$155,$J13)) | G13: =IF($J13="","",IF(INDEX('Tareas'!$K$6:$K$155,$J13)<0,-INDEX('Tareas'!$K$6:$K$155,$J13)&" d de atraso",IF(INDEX('Tareas'!$K$6:$K$155,$J13)=0,"–",INDEX('Tareas'!$K$6:$K$155,$J13)&" d"))) | H13: =IF($J13="","",HYPERLINK("#'Tareas'!G"&($J13+5),"Marcar hecha ›")) | J13: =IFERROR(MATCH(SMALL('Tareas'!$M$6:$M$155,3),'Tareas'!$M$6:$M$155,0),"")
A14: =IF($J14="","",INDEX('Tareas'!$L$6:$L$155,$J14)) | B14: =IF($J14="","",INDEX('Tareas'!$A$6:$A$155,$J14)) | C14: =IF($J14="","",INDEX('Tareas'!$B$6:$B$155,$J14)) | D14: =IF($J14="","",INDEX('Tareas'!$F$6:$F$155,$J14)&"") | E14: =IF($J14="","",INDEX('Tareas'!$E$6:$E$155,$J14)) | F14: =IF($J14="","",INDEX('Tareas'!$J$6:$J$155,$J14)) | G14: =IF($J14="","",IF(INDEX('Tareas'!$K$6:$K$155,$J14)<0,-INDEX('Tareas'!$K$6:$K$155,$J14)&" d de atraso",IF(INDEX('Tareas'!$K$6:$K$155,$J14)=0,"–",INDEX('Tareas'!$K$6:$K$155,$J14)&" d"))) | H14: =IF($J14="","",HYPERLINK("#'Tareas'!G"&($J14+5),"Marcar hecha ›")) | J14: =IFERROR(MATCH(SMALL('Tareas'!$M$6:$M$155,4),'Tareas'!$M$6:$M$155,0),"")
A15: =IF($J15="","",INDEX('Tareas'!$L$6:$L$155,$J15)) | B15: =IF($J15="","",INDEX('Tareas'!$A$6:$A$155,$J15)) | C15: =IF($J15="","",INDEX('Tareas'!$B$6:$B$155,$J15)) | D15: =IF($J15="","",INDEX('Tareas'!$F$6:$F$155,$J15)&"") | E15: =IF($J15="","",INDEX('Tareas'!$E$6:$E$155,$J15)) | F15: =IF($J15="","",INDEX('Tareas'!$J$6:$J$155,$J15)) | G15: =IF($J15="","",IF(INDEX('Tareas'!$K$6:$K$155,$J15)<0,-INDEX('Tareas'!$K$6:$K$155,$J15)&" d de atraso",IF(INDEX('Tareas'!$K$6:$K$155,$J15)=0,"–",INDEX('Tareas'!$K$6:$K$155,$J15)&" d"))) | H15: =IF($J15="","",HYPERLINK("#'Tareas'!G"&($J15+5),"Marcar hecha ›")) | J15: =IFERROR(MATCH(SMALL('Tareas'!$M$6:$M$155,5),'Tareas'!$M$6:$M$155,0),"")
A16: =IF($J16="","",INDEX('Tareas'!$L$6:$L$155,$J16)) | B16: =IF($J16="","",INDEX('Tareas'!$A$6:$A$155,$J16)) | C16: =IF($J16="","",INDEX('Tareas'!$B$6:$B$155,$J16)) | D16: =IF($J16="","",INDEX('Tareas'!$F$6:$F$155,$J16)&"") | E16: =IF($J16="","",INDEX('Tareas'!$E$6:$E$155,$J16)) | F16: =IF($J16="","",INDEX('Tareas'!$J$6:$J$155,$J16)) | G16: =IF($J16="","",IF(INDEX('Tareas'!$K$6:$K$155,$J16)<0,-INDEX('Tareas'!$K$6:$K$155,$J16)&" d de atraso",IF(INDEX('Tareas'!$K$6:$K$155,$J16)=0,"–",INDEX('Tareas'!$K$6:$K$155,$J16)&" d"))) | H16: =IF($J16="","",HYPERLINK("#'Tareas'!G"&($J16+5),"Marcar hecha ›")) | J16: =IFERROR(MATCH(SMALL('Tareas'!$M$6:$M$155,6),'Tareas'!$M$6:$M$155,0),"")
A17: =IF($J17="","",INDEX('Tareas'!$L$6:$L$155,$J17)) | B17: =IF($J17="","",INDEX('Tareas'!$A$6:$A$155,$J17)) | C17: =IF($J17="","",INDEX('Tareas'!$B$6:$B$155,$J17)) | D17: =IF($J17="","",INDEX('Tareas'!$F$6:$F$155,$J17)&"") | E17: =IF($J17="","",INDEX('Tareas'!$E$6:$E$155,$J17)) | F17: =IF($J17="","",INDEX('Tareas'!$J$6:$J$155,$J17)) | G17: =IF($J17="","",IF(INDEX('Tareas'!$K$6:$K$155,$J17)<0,-INDEX('Tareas'!$K$6:$K$155,$J17)&" d de atraso",IF(INDEX('Tareas'!$K$6:$K$155,$J17)=0,"–",INDEX('Tareas'!$K$6:$K$155,$J17)&" d"))) | H17: =IF($J17="","",HYPERLINK("#'Tareas'!G"&($J17+5),"Marcar hecha ›")) | J17: =IFERROR(MATCH(SMALL('Tareas'!$M$6:$M$155,7),'Tareas'!$M$6:$M$155,0),"")
A18: =IF($J18="","",INDEX('Tareas'!$L$6:$L$155,$J18)) | B18: =IF($J18="","",INDEX('Tareas'!$A$6:$A$155,$J18)) | C18: =IF($J18="","",INDEX('Tareas'!$B$6:$B$155,$J18)) | D18: =IF($J18="","",INDEX('Tareas'!$F$6:$F$155,$J18)&"") | E18: =IF($J18="","",INDEX('Tareas'!$E$6:$E$155,$J18)) | F18: =IF($J18="","",INDEX('Tareas'!$J$6:$J$155,$J18)) | G18: =IF($J18="","",IF(INDEX('Tareas'!$K$6:$K$155,$J18)<0,-INDEX('Tareas'!$K$6:$K$155,$J18)&" d de atraso",IF(INDEX('Tareas'!$K$6:$K$155,$J18)=0,"–",INDEX('Tareas'!$K$6:$K$155,$J18)&" d"))) | H18: =IF($J18="","",HYPERLINK("#'Tareas'!G"&($J18+5),"Marcar hecha ›")) | J18: =IFERROR(MATCH(SMALL('Tareas'!$M$6:$M$155,8),'Tareas'!$M$6:$M$155,0),"")
A19: =IF($J19="","",INDEX('Tareas'!$L$6:$L$155,$J19)) | B19: =IF($J19="","",INDEX('Tareas'!$A$6:$A$155,$J19)) | C19: =IF($J19="","",INDEX('Tareas'!$B$6:$B$155,$J19)) | D19: =IF($J19="","",INDEX('Tareas'!$F$6:$F$155,$J19)&"") | E19: =IF($J19="","",INDEX('Tareas'!$E$6:$E$155,$J19)) | F19: =IF($J19="","",INDEX('Tareas'!$J$6:$J$155,$J19)) | G19: =IF($J19="","",IF(INDEX('Tareas'!$K$6:$K$155,$J19)<0,-INDEX('Tareas'!$K$6:$K$155,$J19)&" d de atraso",IF(INDEX('Tareas'!$K$6:$K$155,$J19)=0,"–",INDEX('Tareas'!$K$6:$K$155,$J19)&" d"))) | H19: =IF($J19="","",HYPERLINK("#'Tareas'!G"&($J19+5),"Marcar hecha ›")) | J19: =IFERROR(MATCH(SMALL('Tareas'!$M$6:$M$155,9),'Tareas'!$M$6:$M$155,0),"")
A20: =IF($J20="","",INDEX('Tareas'!$L$6:$L$155,$J20)) | B20: =IF($J20="","",INDEX('Tareas'!$A$6:$A$155,$J20)) | C20: =IF($J20="","",INDEX('Tareas'!$B$6:$B$155,$J20)) | D20: =IF($J20="","",INDEX('Tareas'!$F$6:$F$155,$J20)&"") | E20: =IF($J20="","",INDEX('Tareas'!$E$6:$E$155,$J20)) | F20: =IF($J20="","",INDEX('Tareas'!$J$6:$J$155,$J20)) | G20: =IF($J20="","",IF(INDEX('Tareas'!$K$6:$K$155,$J20)<0,-INDEX('Tareas'!$K$6:$K$155,$J20)&" d de atraso",IF(INDEX('Tareas'!$K$6:$K$155,$J20)=0,"–",INDEX('Tareas'!$K$6:$K$155,$J20)&" d"))) | H20: =IF($J20="","",HYPERLINK("#'Tareas'!G"&($J20+5),"Marcar hecha ›")) | J20: =IFERROR(MATCH(SMALL('Tareas'!$M$6:$M$155,10),'Tareas'!$M$6:$M$155,0),"")
A21: =IF($J21="","",INDEX('Tareas'!$L$6:$L$155,$J21)) | B21: =IF($J21="","",INDEX('Tareas'!$A$6:$A$155,$J21)) | C21: =IF($J21="","",INDEX('Tareas'!$B$6:$B$155,$J21)) | D21: =IF($J21="","",INDEX('Tareas'!$F$6:$F$155,$J21)&"") | E21: =IF($J21="","",INDEX('Tareas'!$E$6:$E$155,$J21)) | F21: =IF($J21="","",INDEX('Tareas'!$J$6:$J$155,$J21)) | G21: =IF($J21="","",IF(INDEX('Tareas'!$K$6:$K$155,$J21)<0,-INDEX('Tareas'!$K$6:$K$155,$J21)&" d de atraso",IF(INDEX('Tareas'!$K$6:$K$155,$J21)=0,"–",INDEX('Tareas'!$K$6:$K$155,$J21)&" d"))) | H21: =IF($J21="","",HYPERLINK("#'Tareas'!G"&($J21+5),"Marcar hecha ›")) | J21: =IFERROR(MATCH(SMALL('Tareas'!$M$6:$M$155,11),'Tareas'!$M$6:$M$155,0),"")
A22: =IF($J22="","",INDEX('Tareas'!$L$6:$L$155,$J22)) | B22: =IF($J22="","",INDEX('Tareas'!$A$6:$A$155,$J22)) | C22: =IF($J22="","",INDEX('Tareas'!$B$6:$B$155,$J22)) | D22: =IF($J22="","",INDEX('Tareas'!$F$6:$F$155,$J22)&"") | E22: =IF($J22="","",INDEX('Tareas'!$E$6:$E$155,$J22)) | F22: =IF($J22="","",INDEX('Tareas'!$J$6:$J$155,$J22)) | G22: =IF($J22="","",IF(INDEX('Tareas'!$K$6:$K$155,$J22)<0,-INDEX('Tareas'!$K$6:$K$155,$J22)&" d de atraso",IF(INDEX('Tareas'!$K$6:$K$155,$J22)=0,"–",INDEX('Tareas'!$K$6:$K$155,$J22)&" d"))) | H22: =IF($J22="","",HYPERLINK("#'Tareas'!G"&($J22+5),"Marcar hecha ›")) | J22: =IFERROR(MATCH(SMALL('Tareas'!$M$6:$M$155,12),'Tareas'!$M$6:$M$155,0),"")
A23: =IF($J23="","",INDEX('Tareas'!$L$6:$L$155,$J23)) | B23: =IF($J23="","",INDEX('Tareas'!$A$6:$A$155,$J23)) | C23: =IF($J23="","",INDEX('Tareas'!$B$6:$B$155,$J23)) | D23: =IF($J23="","",INDEX('Tareas'!$F$6:$F$155,$J23)&"") | E23: =IF($J23="","",INDEX('Tareas'!$E$6:$E$155,$J23)) | F23: =IF($J23="","",INDEX('Tareas'!$J$6:$J$155,$J23)) | G23: =IF($J23="","",IF(INDEX('Tareas'!$K$6:$K$155,$J23)<0,-INDEX('Tareas'!$K$6:$K$155,$J23)&" d de atraso",IF(INDEX('Tareas'!$K$6:$K$155,$J23)=0,"–",INDEX('Tareas'!$K$6:$K$155,$J23)&" d"))) | H23: =IF($J23="","",HYPERLINK("#'Tareas'!G"&($J23+5),"Marcar hecha ›")) | J23: =IFERROR(MATCH(SMALL('Tareas'!$M$6:$M$155,13),'Tareas'!$M$6:$M$155,0),"")
A24: =IF($J24="","",INDEX('Tareas'!$L$6:$L$155,$J24)) | B24: =IF($J24="","",INDEX('Tareas'!$A$6:$A$155,$J24)) | C24: =IF($J24="","",INDEX('Tareas'!$B$6:$B$155,$J24)) | D24: =IF($J24="","",INDEX('Tareas'!$F$6:$F$155,$J24)&"") | E24: =IF($J24="","",INDEX('Tareas'!$E$6:$E$155,$J24)) | F24: =IF($J24="","",INDEX('Tareas'!$J$6:$J$155,$J24)) | G24: =IF($J24="","",IF(INDEX('Tareas'!$K$6:$K$155,$J24)<0,-INDEX('Tareas'!$K$6:$K$155,$J24)&" d de atraso",IF(INDEX('Tareas'!$K$6:$K$155,$J24)=0,"–",INDEX('Tareas'!$K$6:$K$155,$J24)&" d"))) | H24: =IF($J24="","",HYPERLINK("#'Tareas'!G"&($J24+5),"Marcar hecha ›")) | J24: =IFERROR(MATCH(SMALL('Tareas'!$M$6:$M$155,14),'Tareas'!$M$6:$M$155,0),"")
A25: =IF($J25="","",INDEX('Tareas'!$L$6:$L$155,$J25)) | B25: =IF($J25="","",INDEX('Tareas'!$A$6:$A$155,$J25)) | C25: =IF($J25="","",INDEX('Tareas'!$B$6:$B$155,$J25)) | D25: =IF($J25="","",INDEX('Tareas'!$F$6:$F$155,$J25)&"") | E25: =IF($J25="","",INDEX('Tareas'!$E$6:$E$155,$J25)) | F25: =IF($J25="","",INDEX('Tareas'!$J$6:$J$155,$J25)) | G25: =IF($J25="","",IF(INDEX('Tareas'!$K$6:$K$155,$J25)<0,-INDEX('Tareas'!$K$6:$K$155,$J25)&" d de atraso",IF(INDEX('Tareas'!$K$6:$K$155,$J25)=0,"–",INDEX('Tareas'!$K$6:$K$155,$J25)&" d"))) | H25: =IF($J25="","",HYPERLINK("#'Tareas'!G"&($J25+5),"Marcar hecha ›")) | J25: =IFERROR(MATCH(SMALL('Tareas'!$M$6:$M$155,15),'Tareas'!$M$6:$M$155,0),"")
A26: =IF($J26="","",INDEX('Tareas'!$L$6:$L$155,$J26)) | B26: =IF($J26="","",INDEX('Tareas'!$A$6:$A$155,$J26)) | C26: =IF($J26="","",INDEX('Tareas'!$B$6:$B$155,$J26)) | D26: =IF($J26="","",INDEX('Tareas'!$F$6:$F$155,$J26)&"") | E26: =IF($J26="","",INDEX('Tareas'!$E$6:$E$155,$J26)) | F26: =IF($J26="","",INDEX('Tareas'!$J$6:$J$155,$J26)) | G26: =IF($J26="","",IF(INDEX('Tareas'!$K$6:$K$155,$J26)<0,-INDEX('Tareas'!$K$6:$K$155,$J26)&" d de atraso",IF(INDEX('Tareas'!$K$6:$K$155,$J26)=0,"–",INDEX('Tareas'!$K$6:$K$155,$J26)&" d"))) | H26: =IF($J26="","",HYPERLINK("#'Tareas'!G"&($J26+5),"Marcar hecha ›")) | J26: =IFERROR(MATCH(SMALL('Tareas'!$M$6:$M$155,16),'Tareas'!$M$6:$M$155,0),"")
A27: =IF($J27="","",INDEX('Tareas'!$L$6:$L$155,$J27)) | B27: =IF($J27="","",INDEX('Tareas'!$A$6:$A$155,$J27)) | C27: =IF($J27="","",INDEX('Tareas'!$B$6:$B$155,$J27)) | D27: =IF($J27="","",INDEX('Tareas'!$F$6:$F$155,$J27)&"") | E27: =IF($J27="","",INDEX('Tareas'!$E$6:$E$155,$J27)) | F27: =IF($J27="","",INDEX('Tareas'!$J$6:$J$155,$J27)) | G27: =IF($J27="","",IF(INDEX('Tareas'!$K$6:$K$155,$J27)<0,-INDEX('Tareas'!$K$6:$K$155,$J27)&" d de atraso",IF(INDEX('Tareas'!$K$6:$K$155,$J27)=0,"–",INDEX('Tareas'!$K$6:$K$155,$J27)&" d"))) | H27: =IF($J27="","",HYPERLINK("#'Tareas'!G"&($J27+5),"Marcar hecha ›")) | J27: =IFERROR(MATCH(SMALL('Tareas'!$M$6:$M$155,17),'Tareas'!$M$6:$M$155,0),"")
A28: =IF($J28="","",INDEX('Tareas'!$L$6:$L$155,$J28)) | B28: =IF($J28="","",INDEX('Tareas'!$A$6:$A$155,$J28)) | C28: =IF($J28="","",INDEX('Tareas'!$B$6:$B$155,$J28)) | D28: =IF($J28="","",INDEX('Tareas'!$F$6:$F$155,$J28)&"") | E28: =IF($J28="","",INDEX('Tareas'!$E$6:$E$155,$J28)) | F28: =IF($J28="","",INDEX('Tareas'!$J$6:$J$155,$J28)) | G28: =IF($J28="","",IF(INDEX('Tareas'!$K$6:$K$155,$J28)<0,-INDEX('Tareas'!$K$6:$K$155,$J28)&" d de atraso",IF(INDEX('Tareas'!$K$6:$K$155,$J28)=0,"–",INDEX('Tareas'!$K$6:$K$155,$J28)&" d"))) | H28: =IF($J28="","",HYPERLINK("#'Tareas'!G"&($J28+5),"Marcar hecha ›")) | J28: =IFERROR(MATCH(SMALL('Tareas'!$M$6:$M$155,18),'Tareas'!$M$6:$M$155,0),"")
A29: =IF($J29="","",INDEX('Tareas'!$L$6:$L$155,$J29)) | B29: =IF($J29="","",INDEX('Tareas'!$A$6:$A$155,$J29)) | C29: =IF($J29="","",INDEX('Tareas'!$B$6:$B$155,$J29)) | D29: =IF($J29="","",INDEX('Tareas'!$F$6:$F$155,$J29)&"") | E29: =IF($J29="","",INDEX('Tareas'!$E$6:$E$155,$J29)) | F29: =IF($J29="","",INDEX('Tareas'!$J$6:$J$155,$J29)) | G29: =IF($J29="","",IF(INDEX('Tareas'!$K$6:$K$155,$J29)<0,-INDEX('Tareas'!$K$6:$K$155,$J29)&" d de atraso",IF(INDEX('Tareas'!$K$6:$K$155,$J29)=0,"–",INDEX('Tareas'!$K$6:$K$155,$J29)&" d"))) | H29: =IF($J29="","",HYPERLINK("#'Tareas'!G"&($J29+5),"Marcar hecha ›")) | J29: =IFERROR(MATCH(SMALL('Tareas'!$M$6:$M$155,19),'Tareas'!$M$6:$M$155,0),"")
A30: =IF($J30="","",INDEX('Tareas'!$L$6:$L$155,$J30)) | B30: =IF($J30="","",INDEX('Tareas'!$A$6:$A$155,$J30)) | C30: =IF($J30="","",INDEX('Tareas'!$B$6:$B$155,$J30)) | D30: =IF($J30="","",INDEX('Tareas'!$F$6:$F$155,$J30)&"") | E30: =IF($J30="","",INDEX('Tareas'!$E$6:$E$155,$J30)) | F30: =IF($J30="","",INDEX('Tareas'!$J$6:$J$155,$J30)) | G30: =IF($J30="","",IF(INDEX('Tareas'!$K$6:$K$155,$J30)<0,-INDEX('Tareas'!$K$6:$K$155,$J30)&" d de atraso",IF(INDEX('Tareas'!$K$6:$K$155,$J30)=0,"–",INDEX('Tareas'!$K$6:$K$155,$J30)&" d"))) | H30: =IF($J30="","",HYPERLINK("#'Tareas'!G"&($J30+5),"Marcar hecha ›")) | J30: =IFERROR(MATCH(SMALL('Tareas'!$M$6:$M$155,20),'Tareas'!$M$6:$M$155,0),"")
A31: =IF($J31="","",INDEX('Tareas'!$L$6:$L$155,$J31)) | B31: =IF($J31="","",INDEX('Tareas'!$A$6:$A$155,$J31)) | C31: =IF($J31="","",INDEX('Tareas'!$B$6:$B$155,$J31)) | D31: =IF($J31="","",INDEX('Tareas'!$F$6:$F$155,$J31)&"") | E31: =IF($J31="","",INDEX('Tareas'!$E$6:$E$155,$J31)) | F31: =IF($J31="","",INDEX('Tareas'!$J$6:$J$155,$J31)) | G31: =IF($J31="","",IF(INDEX('Tareas'!$K$6:$K$155,$J31)<0,-INDEX('Tareas'!$K$6:$K$155,$J31)&" d de atraso",IF(INDEX('Tareas'!$K$6:$K$155,$J31)=0,"–",INDEX('Tareas'!$K$6:$K$155,$J31)&" d"))) | H31: =IF($J31="","",HYPERLINK("#'Tareas'!G"&($J31+5),"Marcar hecha ›")) | J31: =IFERROR(MATCH(SMALL('Tareas'!$M$6:$M$155,21),'Tareas'!$M$6:$M$155,0),"")
A32: =IF($J32="","",INDEX('Tareas'!$L$6:$L$155,$J32)) | B32: =IF($J32="","",INDEX('Tareas'!$A$6:$A$155,$J32)) | C32: =IF($J32="","",INDEX('Tareas'!$B$6:$B$155,$J32)) | D32: =IF($J32="","",INDEX('Tareas'!$F$6:$F$155,$J32)&"") | E32: =IF($J32="","",INDEX('Tareas'!$E$6:$E$155,$J32)) | F32: =IF($J32="","",INDEX('Tareas'!$J$6:$J$155,$J32)) | G32: =IF($J32="","",IF(INDEX('Tareas'!$K$6:$K$155,$J32)<0,-INDEX('Tareas'!$K$6:$K$155,$J32)&" d de atraso",IF(INDEX('Tareas'!$K$6:$K$155,$J32)=0,"–",INDEX('Tareas'!$K$6:$K$155,$J32)&" d"))) | H32: =IF($J32="","",HYPERLINK("#'Tareas'!G"&($J32+5),"Marcar hecha ›")) | J32: =IFERROR(MATCH(SMALL('Tareas'!$M$6:$M$155,22),'Tareas'!$M$6:$M$155,0),"")
A33: =IF($J33="","",INDEX('Tareas'!$L$6:$L$155,$J33)) | B33: =IF($J33="","",INDEX('Tareas'!$A$6:$A$155,$J33)) | C33: =IF($J33="","",INDEX('Tareas'!$B$6:$B$155,$J33)) | D33: =IF($J33="","",INDEX('Tareas'!$F$6:$F$155,$J33)&"") | E33: =IF($J33="","",INDEX('Tareas'!$E$6:$E$155,$J33)) | F33: =IF($J33="","",INDEX('Tareas'!$J$6:$J$155,$J33)) | G33: =IF($J33="","",IF(INDEX('Tareas'!$K$6:$K$155,$J33)<0,-INDEX('Tareas'!$K$6:$K$155,$J33)&" d de atraso",IF(INDEX('Tareas'!$K$6:$K$155,$J33)=0,"–",INDEX('Tareas'!$K$6:$K$155,$J33)&" d"))) | H33: =IF($J33="","",HYPERLINK("#'Tareas'!G"&($J33+5),"Marcar hecha ›")) | J33: =IFERROR(MATCH(SMALL('Tareas'!$M$6:$M$155,23),'Tareas'!$M$6:$M$155,0),"")
A34: =IF($J34="","",INDEX('Tareas'!$L$6:$L$155,$J34)) | B34: =IF($J34="","",INDEX('Tareas'!$A$6:$A$155,$J34)) | C34: =IF($J34="","",INDEX('Tareas'!$B$6:$B$155,$J34)) | D34: =IF($J34="","",INDEX('Tareas'!$F$6:$F$155,$J34)&"") | E34: =IF($J34="","",INDEX('Tareas'!$E$6:$E$155,$J34)) | F34: =IF($J34="","",INDEX('Tareas'!$J$6:$J$155,$J34)) | G34: =IF($J34="","",IF(INDEX('Tareas'!$K$6:$K$155,$J34)<0,-INDEX('Tareas'!$K$6:$K$155,$J34)&" d de atraso",IF(INDEX('Tareas'!$K$6:$K$155,$J34)=0,"–",INDEX('Tareas'!$K$6:$K$155,$J34)&" d"))) | H34: =IF($J34="","",HYPERLINK("#'Tareas'!G"&($J34+5),"Marcar hecha ›")) | J34: =IFERROR(MATCH(SMALL('Tareas'!$M$6:$M$155,24),'Tareas'!$M$6:$M$155,0),"")
A35: =IF($J35="","",INDEX('Tareas'!$L$6:$L$155,$J35)) | B35: =IF($J35="","",INDEX('Tareas'!$A$6:$A$155,$J35)) | C35: =IF($J35="","",INDEX('Tareas'!$B$6:$B$155,$J35)) | D35: =IF($J35="","",INDEX('Tareas'!$F$6:$F$155,$J35)&"") | E35: =IF($J35="","",INDEX('Tareas'!$E$6:$E$155,$J35)) | F35: =IF($J35="","",INDEX('Tareas'!$J$6:$J$155,$J35)) | G35: =IF($J35="","",IF(INDEX('Tareas'!$K$6:$K$155,$J35)<0,-INDEX('Tareas'!$K$6:$K$155,$J35)&" d de atraso",IF(INDEX('Tareas'!$K$6:$K$155,$J35)=0,"–",INDEX('Tareas'!$K$6:$K$155,$J35)&" d"))) | H35: =IF($J35="","",HYPERLINK("#'Tareas'!G"&($J35+5),"Marcar hecha ›")) | J35: =IFERROR(MATCH(SMALL('Tareas'!$M$6:$M$155,25),'Tareas'!$M$6:$M$155,0),"")
A36: =IF($J36="","",INDEX('Tareas'!$L$6:$L$155,$J36)) | B36: =IF($J36="","",INDEX('Tareas'!$A$6:$A$155,$J36)) | C36: =IF($J36="","",INDEX('Tareas'!$B$6:$B$155,$J36)) | D36: =IF($J36="","",INDEX('Tareas'!$F$6:$F$155,$J36)&"") | E36: =IF($J36="","",INDEX('Tareas'!$E$6:$E$155,$J36)) | F36: =IF($J36="","",INDEX('Tareas'!$J$6:$J$155,$J36)) | G36: =IF($J36="","",IF(INDEX('Tareas'!$K$6:$K$155,$J36)<0,-INDEX('Tareas'!$K$6:$K$155,$J36)&" d de atraso",IF(INDEX('Tareas'!$K$6:$K$155,$J36)=0,"–",INDEX('Tareas'!$K$6:$K$155,$J36)&" d"))) | H36: =IF($J36="","",HYPERLINK("#'Tareas'!G"&($J36+5),"Marcar hecha ›")) | J36: =IFERROR(MATCH(SMALL('Tareas'!$M$6:$M$155,26),'Tareas'!$M$6:$M$155,0),"")
A37: =IF($J37="","",INDEX('Tareas'!$L$6:$L$155,$J37)) | B37: =IF($J37="","",INDEX('Tareas'!$A$6:$A$155,$J37)) | C37: =IF($J37="","",INDEX('Tareas'!$B$6:$B$155,$J37)) | D37: =IF($J37="","",INDEX('Tareas'!$F$6:$F$155,$J37)&"") | E37: =IF($J37="","",INDEX('Tareas'!$E$6:$E$155,$J37)) | F37: =IF($J37="","",INDEX('Tareas'!$J$6:$J$155,$J37)) | G37: =IF($J37="","",IF(INDEX('Tareas'!$K$6:$K$155,$J37)<0,-INDEX('Tareas'!$K$6:$K$155,$J37)&" d de atraso",IF(INDEX('Tareas'!$K$6:$K$155,$J37)=0,"–",INDEX('Tareas'!$K$6:$K$155,$J37)&" d"))) | H37: =IF($J37="","",HYPERLINK("#'Tareas'!G"&($J37+5),"Marcar hecha ›")) | J37: =IFERROR(MATCH(SMALL('Tareas'!$M$6:$M$155,27),'Tareas'!$M$6:$M$155,0),"")
A38: =IF($J38="","",INDEX('Tareas'!$L$6:$L$155,$J38)) | B38: =IF($J38="","",INDEX('Tareas'!$A$6:$A$155,$J38)) | C38: =IF($J38="","",INDEX('Tareas'!$B$6:$B$155,$J38)) | D38: =IF($J38="","",INDEX('Tareas'!$F$6:$F$155,$J38)&"") | E38: =IF($J38="","",INDEX('Tareas'!$E$6:$E$155,$J38)) | F38: =IF($J38="","",INDEX('Tareas'!$J$6:$J$155,$J38)) | G38: =IF($J38="","",IF(INDEX('Tareas'!$K$6:$K$155,$J38)<0,-INDEX('Tareas'!$K$6:$K$155,$J38)&" d de atraso",IF(INDEX('Tareas'!$K$6:$K$155,$J38)=0,"–",INDEX('Tareas'!$K$6:$K$155,$J38)&" d"))) | H38: =IF($J38="","",HYPERLINK("#'Tareas'!G"&($J38+5),"Marcar hecha ›")) | J38: =IFERROR(MATCH(SMALL('Tareas'!$M$6:$M$155,28),'Tareas'!$M$6:$M$155,0),"")
A39: =IF($J39="","",INDEX('Tareas'!$L$6:$L$155,$J39)) | B39: =IF($J39="","",INDEX('Tareas'!$A$6:$A$155,$J39)) | C39: =IF($J39="","",INDEX('Tareas'!$B$6:$B$155,$J39)) | D39: =IF($J39="","",INDEX('Tareas'!$F$6:$F$155,$J39)&"") | E39: =IF($J39="","",INDEX('Tareas'!$E$6:$E$155,$J39)) | F39: =IF($J39="","",INDEX('Tareas'!$J$6:$J$155,$J39)) | G39: =IF($J39="","",IF(INDEX('Tareas'!$K$6:$K$155,$J39)<0,-INDEX('Tareas'!$K$6:$K$155,$J39)&" d de atraso",IF(INDEX('Tareas'!$K$6:$K$155,$J39)=0,"–",INDEX('Tareas'!$K$6:$K$155,$J39)&" d"))) | H39: =IF($J39="","",HYPERLINK("#'Tareas'!G"&($J39+5),"Marcar hecha ›")) | J39: =IFERROR(MATCH(SMALL('Tareas'!$M$6:$M$155,29),'Tareas'!$M$6:$M$155,0),"")
A40: =IF($J40="","",INDEX('Tareas'!$L$6:$L$155,$J40)) | B40: =IF($J40="","",INDEX('Tareas'!$A$6:$A$155,$J40)) | C40: =IF($J40="","",INDEX('Tareas'!$B$6:$B$155,$J40)) | D40: =IF($J40="","",INDEX('Tareas'!$F$6:$F$155,$J40)&"") | E40: =IF($J40="","",INDEX('Tareas'!$E$6:$E$155,$J40)) | F40: =IF($J40="","",INDEX('Tareas'!$J$6:$J$155,$J40)) | G40: =IF($J40="","",IF(INDEX('Tareas'!$K$6:$K$155,$J40)<0,-INDEX('Tareas'!$K$6:$K$155,$J40)&" d de atraso",IF(INDEX('Tareas'!$K$6:$K$155,$J40)=0,"–",INDEX('Tareas'!$K$6:$K$155,$J40)&" d"))) | H40: =IF($J40="","",HYPERLINK("#'Tareas'!G"&($J40+5),"Marcar hecha ›")) | J40: =IFERROR(MATCH(SMALL('Tareas'!$M$6:$M$155,30),'Tareas'!$M$6:$M$155,0),"")
A41: =IF($J41="","",INDEX('Tareas'!$L$6:$L$155,$J41)) | B41: =IF($J41="","",INDEX('Tareas'!$A$6:$A$155,$J41)) | C41: =IF($J41="","",INDEX('Tareas'!$B$6:$B$155,$J41)) | D41: =IF($J41="","",INDEX('Tareas'!$F$6:$F$155,$J41)&"") | E41: =IF($J41="","",INDEX('Tareas'!$E$6:$E$155,$J41)) | F41: =IF($J41="","",INDEX('Tareas'!$J$6:$J$155,$J41)) | G41: =IF($J41="","",IF(INDEX('Tareas'!$K$6:$K$155,$J41)<0,-INDEX('Tareas'!$K$6:$K$155,$J41)&" d de atraso",IF(INDEX('Tareas'!$K$6:$K$155,$J41)=0,"–",INDEX('Tareas'!$K$6:$K$155,$J41)&" d"))) | H41: =IF($J41="","",HYPERLINK("#'Tareas'!G"&($J41+5),"Marcar hecha ›")) | J41: =IFERROR(MATCH(SMALL('Tareas'!$M$6:$M$155,31),'Tareas'!$M$6:$M$155,0),"")
...

Sheet Semana
A1: Próximos 7 días
A2: ="Para: "&'Hoy'!B3&" · Las atrasadas figuran en el día de hoy."
A4: =TODAY()+0 | B4: =TODAY()+1 | C4: =TODAY()+2 | D4: =TODAY()+3 | E4: =TODAY()+4 | F4: =TODAY()+5 | G4: =TODAY()+6
A5: =COUNT('Tareas'!$O$6:$O$155)&" tareas · "&SUMPRODUCT(ISNUMBER('Tareas'!$O$6:$O$155)*'Tareas'!$E$6:$E$155)&" min" | B5: =COUNT('Tareas'!$P$6:$P$155)&" tareas · "&SUMPRODUCT(ISNUMBER('Tareas'!$P$6:$P$155)*'Tareas'!$E$6:$E$155)&" min" | C5: =COUNT('Tareas'!$Q$6:$Q$155)&" tareas · "&SUMPRODUCT(ISNUMBER('Tareas'!$Q$6:$Q$155)*'Tareas'!$E$6:$E$155)&" min" | D5: =COUNT('Tareas'!$R$6:$R$155)&" tareas · "&SUMPRODUCT(ISNUMBER('Tareas'!$R$6:$R$155)*'Tareas'!$E$6:$E$155)&" min" | E5: =COUNT('Tareas'!$S$6:$S$155)&" tareas · "&SUMPRODUCT(ISNUMBER('Tareas'!$S$6:$S$155)*'Tareas'!$E$6:$E$155)&" min" | F5: =COUNT('Tareas'!$T$6:$T$155)&" tareas · "&SUMPRODUCT(ISNUMBER('Tareas'!$T$6:$T$155)*'Tareas'!$E$6:$E$155)&" min" | G5: =COUNT('Tareas'!$U$6:$U$155)&" tareas · "&SUMPRODUCT(ISNUMBER('Tareas'!$U$6:$U$155)*'Tareas'!$E$6:$E$155)&" min"
A6: =IFERROR("☐ "&INDEX('Tareas'!$A$6:$A$155,SMALL('Tareas'!$O$6:$O$155,1)-5)&IF(INDEX('Tareas'!$F$6:$F$155,SMALL('Tareas'!$O$6:$O$155,1)-5)="",""," ("&INDEX('Tareas'!$F$6:$F$155,SMALL('Tareas'!$O$6:$O$155,1)-5)&")"),"") | B6: =IFERROR("☐ "&INDEX('Tareas'!$A$6:$A$155,SMALL('Tareas'!$P$6:$P$155,1)-5)&IF(INDEX('Tareas'!$F$6:$F$155,SMALL('Tareas'!$P$6:$P$155,1)-5)="",""," ("&INDEX('Tareas'!$F$6:$F$155,SMALL('Tareas'!$P$6:$P$155,1)-5)&")"),"") | C6: =IFERROR("☐ "&INDEX('Tareas'!$A$6:$A$155,SMALL('Tareas'!$Q$6:$Q$155,1)-5)&IF(INDEX('Tareas'!$F$6:$F$155,SMALL('Tareas'!$Q$6:$Q$155,1)-5)="",""," ("&INDEX('Tareas'!$F$6:$F$155,SMALL('Tareas'!$Q$6:$Q$155,1)-5)&")"),"") | D6: =IFERROR("☐ "&INDEX('Tareas'!$A$6:$A$155,SMALL('Tareas'!$R$6:$R$155,1)-5)&IF(INDEX('Tareas'!$F$6:$F$155,SMALL('Tareas'!$R$6:$R$155,1)-5)="",""," ("&INDEX('Tareas'!$F$6:$F$155,SMALL('Tareas'!$R$6:$R$155,1)-5)&")"),"") | E6: =IFERROR("☐ "&INDEX('Tareas'!$A$6:$A$155,SMALL('Tareas'!$S$6:$S$155,1)-5)&IF(INDEX('Tareas'!$F$6:$F$155,SMALL('Tareas'!$S$6:$S$155,1)-5)="",""," ("&INDEX('Tareas'!$F$6:$F$155,SMALL('Tareas'!$S$6:$S$155,1)-5)&")"),"") | F6: =IFERROR("☐ "&INDEX('Tareas'!$A$6:$A$155,SMALL('Tareas'!$T$6:$T$155,1)-5)&IF(INDEX('Tareas'!$F$6:$F$155,SMALL('Tareas'!$T$6:$T$155,1)-5)="",""," ("&INDEX('Tareas'!$F$6:$F$155,SMALL('Tareas'!$T$6:$T$155,1)-5)&")"),"") | G6: =IFERROR("☐ "&INDEX('Tareas'!$A$6:$A$155,SMALL('Tareas'!$U$6:$U$155,1)-5)&IF(INDEX('Tareas'!$F$6:$F$155,SMALL('Tareas'!$U$6:$U$155,1)-5)="",""," ("&INDEX('Tareas'!$F$6:$F$155,SMALL('Tareas'!$U$6:$U$155,1)-5)&")"),"")
A7: =IFERROR("☐ "&INDEX('Tareas'!$A$6:$A$155,SMALL('Tareas'!$O$6:$O$155,2)-5)&IF(INDEX('Tareas'!$F$6:$F$155,SMALL('Tareas'!$O$6:$O$155,2)-5)="",""," ("&INDEX('Tareas'!$F$6:$F$155,SMALL('Tareas'!$O$6:$O$155,2)-5)&")"),"") | B7: =IFERROR("☐ "&INDEX('Tareas'!$A$6:$A$155,SMALL('Tareas'!$P$6:$P$155,2)-5)&IF(INDEX('Tareas'!$F$6:$F$155,SMALL('Tareas'!$P$6:$P$155,2)-5)="",""," ("&INDEX('Tareas'!$F$6:$F$155,SMALL('Tareas'!$P$6:$P$155,2)-5)&")"),"") | C7: =IFERROR("☐ "&INDEX('Tareas'!$A$6:$A$155,SMALL('Tareas'!$Q$6:$Q$155,2)-5)&IF(INDEX('Tareas'!$F$6:$F$155,SMALL('Tareas'!$Q$6:$Q$155,2)-5)="",""," ("&INDEX('Tareas'!$F$6:$F$155,SMALL('Tareas'!$Q$6:$Q$155,2)-5)&")"),"") | D7: =IFERROR("☐ "&INDEX('Tareas'!$A$6:$A$155,SMALL('Tareas'!$R$6:$R$155,2)-5)&IF(INDEX('Tareas'!$F$6:$F$155,SMALL('Tareas'!$R$6:$R$155,2)-5)="",""," ("&INDEX('Tareas'!$F$6:$F$155,SMALL('Tareas'!$R$6:$R$155,2)-5)&")"),"") | E7: =IFERROR("☐ "&INDEX('Tareas'!$A$6:$A$155,SMALL('Tareas'!$S$6:$S$155,2)-5)&IF(INDEX('Tareas'!$F$6:$F$155,SMALL('Tareas'!$S$6:$S$155,2)-5)="",""," ("&INDEX('Tareas'!$F$6:$F$155,SMALL('Tareas'!$S$6:$S$155,2)-5)&")"),"") | F7: =IFERROR("☐ "&INDEX('Tareas'!$A$6:$A$155,SMALL('Tareas'!$T$6:$T$155,2)-5)&IF(INDEX('Tareas'!$F$6:$F$155,SMALL('Tareas'!$T$6:$T$155,2)-5)="",""," ("&INDEX('Tareas'!$F$6:$F$155,SMALL('Tareas'!$T$6:$T$155,2)-5)&")"),"") | G7: =IFERROR("☐ "&INDEX('Tareas'!$A$6:$A$155,SMALL('Tareas'!$U$6:$U$155,2)-5)&IF(INDEX('Tareas'!$F$6:$F$155,SMALL('Tareas'!$U$6:$U$155,2)-5)="",""," ("&INDEX('Tareas'!$F$6:$F$155,SMALL('Tareas'!$U$6:$U$155,2)-5)&")"),"")
A8: =IFERROR("☐ "&INDEX('Tareas'!$A$6:$A$155,SMALL('Tareas'!$O$6:$O$155,3)-5)&IF(INDEX('Tareas'!$F$6:$F$155,SMALL('Tareas'!$O$6:$O$155,3)-5)="",""," ("&INDEX('Tareas'!$F$6:$F$155,SMALL('Tareas'!$O$6:$O$155,3)-5)&")"),"") | B8: =IFERROR("☐ "&INDEX('Tareas'!$A$6:$A$155,SMALL('Tareas'!$P$6:$P$155,3)-5)&IF(INDEX('Tareas'!$F$6:$F$155,SMALL('Tareas'!$P$6:$P$155,3)-5)="",""," ("&INDEX('Tareas'!$F$6:$F$155,SMALL('Tareas'!$P$6:$P$155,3)-5)&")"),"") | C8: =IFERROR("☐ "&INDEX('Tareas'!$A$6:$A$155,SMALL('Tareas'!$Q$6:$Q$155,3)-5)&IF(INDEX('Tareas'!$F$6:$F$155,SMALL('Tareas'!$Q$6:$Q$155,3)-5)="",""," ("&INDEX('Tareas'!$F$6:$F$155,SMALL('Tareas'!$Q$6:$Q$155,3)-5)&")"),"") | D8: =IFERROR("☐ "&INDEX('Tareas'!$A$6:$A$155,SMALL('Tareas'!$R$6:$R$155,3)-5)&IF(INDEX('Tareas'!$F$6:$F$155,SMALL('Tareas'!$R$6:$R$155,3)-5)="",""," ("&INDEX('Tareas'!$F$6:$F$155,SMALL('Tareas'!$R$6:$R$155,3)-5)&")"),"") | E8: =IFERROR("☐ "&INDEX('Tareas'!$A$6:$A$155,SMALL('Tareas'!$S$6:$S$155,3)-5)&IF(INDEX('Tareas'!$F$6:$F$155,SMALL('Tareas'!$S$6:$S$155,3)-5)="",""," ("&INDEX('Tareas'!$F$6:$F$155,SMALL('Tareas'!$S$6:$S$155,3)-5)&")"),"") | F8: =IFERROR("☐ "&INDEX('Tareas'!$A$6:$A$155,SMALL('Tareas'!$T$6:$T$155,3)-5)&IF(INDEX('Tareas'!$F$6:$F$155,SMALL('Tareas'!$T$6:$T$155,3)-5)="",""," ("&INDEX('Tareas'!$F$6:$F$155,SMALL('Tareas'!$T$6:$T$155,3)-5)&")"),"") | G8: =IFERROR("☐ "&INDEX('Tareas'!$A$6:$A$155,SMALL('Tareas'!$U$6:$U$155,3)-5)&IF(INDEX('Tareas'!$F$6:$F$155,SMALL('Tareas'!$U$6:$U$155,3)-5)="",""," ("&INDEX('Tareas'!$F$6:$F$155,SMALL('Tareas'!$U$6:$U$155,3)-5)&")"),"")
A9: =IFERROR("☐ "&INDEX('Tareas'!$A$6:$A$155,SMALL('Tareas'!$O$6:$O$155,4)-5)&IF(INDEX('Tareas'!$F$6:$F$155,SMALL('Tareas'!$O$6:$O$155,4)-5)="",""," ("&INDEX('Tareas'!$F$6:$F$155,SMALL('Tareas'!$O$6:$O$155,4)-5)&")"),"") | B9: =IFERROR("☐ "&INDEX('Tareas'!$A$6:$A$155,SMALL('Tareas'!$P$6:$P$155,4)-5)&IF(INDEX('Tareas'!$F$6:$F$155,SMALL('Tareas'!$P$6:$P$155,4)-5)="",""," ("&INDEX('Tareas'!$F$6:$F$155,SMALL('Tareas'!$P$6:$P$155,4)-5)&")"),"") | C9: =IFERROR("☐ "&INDEX('Tareas'!$A$6:$A$155,SMALL('Tareas'!$Q$6:$Q$155,4)-5)&IF(INDEX('Tareas'!$F$6:$F$155,SMALL('Tareas'!$Q$6:$Q$155,4)-5)="",""," ("&INDEX('Tareas'!$F$6:$F$155,SMALL('Tareas'!$Q$6:$Q$155,4)-5)&")"),"") | D9: =IFERROR("☐ "&INDEX('Tareas'!$A$6:$A$155,SMALL('Tareas'!$R$6:$R$155,4)-5)&IF(INDEX('Tareas'!$F$6:$F$155,SMALL('Tareas'!$R$6:$R$155,4)-5)="",""," ("&INDEX('Tareas'!$F$6:$F$155,SMALL('Tareas'!$R$6:$R$155,4)-5)&")"),"") | E9: =IFERROR("☐ "&INDEX('Tareas'!$A$6:$A$155,SMALL('Tareas'!$S$6:$S$155,4)-5)&IF(INDEX('Tareas'!$F$6:$F$155,SMALL('Tareas'!$S$6:$S$155,4)-5)="",""," ("&INDEX('Tareas'!$F$6:$F$155,SMALL('Tareas'!$S$6:$S$155,4)-5)&")"),"") | F9: =IFERROR("☐ "&INDEX('Tareas'!$A$6:$A$155,SMALL('Tareas'!$T$6:$T$155,4)-5)&IF(INDEX('Tareas'!$F$6:$F$155,SMALL('Tareas'!$T$6:$T$155,4)-5)="",""," ("&INDEX('Tareas'!$F$6:$F$155,SMALL('Tareas'!$T$6:$T$155,4)-5)&")"),"") | G9: =IFERROR("☐ "&INDEX('Tareas'!$A$6:$A$155,SMALL('Tareas'!$U$6:$U$155,4)-5)&IF(INDEX('Tareas'!$F$6:$F$155,SMALL('Tareas'!$U$6:$U$155,4)-5)="",""," ("&INDEX('Tareas'!$F$6:$F$155,SMALL('Tareas'!$U$6:$U$155,4)-5)&")"),"")
A10: =IFERROR("☐ "&INDEX('Tareas'!$A$6:$A$155,SMALL('Tareas'!$O$6:$O$155,5)-5)&IF(INDEX('Tareas'!$F$6:$F$155,SMALL('Tareas'!$O$6:$O$155,5)-5)="",""," ("&INDEX('Tareas'!$F$6:$F$155,SMALL('Tareas'!$O$6:$O$155,5)-5)&")"),"") | B10: =IFERROR("☐ "&INDEX('Tareas'!$A$6:$A$155,SMALL('Tareas'!$P$6:$P$155,5)-5)&IF(INDEX('Tareas'!$F$6:$F$155,SMALL('Tareas'!$P$6:$P$155,5)-5)="",""," ("&INDEX('Tareas'!$F$6:$F$155,SMALL('Tareas'!$P$6:$P$155,5)-5)&")"),"") | C10: =IFERROR("☐ "&INDEX('Tareas'!$A$6:$A$155,SMALL('Tareas'!$Q$6:$Q$155,5)-5)&IF(INDEX('Tareas'!$F$6:$F$155,SMALL('Tareas'!$Q$6:$Q$155,5)-5)="",""," ("&INDEX('Tareas'!$F$6:$F$155,SMALL('Tareas'!$Q$6:$Q$155,5)-5)&")"),"") | D10: =IFERROR("☐ "&INDEX('Tareas'!$A$6:$A$155,SMALL('Tareas'!$R$6:$R$155,5)-5)&IF(INDEX('Tareas'!$F$6:$F$155,SMALL('Tareas'!$R$6:$R$155,5)-5)="",""," ("&INDEX('Tareas'!$F$6:$F$155,SMALL('Tareas'!$R$6:$R$155,5)-5)&")"),"") | E10: =IFERROR("☐ "&INDEX('Tareas'!$A$6:$A$155,SMALL('Tareas'!$S$6:$S$155,5)-5)&IF(INDEX('Tareas'!$F$6:$F$155,SMALL('Tareas'!$S$6:$S$155,5)-5)="",""," ("&INDEX('Tareas'!$F$6:$F$155,SMALL('Tareas'!$S$6:$S$155,5)-5)&")"),"") | F10: =IFERROR("☐ "&INDEX('Tareas'!$A$6:$A$155,SMALL('Tareas'!$T$6:$T$155,5)-5)&IF(INDEX('Tareas'!$F$6:$F$155,SMALL('Tareas'!$T$6:$T$155,5)-5)="",""," ("&INDEX('Tareas'!$F$6:$F$155,SMALL('Tareas'!$T$6:$T$155,5)-5)&")"),"") | G10: =IFERROR("☐ "&INDEX('Tareas'!$A$6:$A$155,SMALL('Tareas'!$U$6:$U$155,5)-5)&IF(INDEX('Tareas'!$F$6:$F$155,SMALL('Tareas'!$U$6:$U$155,5)-5)="",""," ("&INDEX('Tareas'!$F$6:$F$155,SMALL('Tareas'!$U$6:$U$155,5)-5)&")"),"")
A11: =IFERROR("☐ "&INDEX('Tareas'!$A$6:$A$155,SMALL('Tareas'!$O$6:$O$155,6)-5)&IF(INDEX('Tareas'!$F$6:$F$155,SMALL('Tareas'!$O$6:$O$155,6)-5)="",""," ("&INDEX('Tareas'!$F$6:$F$155,SMALL('Tareas'!$O$6:$O$155,6)-5)&")"),"") | B11: =IFERROR("☐ "&INDEX('Tareas'!$A$6:$A$155,SMALL('Tareas'!$P$6:$P$155,6)-5)&IF(INDEX('Tareas'!$F$6:$F$155,SMALL('Tareas'!$P$6:$P$155,6)-5)="",""," ("&INDEX('Tareas'!$F$6:$F$155,SMALL('Tareas'!$P$6:$P$155,6)-5)&")"),"") | C11: =IFERROR("☐ "&INDEX('Tareas'!$A$6:$A$155,SMALL('Tareas'!$Q$6:$Q$155,6)-5)&IF(INDEX('Tareas'!$F$6:$F$155,SMALL('Tareas'!$Q$6:$Q$155,6)-5)="",""," ("&INDEX('Tareas'!$F$6:$F$155,SMALL('Tareas'!$Q$6:$Q$155,6)-5)&")"),"") | D11: =IFERROR("☐ "&INDEX('Tareas'!$A$6:$A$155,SMALL('Tareas'!$R$6:$R$155,6)-5)&IF(INDEX('Tareas'!$F$6:$F$155,SMALL('Tareas'!$R$6:$R$155,6)-5)="",""," ("&INDEX('Tareas'!$F$6:$F$155,SMALL('Tareas'!$R$6:$R$155,6)-5)&")"),"") | E11: =IFERROR("☐ "&INDEX('Tareas'!$A$6:$A$155,SMALL('Tareas'!$S$6:$S$155,6)-5)&IF(INDEX('Tareas'!$F$6:$F$155,SMALL('Tareas'!$S$6:$S$155,6)-5)="",""," ("&INDEX('Tareas'!$F$6:$F$155,SMALL('Tareas'!$S$6:$S$155,6)-5)&")"),"") | F11: =IFERROR("☐ "&INDEX('Tareas'!$A$6:$A$155,SMALL('Tareas'!$T$6:$T$155,6)-5)&IF(INDEX('Tareas'!$F$6:$F$155,SMALL('Tareas'!$T$6:$T$155,6)-5)="",""," ("&INDEX('Tareas'!$F$6:$F$155,SMALL('Tareas'!$T$6:$T$155,6)-5)&")"),"") | G11: =IFERROR("☐ "&INDEX('Tareas'!$A$6:$A$155,SMALL('Tareas'!$U$6:$U$155,6)-5)&IF(INDEX('Tareas'!$F$6:$F$155,SMALL('Tareas'!$U$6:$U$155,6)-5)="",""," ("&INDEX('Tareas'!$F$6:$F$155,SMALL('Tareas'!$U$6:$U$155,6)-5)&")"),"")
A12: =IFERROR("☐ "&INDEX('Tareas'!$A$6:$A$155,SMALL('Tareas'!$O$6:$O$155,7)-5)&IF(INDEX('Tareas'!$F$6:$F$155,SMALL('Tareas'!$O$6:$O$155,7)-5)="",""," ("&INDEX('Tareas'!$F$6:$F$155,SMALL('Tareas'!$O$6:$O$155,7)-5)&")"),"") | B12: =IFERROR("☐ "&INDEX('Tareas'!$A$6:$A$155,SMALL('Tareas'!$P$6:$P$155,7)-5)&IF(INDEX('Tareas'!$F$6:$F$155,SMALL('Tareas'!$P$6:$P$155,7)-5)="",""," ("&INDEX('Tareas'!$F$6:$F$155,SMALL('Tareas'!$P$6:$P$155,7)-5)&")"),"") | C12: =IFERROR("☐ "&INDEX('Tareas'!$A$6:$A$155,SMALL('Tareas'!$Q$6:$Q$155,7)-5)&IF(INDEX('Tareas'!$F$6:$F$155,SMALL('Tareas'!$Q$6:$Q$155,7)-5)="",""," ("&INDEX('Tareas'!$F$6:$F$155,SMALL('Tareas'!$Q$6:$Q$155,7)-5)&")"),"") | D12: =IFERROR("☐ "&INDEX('Tareas'!$A$6:$A$155,SMALL('Tareas'!$R$6:$R$155,7)-5)&IF(INDEX('Tareas'!$F$6:$F$155,SMALL('Tareas'!$R$6:$R$155,7)-5)="",""," ("&INDEX('Tareas'!$F$6:$F$155,SMALL('Tareas'!$R$6:$R$155,7)-5)&")"),"") | E12: =IFERROR("☐ "&INDEX('Tareas'!$A$6:$A$155,SMALL('Tareas'!$S$6:$S$155,7)-5)&IF(INDEX('Tareas'!$F$6:$F$155,SMALL('Tareas'!$S$6:$S$155,7)-5)="",""," ("&INDEX('Tareas'!$F$6:$F$155,SMALL('Tareas'!$S$6:$S$155,7)-5)&")"),"") | F12: =IFERROR("☐ "&INDEX('Tareas'!$A$6:$A$155,SMALL('Tareas'!$T$6:$T$155,7)-5)&IF(INDEX('Tareas'!$F$6:$F$155,SMALL('Tareas'!$T$6:$T$155,7)-5)="",""," ("&INDEX('Tareas'!$F$6:$F$155,SMALL('Tareas'!$T$6:$T$155,7)-5)&")"),"") | G12: =IFERROR("☐ "&INDEX('Tareas'!$A$6:$A$155,SMALL('Tareas'!$U$6:$U$155,7)-5)&IF(INDEX('Tareas'!$F$6:$F$155,SMALL('Tareas'!$U$6:$U$155,7)-5)="",""," ("&INDEX('Tareas'!$F$6:$F$155,SMALL('Tareas'!$U$6:$U$155,7)-5)&")"),"")
A13: =IFERROR("☐ "&INDEX('Tareas'!$A$6:$A$155,SMALL('Tareas'!$O$6:$O$155,8)-5)&IF(INDEX('Tareas'!$F$6:$F$155,SMALL('Tareas'!$O$6:$O$155,8)-5)="",""," ("&INDEX('Tareas'!$F$6:$F$155,SMALL('Tareas'!$O$6:$O$155,8)-5)&")"),"") | B13: =IFERROR("☐ "&INDEX('Tareas'!$A$6:$A$155,SMALL('Tareas'!$P$6:$P$155,8)-5)&IF(INDEX('Tareas'!$F$6:$F$155,SMALL('Tareas'!$P$6:$P$155,8)-5)="",""," ("&INDEX('Tareas'!$F$6:$F$155,SMALL('Tareas'!$P$6:$P$155,8)-5)&")"),"") | C13: =IFERROR("☐ "&INDEX('Tareas'!$A$6:$A$155,SMALL('Tareas'!$Q$6:$Q$155,8)-5)&IF(INDEX('Tareas'!$F$6:$F$155,SMALL('Tareas'!$Q$6:$Q$155,8)-5)="",""," ("&INDEX('Tareas'!$F$6:$F$155,SMALL('Tareas'!$Q$6:$Q$155,8)-5)&")"),"") | D13: =IFERROR("☐ "&INDEX('Tareas'!$A$6:$A$155,SMALL('Tareas'!$R$6:$R$155,8)-5)&IF(INDEX('Tareas'!$F$6:$F$155,SMALL('Tareas'!$R$6:$R$155,8)-5)="",""," ("&INDEX('Tareas'!$F$6:$F$155,SMALL('Tareas'!$R$6:$R$155,8)-5)&")"),"") | E13: =IFERROR("☐ "&INDEX('Tareas'!$A$6:$A$155,SMALL('Tareas'!$S$6:$S$155,8)-5)&IF(INDEX('Tareas'!$F$6:$F$155,SMALL('Tareas'!$S$6:$S$155,8)-5)="",""," ("&INDEX('Tareas'!$F$6:$F$155,SMALL('Tareas'!$S$6:$S$155,8)-5)&")"),"") | F13: =IFERROR("☐ "&INDEX('Tareas'!$A$6:$A$155,SMALL('Tareas'!$T$6:$T$155,8)-5)&IF(INDEX('Tareas'!$F$6:$F$155,SMALL('Tareas'!$T$6:$T$155,8)-5)="",""," ("&INDEX('Tareas'!$F$6:$F$155,SMALL('Tareas'!$T$6:$T$155,8)-5)&")"),"") | G13: =IFERROR("☐ "&INDEX('Tareas'!$A$6:$A$155,SMALL('Tareas'!$U$6:$U$155,8)-5)&IF(INDEX('Tareas'!$F$6:$F$155,SMALL('Tareas'!$U$6:$U$155,8)-5)="",""," ("&INDEX('Tareas'!$F$6:$F$155,SMALL('Tareas'!$U$6:$U$155,8)-5)&")"),"")
A14: =IFERROR("☐ "&INDEX('Tareas'!$A$6:$A$155,SMALL('Tareas'!$O$6:$O$155,9)-5)&IF(INDEX('Tareas'!$F$6:$F$155,SMALL('Tareas'!$O$6:$O$155,9)-5)="",""," ("&INDEX('Tareas'!$F$6:$F$155,SMALL('Tareas'!$O$6:$O$155,9)-5)&")"),"") | B14: =IFERROR("☐ "&INDEX('Tareas'!$A$6:$A$155,SMALL('Tareas'!$P$6:$P$155,9)-5)&IF(INDEX('Tareas'!$F$6:$F$155,SMALL('Tareas'!$P$6:$P$155,9)-5)="",""," ("&INDEX('Tareas'!$F$6:$F$155,SMALL('Tareas'!$P$6:$P$155,9)-5)&")"),"") | C14: =IFERROR("☐ "&INDEX('Tareas'!$A$6:$A$155,SMALL('Tareas'!$Q$6:$Q$155,9)-5)&IF(INDEX('Tareas'!$F$6:$F$155,SMALL('Tareas'!$Q$6:$Q$155,9)-5)="",""," ("&INDEX('Tareas'!$F$6:$F$155,SMALL('Tareas'!$Q$6:$Q$155,9)-5)&")"),"") | D14: =IFERROR("☐ "&INDEX('Tareas'!$A$6:$A$155,SMALL('Tareas'!$R$6:$R$155,9)-5)&IF(INDEX('Tareas'!$F$6:$F$155,SMALL('Tareas'!$R$6:$R$155,9)-5)="",""," ("&INDEX('Tareas'!$F$6:$F$155,SMALL('Tareas'!$R$6:$R$155,9)-5)&")"),"") | E14: =IFERROR("☐ "&INDEX('Tareas'!$A$6:$A$155,SMALL('Tareas'!$S$6:$S$155,9)-5)&IF(INDEX('Tareas'!$F$6:$F$155,SMALL('Tareas'!$S$6:$S$155,9)-5)="",""," ("&INDEX('Tareas'!$F$6:$F$155,SMALL('Tareas'!$S$6:$S$155,9)-5)&")"),"") | F14: =IFERROR("☐ "&INDEX('Tareas'!$A$6:$A$155,SMALL('Tareas'!$T$6:$T$155,9)-5)&IF(INDEX('Tareas'!$F$6:$F$155,SMALL('Tareas'!$T$6:$T$155,9)-5)="",""," ("&INDEX('Tareas'!$F$6:$F$155,SMALL('Tareas'!$T$6:$T$155,9)-5)&")"),"") | G14: =IFERROR("☐ "&INDEX('Tareas'!$A$6:$A$155,SMALL('Tareas'!$U$6:$U$155,9)-5)&IF(INDEX('Tareas'!$F$6:$F$155,SMALL('Tareas'!$U$6:$U$155,9)-5)="",""," ("&INDEX('Tareas'!$F$6:$F$155,SMALL('Tareas'!$U$6:$U$155,9)-5)&")"),"")
A15: =IFERROR("☐ "&INDEX('Tareas'!$A$6:$A$155,SMALL('Tareas'!$O$6:$O$155,10)-5)&IF(INDEX('Tareas'!$F$6:$F$155,SMALL('Tareas'!$O$6:$O$155,10)-5)="",""," ("&INDEX('Tareas'!$F$6:$F$155,SMALL('Tareas'!$O$6:$O$155,10)-5)&")"),"") | B15: =IFERROR("☐ "&INDEX('Tareas'!$A$6:$A$155,SMALL('Tareas'!$P$6:$P$155,10)-5)&IF(INDEX('Tareas'!$F$6:$F$155,SMALL('Tareas'!$P$6:$P$155,10)-5)="",""," ("&INDEX('Tareas'!$F$6:$F$155,SMALL('Tareas'!$P$6:$P$155,10)-5)&")"),"") | C15: =IFERROR("☐ "&INDEX('Tareas'!$A$6:$A$155,SMALL('Tareas'!$Q$6:$Q$155,10)-5)&IF(INDEX('Tareas'!$F$6:$F$155,SMALL('Tareas'!$Q$6:$Q$155,10)-5)="",""," ("&INDEX('Tareas'!$F$6:$F$155,SMALL('Tareas'!$Q$6:$Q$155,10)-5)&")"),"") | D15: =IFERROR("☐ "&INDEX('Tareas'!$A$6:$A$155,SMALL('Tareas'!$R$6:$R$155,10)-5)&IF(INDEX('Tareas'!$F$6:$F$155,SMALL('Tareas'!$R$6:$R$155,10)-5)="",""," ("&INDEX('Tareas'!$F$6:$F$155,SMALL('Tareas'!$R$6:$R$155,10)-5)&")"),"") | E15: =IFERROR("☐ "&INDEX('Tareas'!$A$6:$A$155,SMALL('Tareas'!$S$6:$S$155,10)-5)&IF(INDEX('Tareas'!$F$6:$F$155,SMALL('Tareas'!$S$6:$S$155,10)-5)="",""," ("&INDEX('Tareas'!$F$6:$F$155,SMALL('Tareas'!$S$6:$S$155,10)-5)&")"),"") | F15: =IFERROR("☐ "&INDEX('Tareas'!$A$6:$A$155,SMALL('Tareas'!$T$6:$T$155,10)-5)&IF(INDEX('Tareas'!$F$6:$F$155,SMALL('Tareas'!$T$6:$T$155,10)-5)="",""," ("&INDEX('Tareas'!$F$6:$F$155,SMALL('Tareas'!$T$6:$T$155,10)-5)&")"),"") | G15: =IFERROR("☐ "&INDEX('Tareas'!$A$6:$A$155,SMALL('Tareas'!$U$6:$U$155,10)-5)&IF(INDEX('Tareas'!$F$6:$F$155,SMALL('Tareas'!$U$6:$U$155,10)-5)="",""," ("&INDEX('Tareas'!$F$6:$F$155,SMALL('Tareas'!$U$6:$U$155,10)-5)&")"),"")
A16: =IFERROR("☐ "&INDEX('Tareas'!$A$6:$A$155,SMALL('Tareas'!$O$6:$O$155,11)-5)&IF(INDEX('Tareas'!$F$6:$F$155,SMALL('Tareas'!$O$6:$O$155,11)-5)="",""," ("&INDEX('Tareas'!$F$6:$F$155,SMALL('Tareas'!$O$6:$O$155,11)-5)&")"),"") | B16: =IFERROR("☐ "&INDEX('Tareas'!$A$6:$A$155,SMALL('Tareas'!$P$6:$P$155,11)-5)&IF(INDEX('Tareas'!$F$6:$F$155,SMALL('Tareas'!$P$6:$P$155,11)-5)="",""," ("&INDEX('Tareas'!$F$6:$F$155,SMALL('Tareas'!$P$6:$P$155,11)-5)&")"),"") | C16: =IFERROR("☐ "&INDEX('Tareas'!$A$6:$A$155,SMALL('Tareas'!$Q$6:$Q$155,11)-5)&IF(INDEX('Tareas'!$F$6:$F$155,SMALL('Tareas'!$Q$6:$Q$155,11)-5)="",""," ("&INDEX('Tareas'!$F$6:$F$155,SMALL('Tareas'!$Q$6:$Q$155,11)-5)&")"),"") | D16: =IFERROR("☐ "&INDEX('Tareas'!$A$6:$A$155,SMALL('Tareas'!$R$6:$R$155,11)-5)&IF(INDEX('Tareas'!$F$6:$F$155,SMALL('Tareas'!$R$6:$R$155,11)-5)="",""," ("&INDEX('Tareas'!$F$6:$F$155,SMALL('Tareas'!$R$6:$R$155,11)-5)&")"),"") | E16: =IFERROR("☐ "&INDEX('Tareas'!$A$6:$A$155,SMALL('Tareas'!$S$6:$S$155,11)-5)&IF(INDEX('Tareas'!$F$6:$F$155,SMALL('Tareas'!$S$6:$S$155,11)-5)="",""," ("&INDEX('Tareas'!$F$6:$F$155,SMALL('Tareas'!$S$6:$S$155,11)-5)&")"),"") | F16: =IFERROR("☐ "&INDEX('Tareas'!$A$6:$A$155,SMALL('Tareas'!$T$6:$T$155,11)-5)&IF(INDEX('Tareas'!$F$6:$F$155,SMALL('Tareas'!$T$6:$T$155,11)-5)="",""," ("&INDEX('Tareas'!$F$6:$F$155,SMALL('Tareas'!$T$6:$T$155,11)-5)&")"),"") | G16: =IFERROR("☐ "&INDEX('Tareas'!$A$6:$A$155,SMALL('Tareas'!$U$6:$U$155,11)-5)&IF(INDEX('Tareas'!$F$6:$F$155,SMALL('Tareas'!$U$6:$U$155,11)-5)="",""," ("&INDEX('Tareas'!$F$6:$F$155,SMALL('Tareas'!$U$6:$U$155,11)-5)&")"),"")
A17: =IFERROR("☐ "&INDEX('Tareas'!$A$6:$A$155,SMALL('Tareas'!$O$6:$O$155,12)-5)&IF(INDEX('Tareas'!$F$6:$F$155,SMALL('Tareas'!$O$6:$O$155,12)-5)="",""," ("&INDEX('Tareas'!$F$6:$F$155,SMALL('Tareas'!$O$6:$O$155,12)-5)&")"),"") | B17: =IFERROR("☐ "&INDEX('Tareas'!$A$6:$A$155,SMALL('Tareas'!$P$6:$P$155,12)-5)&IF(INDEX('Tareas'!$F$6:$F$155,SMALL('Tareas'!$P$6:$P$155,12)-5)="",""," ("&INDEX('Tareas'!$F$6:$F$155,SMALL('Tareas'!$P$6:$P$155,12)-5)&")"),"") | C17: =IFERROR("☐ "&INDEX('Tareas'!$A$6:$A$155,SMALL('Tareas'!$Q$6:$Q$155,12)-5)&IF(INDEX('Tareas'!$F$6:$F$155,SMALL('Tareas'!$Q$6:$Q$155,12)-5)="",""," ("&INDEX('Tareas'!$F$6:$F$155,SMALL('Tareas'!$Q$6:$Q$155,12)-5)&")"),"") | D17: =IFERROR("☐ "&INDEX('Tareas'!$A$6:$A$155,SMALL('Tareas'!$R$6:$R$155,12)-5)&IF(INDEX('Tareas'!$F$6:$F$155,SMALL('Tareas'!$R$6:$R$155,12)-5)="",""," ("&INDEX('Tareas'!$F$6:$F$155,SMALL('Tareas'!$R$6:$R$155,12)-5)&")"),"") | E17: =IFERROR("☐ "&INDEX('Tareas'!$A$6:$A$155,SMALL('Tareas'!$S$6:$S$155,12)-5)&IF(INDEX('Tareas'!$F$6:$F$155,SMALL('Tareas'!$S$6:$S$155,12)-5)="",""," ("&INDEX('Tareas'!$F$6:$F$155,SMALL('Tareas'!$S$6:$S$155,12)-5)&")"),"") | F17: =IFERROR("☐ "&INDEX('Tareas'!$A$6:$A$155,SMALL('Tareas'!$T$6:$T$155,12)-5)&IF(INDEX('Tareas'!$F$6:$F$155,SMALL('Tareas'!$T$6:$T$155,12)-5)="",""," ("&INDEX('Tareas'!$F$6:$F$155,SMALL('Tareas'!$T$6:$T$155,12)-5)&")"),"") | G17: =IFERROR("☐ "&INDEX('Tareas'!$A$6:$A$155,SMALL('Tareas'!$U$6:$U$155,12)-5)&IF(INDEX('Tareas'!$F$6:$F$155,SMALL('Tareas'!$U$6:$U$155,12)-5)="",""," ("&INDEX('Tareas'!$F$6:$F$155,SMALL('Tareas'!$U$6:$U$155,12)-5)&")"),"")
A18: =IF(COUNT('Tareas'!$O$6:$O$155)>12,"+ "&(COUNT('Tareas'!$O$6:$O$155)-12)&" más","") | B18: =IF(COUNT('Tareas'!$P$6:$P$155)>12,"+ "&(COUNT('Tareas'!$P$6:$P$155)-12)&" más","") | C18: =IF(COUNT('Tareas'!$Q$6:$Q$155)>12,"+ "&(COUNT('Tareas'!$Q$6:$Q$155)-12)&" más","") | D18: =IF(COUNT('Tareas'!$R$6:$R$155)>12,"+ "&(COUNT('Tareas'!$R$6:$R$155)-12)&" más","") | E18: =IF(COUNT('Tareas'!$S$6:$S$155)>12,"+ "&(COUNT('Tareas'!$S$6:$S$155)-12)&" más","") | F18: =IF(COUNT('Tareas'!$T$6:$T$155)>12,"+ "&(COUNT('Tareas'!$T$6:$T$155)-12)&" más","") | G18: =IF(COUNT('Tareas'!$U$6:$U$155)>12,"+ "&(COUNT('Tareas'!$U$6:$U$155)-12)&" más","")
A20: Notas

Sheet Tareas
A1: Tareas
A2: Una fila por tarea que se repite. Cuando la terminás, anotá la fecha en 'Última vez'; el resto es automático.
A5: Tarea | B5: Ambiente / área | C5: Cada | D5: Unidad | E5: Minutos | F5: Quién | G5: Última vez | H5: Activa | I5: Intervalo (días) | J5: Próxima vez | K5: Días que faltan | L5: Estado | M5: key | N5: wk | O5: d0 | P5: d1 | Q5: d2 | R5: d3 | S5: d4 | T5: d5 | U5: d6
A6: Lavar los platos / usar el lavavajillas | B6: Cocina | C6: 1 | D6: Días | E6: 15 | H6: Sí | I6: =IFERROR(IF(OR(A6="",C6=""),"",C6*INDEX('Ajustes'!$I$5:$I$8,MATCH(D6,'Ajustes'!$H$5:$H$8,0))),"") | J6: =IFERROR(IF(I6="","",IF(G6="",IF('Ajustes'!$B$5="",TODAY(),'Ajustes'!$B$5)+MOD(ROW()*13,I6),IF(D6='Ajustes'!$H$7,EDATE(G6,C6),IF(D6='Ajustes'!$H$8,EDATE(G6,12*C6),G6+I6)))),"") | K6: =IF(J6="","",J6-TODAY()) | L6: =IF(A6="","",IF(H6="No","Pausada",IF(K6="","",IF(K6<0,"Atrasada",IF(K6=0,"Hoy",IF(K6<=7,"Esta semana","Más adelante")))))) | M6: =IFERROR(IF(AND(OR(L6="Atrasada",L6="Hoy",L6="Esta semana"),OR('Hoy'!$B$3='Ajustes'!$D$5,F6='Hoy'!$B$3)),K6+ROW()/100000,""),"") | N6: =IF(OR(A6="",H6="No",I6=""),0,E6*7/I6) | O6: =IFERROR(IF(AND(A6<>"",H6<>"No",I6<>"",OR('Hoy'!$B$3='Ajustes'!$D$5,F6='Hoy'!$B$3),J6<=TODAY()),ROW(),""),"") | P6: =IFERROR(IF(AND(A6<>"",H6<>"No",I6<>"",OR('Hoy'!$B$3='Ajustes'!$D$5,F6='Hoy'!$B$3),OR(J6=TODAY()+1,AND(I6<=7,J6>=TODAY(),J6<TODAY()+1,MOD(TODAY()+1-J6,I6)=0))),ROW(),""),"") | Q6: =IFERROR(IF(AND(A6<>"",H6<>"No",I6<>"",OR('Hoy'!$B$3='Ajustes'!$D$5,F6='Hoy'!$B$3),OR(J6=TODAY()+2,AND(I6<=7,J6>=TODAY(),J6<TODAY()+2,MOD(TODAY()+2-J6,I6)=0))),ROW(),""),"") | R6: =IFERROR(IF(AND(A6<>"",H6<>"No",I6<>"",OR('Hoy'!$B$3='Ajustes'!$D$5,F6='Hoy'!$B$3),OR(J6=TODAY()+3,AND(I6<=7,J6>=TODAY(),J6<TODAY()+3,MOD(TODAY()+3-J6,I6)=0))),ROW(),""),"") | S6: =IFERROR(IF(AND(A6<>"",H6<>"No",I6<>"",OR('Hoy'!$B$3='Ajustes'!$D$5,F6='Hoy'!$B$3),OR(J6=TODAY()+4,AND(I6<=7,J6>=TODAY(),J6<TODAY()+4,MOD(TODAY()+4-J6,I6)=0))),ROW(),""),"") | T6: =IFERROR(IF(AND(A6<>"",H6<>"No",I6<>"",OR('Hoy'!$B$3='Ajustes'!$D$5,F6='Hoy'!$B$3),OR(J6=TODAY()+5,AND(I6<=7,J6>=TODAY(),J6<TODAY()+5,MOD(TODAY()+5-J6,I6)=0))),ROW(),""),"") | U6: =IFERROR(IF(AND(A6<>"",H6<>"No",I6<>"",OR('Hoy'!$B$3='Ajustes'!$D$5,F6='Hoy'!$B$3),OR(J6=TODAY()+6,AND(I6<=7,J6>=TODAY(),J6<TODAY()+6,MOD(TODAY()+6-J6,I6)=0))),ROW(),""),"")
A7: Pasar un trapo por mesada y cocina | B7: Cocina | C7: 1 | D7: Días | E7: 5 | H7: Sí | I7: =IFERROR(IF(OR(A7="",C7=""),"",C7*INDEX('Ajustes'!$I$5:$I$8,MATCH(D7,'Ajustes'!$H$5:$H$8,0))),"") | J7: =IFERROR(IF(I7="","",IF(G7="",IF('Ajustes'!$B$5="",TODAY(),'Ajustes'!$B$5)+MOD(ROW()*13,I7),IF(D7='Ajustes'!$H$7,EDATE(G7,C7),IF(D7='Ajustes'!$H$8,EDATE(G7,12*C7),G7+I7)))),"") | K7: =IF(J7="","",J7-TODAY()) | L7: =IF(A7="","",IF(H7="No","Pausada",IF(K7="","",IF(K7<0,"Atrasada",IF(K7=0,"Hoy",IF(K7<=7,"Esta semana","Más adelante")))))) | M7: =IFERROR(IF(AND(OR(L7="Atrasada",L7="Hoy",L7="Esta semana"),OR('Hoy'!$B$3='Ajustes'!$D$5,F7='Hoy'!$B$3)),K7+ROW()/100000,""),"") | N7: =IF(OR(A7="",H7="No",I7=""),0,E7*7/I7) | O7: =IFERROR(IF(AND(A7<>"",H7<>"No",I7<>"",OR('Hoy'!$B$3='Ajustes'!$D$5,F7='Hoy'!$B$3),J7<=TODAY()),ROW(),""),"") | P7: =IFERROR(IF(AND(A7<>"",H7<>"No",I7<>"",OR('Hoy'!$B$3='Ajustes'!$D$5,F7='Hoy'!$B$3),OR(J7=TODAY()+1,AND(I7<=7,J7>=TODAY(),J7<TODAY()+1,MOD(TODAY()+1-J7,I7)=0))),ROW(),""),"") | Q7: =IFERROR(IF(AND(A7<>"",H7<>"No",I7<>"",OR('Hoy'!$B$3='Ajustes'!$D$5,F7='Hoy'!$B$3),OR(J7=TODAY()+2,AND(I7<=7,J7>=TODAY(),J7<TODAY()+2,MOD(TODAY()+2-J7,I7)=0))),ROW(),""),"") | R7: =IFERROR(IF(AND(A7<>"",H7<>"No",I7<>"",OR('Hoy'!$B$3='Ajustes'!$D$5,F7='Hoy'!$B$3),OR(J7=TODAY()+3,AND(I7<=7,J7>=TODAY(),J7<TODAY()+3,MOD(TODAY()+3-J7,I7)=0))),ROW(),""),"") | S7: =IFERROR(IF(AND(A7<>"",H7<>"No",I7<>"",OR('Hoy'!$B$3='Ajustes'!$D$5,F7='Hoy'!$B$3),OR(J7=TODAY()+4,AND(I7<=7,J7>=TODAY(),J7<TODAY()+4,MOD(TODAY()+4-J7,I7)=0))),ROW(),""),"") | T7: =IFERROR(IF(AND(A7<>"",H7<>"No",I7<>"",OR('Hoy'!$B$3='Ajustes'!$D$5,F7='Hoy'!$B$3),OR(J7=TODAY()+5,AND(I7<=7,J7>=TODAY(),J7<TODAY()+5,MOD(TODAY()+5-J7,I7)=0))),ROW(),""),"") | U7: =IFERROR(IF(AND(A7<>"",H7<>"No",I7<>"",OR('Hoy'!$B$3='Ajustes'!$D$5,F7='Hoy'!$B$3),OR(J7=TODAY()+6,AND(I7<=7,J7>=TODAY(),J7<TODAY()+6,MOD(TODAY()+6-J7,I7)=0))),ROW(),""),"")
A8: Sacar la basura de la cocina | B8: Cocina | C8: 1 | D8: Días | E8: 3 | H8: Sí | I8: =IFERROR(IF(OR(A8="",C8=""),"",C8*INDEX('Ajustes'!$I$5:$I$8,MATCH(D8,'Ajustes'!$H$5:$H$8,0))),"") | J8: =IFERROR(IF(I8="","",IF(G8="",IF('Ajustes'!$B$5="",TODAY(),'Ajustes'!$B$5)+MOD(ROW()*13,I8),IF(D8='Ajustes'!$H$7,EDATE(G8,C8),IF(D8='Ajustes'!$H$8,EDATE(G8,12*C8),G8+I8)))),"") | K8: =IF(J8="","",J8-TODAY()) | L8: =IF(A8="","",IF(H8="No","Pausada",IF(K8="","",IF(K8<0,"Atrasada",IF(K8=0,"Hoy",IF(K8<=7,"Esta semana","Más adelante")))))) | M8: =IFERROR(IF(AND(OR(L8="Atrasada",L8="Hoy",L8="Esta semana"),OR('Hoy'!$B$3='Ajustes'!$D$5,F8='Hoy'!$B$3)),K8+ROW()/100000,""),"") | N8: =IF(OR(A8="",H8="No",I8=""),0,E8*7/I8) | O8: =IFERROR(IF(AND(A8<>"",H8<>"No",I8<>"",OR('Hoy'!$B$3='Ajustes'!$D$5,F8='Hoy'!$B$3),J8<=TODAY()),ROW(),""),"") | P8: =IFERROR(IF(AND(A8<>"",H8<>"No",I8<>"",OR('Hoy'!$B$3='Ajustes'!$D$5,F8='Hoy'!$B$3),OR(J8=TODAY()+1,AND(I8<=7,J8>=TODAY(),J8<TODAY()+1,MOD(TODAY()+1-J8,I8)=0))),ROW(),""),"") | Q8: =IFERROR(IF(AND(A8<>"",H8<>"No",I8<>"",OR('Hoy'!$B$3='Ajustes'!$D$5,F8='Hoy'!$B$3),OR(J8=TODAY()+2,AND(I8<=7,J8>=TODAY(),J8<TODAY()+2,MOD(TODAY()+2-J8,I8)=0))),ROW(),""),"") | R8: =IFERROR(IF(AND(A8<>"",H8<>"No",I8<>"",OR('Hoy'!$B$3='Ajustes'!$D$5,F8='Hoy'!$B$3),OR(J8=TODAY()+3,AND(I8<=7,J8>=TODAY(),J8<TODAY()+3,MOD(TODAY()+3-J8,I8)=0))),ROW(),""),"") | S8: =IFERROR(IF(AND(A8<>"",H8<>"No",I8<>"",OR('Hoy'!$B$3='Ajustes'!$D$5,F8='Hoy'!$B$3),OR(J8=TODAY()+4,AND(I8<=7,J8>=TODAY(),J8<TODAY()+4,MOD(TODAY()+4-J8,I8)=0))),ROW(),""),"") | T8: =IFERROR(IF(AND(A8<>"",H8<>"No",I8<>"",OR('Hoy'!$B$3='Ajustes'!$D$5,F8='Hoy'!$B$3),OR(J8=TODAY()+5,AND(I8<=7,J8>=TODAY(),J8<TODAY()+5,MOD(TODAY()+5-J8,I8)=0))),ROW(),""),"") | U8: =IFERROR(IF(AND(A8<>"",H8<>"No",I8<>"",OR('Hoy'!$B$3='Ajustes'!$D$5,F8='Hoy'!$B$3),OR(J8=TODAY()+6,AND(I8<=7,J8>=TODAY(),J8<TODAY()+6,MOD(TODAY()+6-J8,I8)=0))),ROW(),""),"")
A9: Barrer el piso de la cocina | B9: Cocina | C9: 2 | D9: Días | E9: 5 | H9: Sí | I9: =IFERROR(IF(OR(A9="",C9=""),"",C9*INDEX('Ajustes'!$I$5:$I$8,MATCH(D9,'Ajustes'!$H$5:$H$8,0))),"") | J9: =IFERROR(IF(I9="","",IF(G9="",IF('Ajustes'!$B$5="",TODAY(),'Ajustes'!$B$5)+MOD(ROW()*13,I9),IF(D9='Ajustes'!$H$7,EDATE(G9,C9),IF(D9='Ajustes'!$H$8,EDATE(G9,12*C9),G9+I9)))),"") | K9: =IF(J9="","",J9-TODAY()) | L9: =IF(A9="","",IF(H9="No","Pausada",IF(K9="","",IF(K9<0,"Atrasada",IF(K9=0,"Hoy",IF(K9<=7,"Esta semana","Más adelante")))))) | M9: =IFERROR(IF(AND(OR(L9="Atrasada",L9="Hoy",L9="Esta semana"),OR('Hoy'!$B$3='Ajustes'!$D$5,F9='Hoy'!$B$3)),K9+ROW()/100000,""),"") | N9: =IF(OR(A9="",H9="No",I9=""),0,E9*7/I9) | O9: =IFERROR(IF(AND(A9<>"",H9<>"No",I9<>"",OR('Hoy'!$B$3='Ajustes'!$D$5,F9='Hoy'!$B$3),J9<=TODAY()),ROW(),""),"") | P9: =IFERROR(IF(AND(A9<>"",H9<>"No",I9<>"",OR('Hoy'!$B$3='Ajustes'!$D$5,F9='Hoy'!$B$3),OR(J9=TODAY()+1,AND(I9<=7,J9>=TODAY(),J9<TODAY()+1,MOD(TODAY()+1-J9,I9)=0))),ROW(),""),"") | Q9: =IFERROR(IF(AND(A9<>"",H9<>"No",I9<>"",OR('Hoy'!$B$3='Ajustes'!$D$5,F9='Hoy'!$B$3),OR(J9=TODAY()+2,AND(I9<=7,J9>=TODAY(),J9<TODAY()+2,MOD(TODAY()+2-J9,I9)=0))),ROW(),""),"") | R9: =IFERROR(IF(AND(A9<>"",H9<>"No",I9<>"",OR('Hoy'!$B$3='Ajustes'!$D$5,F9='Hoy'!$B$3),OR(J9=TODAY()+3,AND(I9<=7,J9>=TODAY(),J9<TODAY()+3,MOD(TODAY()+3-J9,I9)=0))),ROW(),""),"") | S9: =IFERROR(IF(AND(A9<>"",H9<>"No",I9<>"",OR('Hoy'!$B$3='Ajustes'!$D$5,F9='Hoy'!$B$3),OR(J9=TODAY()+4,AND(I9<=7,J9>=TODAY(),J9<TODAY()+4,MOD(TODAY()+4-J9,I9)=0))),ROW(),""),"") | T9: =IFERROR(IF(AND(A9<>"",H9<>"No",I9<>"",OR('Hoy'!$B$3='Ajustes'!$D$5,F9='Hoy'!$B$3),OR(J9=TODAY()+5,AND(I9<=7,J9>=TODAY(),J9<TODAY()+5,MOD(TODAY()+5-J9,I9)=0))),ROW(),""),"") | U9: =IFERROR(IF(AND(A9<>"",H9<>"No",I9<>"",OR('Hoy'!$B$3='Ajustes'!$D$5,F9='Hoy'!$B$3),OR(J9=TODAY()+6,AND(I9<=7,J9>=TODAY(),J9<TODAY()+6,MOD(TODAY()+6-J9,I9)=0))),ROW(),""),"")
A10: Trapear el piso de la cocina | B10: Cocina | C10: 1 | D10: Semanas | E10: 15 | H10: Sí | I10: =IFERROR(IF(OR(A10="",C10=""),"",C10*INDEX('Ajustes'!$I$5:$I$8,MATCH(D10,'Ajustes'!$H$5:$H$8,0))),"") | J10: =IFERROR(IF(I10="","",IF(G10="",IF('Ajustes'!$B$5="",TODAY(),'Ajustes'!$B$5)+MOD(ROW()*13,I10),IF(D10='Ajustes'!$H$7,EDATE(G10,C10),IF(D10='Ajustes'!$H$8,EDATE(G10,12*C10),G10+I10)))),"") | K10: =IF(J10="","",J10-TODAY()) | L10: =IF(A10="","",IF(H10="No","Pausada",IF(K10="","",IF(K10<0,"Atrasada",IF(K10=0,"Hoy",IF(K10<=7,"Esta semana","Más adelante")))))) | M10: =IFERROR(IF(AND(OR(L10="Atrasada",L10="Hoy",L10="Esta semana"),OR('Hoy'!$B$3='Ajustes'!$D$5,F10='Hoy'!$B$3)),K10+ROW()/100000,""),"") | N10: =IF(OR(A10="",H10="No",I10=""),0,E10*7/I10) | O10: =IFERROR(IF(AND(A10<>"",H10<>"No",I10<>"",OR('Hoy'!$B$3='Ajustes'!$D$5,F10='Hoy'!$B$3),J10<=TODAY()),ROW(),""),"") | P10: =IFERROR(IF(AND(A10<>"",H10<>"No",I10<>"",OR('Hoy'!$B$3='Ajustes'!$D$5,F10='Hoy'!$B$3),OR(J10=TODAY()+1,AND(I10<=7,J10>=TODAY(),J10<TODAY()+1,MOD(TODAY()+1-J10,I10)=0))),ROW(),""),"") | Q10: =IFERROR(IF(AND(A10<>"",H10<>"No",I10<>"",OR('Hoy'!$B$3='Ajustes'!$D$5,F10='Hoy'!$B$3),OR(J10=TODAY()+2,AND(I10<=7,J10>=TODAY(),J10<TODAY()+2,MOD(TODAY()+2-J10,I10)=0))),ROW(),""),"") | R10: =IFERROR(IF(AND(A10<>"",H10<>"No",I10<>"",OR('Hoy'!$B$3='Ajustes'!$D$5,F10='Hoy'!$B$3),OR(J10=TODAY()+3,AND(I10<=7,J10>=TODAY(),J10<TODAY()+3,MOD(TODAY()+3-J10,I10)=0))),ROW(),""),"") | S10: =IFERROR(IF(AND(A10<>"",H10<>"No",I10<>"",OR('Hoy'!$B$3='Ajustes'!$D$5,F10='Hoy'!$B$3),OR(J10=TODAY()+4,AND(I10<=7,J10>=TODAY(),J10<TODAY()+4,MOD(TODAY()+4-J10,I10)=0))),ROW(),""),"") | T10: =IFERROR(IF(AND(A10<>"",H10<>"No",I10<>"",OR('Hoy'!$B$3='Ajustes'!$D$5,F10='Hoy'!$B$3),OR(J10=TODAY()+5,AND(I10<=7,J10>=TODAY(),J10<TODAY()+5,MOD(TODAY()+5-J10,I10)=0))),ROW(),""),"") | U10: =IFERROR(IF(AND(A10<>"",H10<>"No",I10<>"",OR('Hoy'!$B$3='Ajustes'!$D$5,F10='Hoy'!$B$3),OR(J10=TODAY()+6,AND(I10<=7,J10>=TODAY(),J10<TODAY()+6,MOD(TODAY()+6-J10,I10)=0))),ROW(),""),"")
A11: Limpiar la pileta y el desagüe | B11: Cocina | C11: 1 | D11: Semanas | E11: 5 | H11: Sí | I11: =IFERROR(IF(OR(A11="",C11=""),"",C11*INDEX('Ajustes'!$I$5:$I$8,MATCH(D11,'Ajustes'!$H$5:$H$8,0))),"") | J11: =IFERROR(IF(I11="","",IF(G11="",IF('Ajustes'!$B$5="",TODAY(),'Ajustes'!$B$5)+MOD(ROW()*13,I11),IF(D11='Ajustes'!$H$7,EDATE(G11,C11),IF(D11='Ajustes'!$H$8,EDATE(G11,12*C11),G11+I11)))),"") | K11: =IF(J11="","",J11-TODAY()) | L11: =IF(A11="","",IF(H11="No","Pausada",IF(K11="","",IF(K11<0,"Atrasada",IF(K11=0,"Hoy",IF(K11<=7,"Esta semana","Más adelante")))))) | M11: =IFERROR(IF(AND(OR(L11="Atrasada",L11="Hoy",L11="Esta semana"),OR('Hoy'!$B$3='Ajustes'!$D$5,F11='Hoy'!$B$3)),K11+ROW()/100000,""),"") | N11: =IF(OR(A11="",H11="No",I11=""),0,E11*7/I11) | O11: =IFERROR(IF(AND(A11<>"",H11<>"No",I11<>"",OR('Hoy'!$B$3='Ajustes'!$D$5,F11='Hoy'!$B$3),J11<=TODAY()),ROW(),""),"") | P11: =IFERROR(IF(AND(A11<>"",H11<>"No",I11<>"",OR('Hoy'!$B$3='Ajustes'!$D$5,F11='Hoy'!$B$3),OR(J11=TODAY()+1,AND(I11<=7,J11>=TODAY(),J11<TODAY()+1,MOD(TODAY()+1-J11,I11)=0))),ROW(),""),"") | Q11: =IFERROR(IF(AND(A11<>"",H11<>"No",I11<>"",OR('Hoy'!$B$3='Ajustes'!$D$5,F11='Hoy'!$B$3),OR(J11=TODAY()+2,AND(I11<=7,J11>=TODAY(),J11<TODAY()+2,MOD(TODAY()+2-J11,I11)=0))),ROW(),""),"") | R11: =IFERROR(IF(AND(A11<>"",H11<>"No",I11<>"",OR('Hoy'!$B$3='Ajustes'!$D$5,F11='Hoy'!$B$3),OR(J11=TODAY()+3,AND(I11<=7,J11>=TODAY(),J11<TODAY()+3,MOD(TODAY()+3-J11,I11)=0))),ROW(),""),"") | S11: =IFERROR(IF(AND(A11<>"",H11<>"No",I11<>"",OR('Hoy'!$B$3='Ajustes'!$D$5,F11='Hoy'!$B$3),OR(J11=TODAY()+4,AND(I11<=7,J11>=TODAY(),J11<TODAY()+4,MOD(TODAY()+4-J11,I11)=0))),ROW(),""),"") | T11: =IFERROR(IF(AND(A11<>"",H11<>"No",I11<>"",OR('Hoy'!$B$3='Ajustes'!$D$5,F11='Hoy'!$B$3),OR(J11=TODAY()+5,AND(I11<=7,J11>=TODAY(),J11<TODAY()+5,MOD(TODAY()+5-J11,I11)=0))),ROW(),""),"") | U11: =IFERROR(IF(AND(A11<>"",H11<>"No",I11<>"",OR('Hoy'!$B$3='Ajustes'!$D$5,F11='Hoy'!$B$3),OR(J11=TODAY()+6,AND(I11<=7,J11>=TODAY(),J11<TODAY()+6,MOD(TODAY()+6-J11,I11)=0))),ROW(),""),"")
A12: Limpiar estantes de la heladera y tirar lo vencido | B12: Cocina | C12: 1 | D12: Semanas | E12: 10 | H12: Sí | I12: =IFERROR(IF(OR(A12="",C12=""),"",C12*INDEX('Ajustes'!$I$5:$I$8,MATCH(D12,'Ajustes'!$H$5:$H$8,0))),"") | J12: =IFERROR(IF(I12="","",IF(G12="",IF('Ajustes'!$B$5="",TODAY(),'Ajustes'!$B$5)+MOD(ROW()*13,I12),IF(D12='Ajustes'!$H$7,EDATE(G12,C12),IF(D12='Ajustes'!$H$8,EDATE(G12,12*C12),G12+I12)))),"") | K12: =IF(J12="","",J12-TODAY()) | L12: =IF(A12="","",IF(H12="No","Pausada",IF(K12="","",IF(K12<0,"Atrasada",IF(K12=0,"Hoy",IF(K12<=7,"Esta semana","Más adelante")))))) | M12: =IFERROR(IF(AND(OR(L12="Atrasada",L12="Hoy",L12="Esta semana"),OR('Hoy'!$B$3='Ajustes'!$D$5,F12='Hoy'!$B$3)),K12+ROW()/100000,""),"") | N12: =IF(OR(A12="",H12="No",I12=""),0,E12*7/I12) | O12: =IFERROR(IF(AND(A12<>"",H12<>"No",I12<>"",OR('Hoy'!$B$3='Ajustes'!$D$5,F12='Hoy'!$B$3),J12<=TODAY()),ROW(),""),"") | P12: =IFERROR(IF(AND(A12<>"",H12<>"No",I12<>"",OR('Hoy'!$B$3='Ajustes'!$D$5,F12='Hoy'!$B$3),OR(J12=TODAY()+1,AND(I12<=7,J12>=TODAY(),J12<TODAY()+1,MOD(TODAY()+1-J12,I12)=0))),ROW(),""),"") | Q12: =IFERROR(IF(AND(A12<>"",H12<>"No",I12<>"",OR('Hoy'!$B$3='Ajustes'!$D$5,F12='Hoy'!$B$3),OR(J12=TODAY()+2,AND(I12<=7,J12>=TODAY(),J12<TODAY()+2,MOD(TODAY()+2-J12,I12)=0))),ROW(),""),"") | R12: =IFERROR(IF(AND(A12<>"",H12<>"No",I12<>"",OR('Hoy'!$B$3='Ajustes'!$D$5,F12='Hoy'!$B$3),OR(J12=TODAY()+3,AND(I12<=7,J12>=TODAY(),J12<TODAY()+3,MOD(TODAY()+3-J12,I12)=0))),ROW(),""),"") | S12: =IFERROR(IF(AND(A12<>"",H12<>"No",I12<>"",OR('Hoy'!$B$3='Ajustes'!$D$5,F12='Hoy'!$B$3),OR(J12=TODAY()+4,AND(I12<=7,J12>=TODAY(),J12<TODAY()+4,MOD(TODAY()+4-J12,I12)=0))),ROW(),""),"") | T12: =IFERROR(IF(AND(A12<>"",H12<>"No",I12<>"",OR('Hoy'!$B$3='Ajustes'!$D$5,F12='Hoy'!$B$3),OR(J12=TODAY()+5,AND(I12<=7,J12>=TODAY(),J12<TODAY()+5,MOD(TODAY()+5-J12,I12)=0))),ROW(),""),"") | U12: =IFERROR(IF(AND(A12<>"",H12<>"No",I12<>"",OR('Hoy'!$B$3='Ajustes'!$D$5,F12='Hoy'!$B$3),OR(J12=TODAY()+6,AND(I12<=7,J12>=TODAY(),J12<TODAY()+6,MOD(TODAY()+6-J12,I12)=0))),ROW(),""),"")
