Workbook

Sheet Inicio
A1: Control de Horas Extra y Francos
A2: Registrá las horas extra, mirá el saldo de francos a tomar de cada persona y mantenelo separado de las vacaciones oficiales. Funciona en Excel y Google Sheets.
A4: CÓMO USARLA
A5: 1. Equipo: cargá a tu gente (hasta 25). Para cada persona definí cuántas horas dura su jornada, un saldo inicial si ya tiene horas acumuladas y sus días de vacaciones por año.
A6: 2. Registro: una fila por cada hecho. Elegí la fecha, la persona y el tipo, y escribí las horas (por ejemplo 3 horas extra). Los francos se pueden cargar en horas, en días o ambos. Dejá vacía la celda que no uses.
A7: 3. Perfil: elegí una persona y mirá su saldo en horas y en días, cuántas vacaciones le quedan y cada movimiento con el saldo acumulado.
A8: 4. Resumen: todo el equipo de un vistazo, con un gráfico. No hay nada que escribir.
A9: 5. Ajustes: podés renombrar los tipos y definir un coeficiente por tipo (1 = una hora por hora; 1,5 = cada hora trabajada cuenta como 1,5 horas de franco).
A11: CÓMO SE CALCULA EL SALDO
A12: Saldo = saldo inicial + horas extra acreditadas - francos tomados. Las 'Vacaciones / licencia oficial' nunca tocan ese saldo: se cuentan aparte contra los días anuales de vacaciones.
A13: Los 'días' son el saldo dividido por la jornada de la persona: 8 horas extra con jornada de 8 horas = 1 franco para tomar.
A15: COLORES
... A19: Herramienta de registro. No aplica ninguna ley, convenio ni política de la empresa y no es asesoramiento legal ni de recursos humanos: verificá tus propias reglas sobre cómo se pagan o compensan las horas extra. Para uso personal o interno del equipo; no se permite su reventa ni redistribución.

Sheet Perfil
A1: Perfil
A2: Elegí una persona para ver su saldo e historial.
A3: Persona | B3: Lucía Fernández
A5: FRANCOS COMPENSATORIOS | D5: VACACIONES OFICIALES (APARTE)
A6: Horas extra acreditadas | B6: =IFERROR(INDEX('Resumen'!$B$5:$B$29,MATCH($B$3,'Resumen'!$A$5:$A$29,0)),"") | D6: Corresponden (días) | F6: =IFERROR(INDEX('Equipo'!$D$5:$D$29,MATCH($B$3,'Equipo'!$A$5:$A$29,0)),"")
A7: Francos tomados (h) | B7: =IFERROR(INDEX('Resumen'!$C$5:$C$29,MATCH($B$3,'Resumen'!$A$5:$A$29,0)),"") | D7: Usados este año (días) | F7: =IFERROR(INDEX('Resumen'!$G$5:$G$29,MATCH($B$3,'Resumen'!$A$5:$A$29,0)),"")
A8: Saldo inicial (h) | B8: =IFERROR(INDEX('Resumen'!$D$5:$D$29,MATCH($B$3,'Resumen'!$A$5:$A$29,0)),"") | D8: Quedan (días) | F8: =IFERROR(INDEX('Resumen'!$H$5:$H$29,MATCH($B$3,'Resumen'!$A$5:$A$29,0)),"")
A9: SALDO (horas) | B9: =IFERROR(INDEX('Resumen'!$E$5:$E$29,MATCH($B$3,'Resumen'!$A$5:$A$29,0)),"") | D9: Año | F9: ='Ajustes'!$A$12
A10: SALDO (días) | B10: =IFERROR(INDEX('Resumen'!$F$5:$F$29,MATCH($B$3,'Resumen'!$A$5:$A$29,0)),"")
A11: Jornada (h) | B11: =IFERROR(INDEX('Equipo'!$B$5:$B$29,MATCH($B$3,'Equipo'!$A$5:$A$29,0)),"")
A13: =IF($B$9="","",IF($B$9>0.0001,"A tomar: "&INT($B$9/$B$11)&" día(s) y "&ROUND($B$9-INT($B$9/$B$11)*$B$11,2)&" h",IF($B$9<-0.0001,"Tomó de más: "&ROUND(-$B$9,2)&" h","Al día, sin saldo")))
A15: Fecha | B15: Tipo | C15: Horas | D15: Días | E15: Acreditadas (h) | F15: Saldo después (h) | G15: Nota
A16: =IFERROR(IF(INDEX('Registro'!$A$4:$A$1503,MATCH(1,'Registro'!$I$4:$I$1503,0))="","",INDEX('Registro'!$A$4:$A$1503,MATCH(1,'Registro'!$I$4:$I$1503,0))),"") | B16: =IFERROR(IF(INDEX('Registro'!$C$4:$C$1503,MATCH(1,'Registro'!$I$4:$I$1503,0))="","",INDEX('Registro'!$C$4:$C$1503,MATCH(1,'Registro'!$I$4:$I$1503,0))),"") | C16: =IFERROR(IF(INDEX('Registro'!$D$4:$D$1503,MATCH(1,'Registro'!$I$4:$I$1503,0))="","",INDEX('Registro'!$D$4:$D$1503,MATCH(1,'Registro'!$I$4:$I$1503,0))),"") | D16: =IFERROR(IF(INDEX('Registro'!$E$4:$E$1503,MATCH(1,'Registro'!$I$4:$I$1503,0))="","",INDEX('Registro'!$E$4:$E$1503,MATCH(1,'Registro'!$I$4:$I$1503,0))),"") | E16: =IFERROR(IF(INDEX('Registro'!$G$4:$G$1503,MATCH(1,'Registro'!$I$4:$I$1503,0))="","",INDEX('Registro'!$G$4:$G$1503,MATCH(1,'Registro'!$I$4:$I$1503,0))),"") | F16: =IF($A16="","",$B$8+SUMIFS('Registro'!$G$4:$G$1503,'Registro'!$B$4:$B$1503,$B$3,'Registro'!$A$4:$A$1503,"<="&$A16)) | G16: =IFERROR(IF(INDEX('Registro'!$F$4:$F$1503,MATCH(1,'Registro'!$I$4:$I$1503,0))="","",INDEX('Registro'!$F$4:$F$1503,MATCH(1,'Registro'!$I$4:$I$1503,0))),"")
A17: =IFERROR(IF(INDEX('Registro'!$A$4:$A$1503,MATCH(2,'Registro'!$I$4:$I$1503,0))="","",INDEX('Registro'!$A$4:$A$1503,MATCH(2,'Registro'!$I$4:$I$1503,0))),"") | B17: =IFERROR(IF(INDEX('Registro'!$C$4:$C$1503,MATCH(2,'Registro'!$I$4:$I$1503,0))="","",INDEX('Registro'!$C$4:$C$1503,MATCH(2,'Registro'!$I$4:$I$1503,0))),"") | C17: =IFERROR(IF(INDEX('Registro'!$D$4:$D$1503,MATCH(2,'Registro'!$I$4:$I$1503,0))="","",INDEX('Registro'!$D$4:$D$1503,MATCH(2,'Registro'!$I$4:$I$1503,0))),"") | D17: =IFERROR(IF(INDEX('Registro'!$E$4:$E$1503,MATCH(2,'Registro'!$I$4:$I$1503,0))="","",INDEX('Registro'!$E$4:$E$1503,MATCH(2,'Registro'!$I$4:$I$1503,0))),"") | E17: =IFERROR(IF(INDEX('Registro'!$G$4:$G$1503,MATCH(2,'Registro'!$I$4:$I$1503,0))="","",INDEX('Registro'!$G$4:$G$1503,MATCH(2,'Registro'!$I$4:$I$1503,0))),"") | F17: =IF($A17="","",$B$8+SUMIFS('Registro'!$G$4:$G$1503,'Registro'!$B$4:$B$1503,$B$3,'Registro'!$A$4:$A$1503,"<="&$A17)) | G17: =IFERROR(IF(INDEX('Registro'!$F$4:$F$1503,MATCH(2,'Registro'!$I$4:$I$1503,0))="","",INDEX('Registro'!$F$4:$F$1503,MATCH(2,'Registro'!$I$4:$I$1503,0))),"")
A18: =IFERROR(IF(INDEX('Registro'!$A$4:$A$1503,MATCH(3,'Registro'!$I$4:$I$1503,0))="","",INDEX('Registro'!$A$4:$A$1503,MATCH(3,'Registro'!$I$4:$I$1503,0))),"") | B18: =IFERROR(IF(INDEX('Registro'!$C$4:$C$1503,MATCH(3,'Registro'!$I$4:$I$1503,0))="","",INDEX('Registro'!$C$4:$C$1503,MATCH(3,'Registro'!$I$4:$I$1503,0))),"") | C18: =IFERROR(IF(INDEX('Registro'!$D$4:$D$1503,MATCH(3,'Registro'!$I$4:$I$1503,0))="","",INDEX('Registro'!$D$4:$D$1503,MATCH(3,'Registro'!$I$4:$I$1503,0))),"") | D18: =IFERROR(IF(INDEX('Registro'!$E$4:$E$1503,MATCH(3,'Registro'!$I$4:$I$1503,0))="","",INDEX('Registro'!$E$4:$E$1503,MATCH(3,'Registro'!$I$4:$I$1503,0))),"") | E18: =IFERROR(IF(INDEX('Registro'!$G$4:$G$1503,MATCH(3,'Registro'!$I$4:$I$1503,0))="","",INDEX('Registro'!$G$4:$G$1503,MATCH(3,'Registro'!$I$4:$I$1503,0))),"") | F18: =IF($A18="","",$B$8+SUMIFS('Registro'!$G$4:$G$1503,'Registro'!$B$4:$B$1503,$B$3,'Registro'!$A$4:$A$1503,"<="&$A18)) | G18: =IFERROR(IF(INDEX('Registro'!$F$4:$F$1503,MATCH(3,'Registro'!$I$4:$I$1503,0))="","",INDEX('Registro'!$F$4:$F$1503,MATCH(3,'Registro'!$I$4:$I$1503,0))),"")
A19: =IFERROR(IF(INDEX('Registro'!$A$4:$A$1503,MATCH(4,'Registro'!$I$4:$I$1503,0))="","",INDEX('Registro'!$A$4:$A$1503,MATCH(4,'Registro'!$I$4:$I$1503,0))),"") | B19: =IFERROR(IF(INDEX('Registro'!$C$4:$C$1503,MATCH(4,'Registro'!$I$4:$I$1503,0))="","",INDEX('Registro'!$C$4:$C$1503,MATCH(4,'Registro'!$I$4:$I$1503,0))),"") | C19: =IFERROR(IF(INDEX('Registro'!$D$4:$D$1503,MATCH(4,'Registro'!$I$4:$I$1503,0))="","",INDEX('Registro'!$D$4:$D$1503,MATCH(4,'Registro'!$I$4:$I$1503,0))),"") | D19: =IFERROR(IF(INDEX('Registro'!$E$4:$E$1503,MATCH(4,'Registro'!$I$4:$I$1503,0))="","",INDEX('Registro'!$E$4:$E$1503,MATCH(4,'Registro'!$I$4:$I$1503,0))),"") | E19: =IFERROR(IF(INDEX('Registro'!$G$4:$G$1503,MATCH(4,'Registro'!$I$4:$I$1503,0))="","",INDEX('Registro'!$G$4:$G$1503,MATCH(4,'Registro'!$I$4:$I$1503,0))),"") | F19: =IF($A19="","",$B$8+SUMIFS('Registro'!$G$4:$G$1503,'Registro'!$B$4:$B$1503,$B$3,'Registro'!$A$4:$A$1503,"<="&$A19)) | G19: =IFERROR(IF(INDEX('Registro'!$F$4:$F$1503,MATCH(4,'Registro'!$I$4:$I$1503,0))="","",INDEX('Registro'!$F$4:$F$1503,MATCH(4,'Registro'!$I$4:$I$1503,0))),"")
A20: =IFERROR(IF(INDEX('Registro'!$A$4:$A$1503,MATCH(5,'Registro'!$I$4:$I$1503,0))="","",INDEX('Registro'!$A$4:$A$1503,MATCH(5,'Registro'!$I$4:$I$1503,0))),"") | B20: =IFERROR(IF(INDEX('Registro'!$C$4:$C$1503,MATCH(5,'Registro'!$I$4:$I$1503,0))="","",INDEX('Registro'!$C$4:$C$1503,MATCH(5,'Registro'!$I$4:$I$1503,0))),"") | C20: =IFERROR(IF(INDEX('Registro'!$D$4:$D$1503,MATCH(5,'Registro'!$I$4:$I$1503,0))="","",INDEX('Registro'!$D$4:$D$1503,MATCH(5,'Registro'!$I$4:$I$1503,0))),"") | D20: =IFERROR(IF(INDEX('Registro'!$E$4:$E$1503,MATCH(5,'Registro'!$I$4:$I$1503,0))="","",INDEX('Registro'!$E$4:$E$1503,MATCH(5,'Registro'!$I$4:$I$1503,0))),"") | E20: =IFERROR(IF(INDEX('Registro'!$G$4:$G$1503,MATCH(5,'Registro'!$I$4:$I$1503,0))="","",INDEX('Registro'!$G$4:$G$1503,MATCH(5,'Registro'!$I$4:$I$1503,0))),"") | F20: =IF($A20="","",$B$8+SUMIFS('Registro'!$G$4:$G$1503,'Registro'!$B$4:$B$1503,$B$3,'Registro'!$A$4:$A$1503,"<="&$A20)) | G20: =IFERROR(IF(INDEX('Registro'!$F$4:$F$1503,MATCH(5,'Registro'!$I$4:$I$1503,0))="","",INDEX('Registro'!$F$4:$F$1503,MATCH(5,'Registro'!$I$4:$I$1503,0))),"")
A21: =IFERROR(IF(INDEX('Registro'!$A$4:$A$1503,MATCH(6,'Registro'!$I$4:$I$1503,0))="","",INDEX('Registro'!$A$4:$A$1503,MATCH(6,'Registro'!$I$4:$I$1503,0))),"") | B21: =IFERROR(IF(INDEX('Registro'!$C$4:$C$1503,MATCH(6,'Registro'!$I$4:$I$1503,0))="","",INDEX('Registro'!$C$4:$C$1503,MATCH(6,'Registro'!$I$4:$I$1503,0))),"") | C21: =IFERROR(IF(INDEX('Registro'!$D$4:$D$1503,MATCH(6,'Registro'!$I$4:$I$1503,0))="","",INDEX('Registro'!$D$4:$D$1503,MATCH(6,'Registro'!$I$4:$I$1503,0))),"") | D21: =IFERROR(IF(INDEX('Registro'!$E$4:$E$1503,MATCH(6,'Registro'!$I$4:$I$1503,0))="","",INDEX('Registro'!$E$4:$E$1503,MATCH(6,'Registro'!$I$4:$I$1503,0))),"") | E21: =IFERROR(IF(INDEX('Registro'!$G$4:$G$1503,MATCH(6,'Registro'!$I$4:$I$1503,0))="","",INDEX('Registro'!$G$4:$G$1503,MATCH(6,'Registro'!$I$4:$I$1503,0))),"") | F21: =IF($A21="","",$B$8+SUMIFS('Registro'!$G$4:$G$1503,'Registro'!$B$4:$B$1503,$B$3,'Registro'!$A$4:$A$1503,"<="&$A21)) | G21: =IFERROR(IF(INDEX('Registro'!$F$4:$F$1503,MATCH(6,'Registro'!$I$4:$I$1503,0))="","",INDEX('Registro'!$F$4:$F$1503,MATCH(6,'Registro'!$I$4:$I$1503,0))),"")
A22: =IFERROR(IF(INDEX('Registro'!$A$4:$A$1503,MATCH(7,'Registro'!$I$4:$I$1503,0))="","",INDEX('Registro'!$A$4:$A$1503,MATCH(7,'Registro'!$I$4:$I$1503,0))),"") | B22: =IFERROR(IF(INDEX('Registro'!$C$4:$C$1503,MATCH(7,'Registro'!$I$4:$I$1503,0))="","",INDEX('Registro'!$C$4:$C$1503,MATCH(7,'Registro'!$I$4:$I$1503,0))),"") | C22: =IFERROR(IF(INDEX('Registro'!$D$4:$D$1503,MATCH(7,'Registro'!$I$4:$I$1503,0))="","",INDEX('Registro'!$D$4:$D$1503,MATCH(7,'Registro'!$I$4:$I$1503,0))),"") | D22: =IFERROR(IF(INDEX('Registro'!$E$4:$E$1503,MATCH(7,'Registro'!$I$4:$I$1503,0))="","",INDEX('Registro'!$E$4:$E$1503,MATCH(7,'Registro'!$I$4:$I$1503,0))),"") | E22: =IFERROR(IF(INDEX('Registro'!$G$4:$G$1503,MATCH(7,'Registro'!$I$4:$I$1503,0))="","",INDEX('Registro'!$G$4:$G$1503,MATCH(7,'Registro'!$I$4:$I$1503,0))),"") | F22: =IF($A22="","",$B$8+SUMIFS('Registro'!$G$4:$G$1503,'Registro'!$B$4:$B$1503,$B$3,'Registro'!$A$4:$A$1503,"<="&$A22)) | G22: =IFERROR(IF(INDEX('Registro'!$F$4:$F$1503,MATCH(7,'Registro'!$I$4:$I$1503,0))="","",INDEX('Registro'!$F$4:$F$1503,MATCH(7,'Registro'!$I$4:$I$1503,0))),"")
A23: =IFERROR(IF(INDEX('Registro'!$A$4:$A$1503,MATCH(8,'Registro'!$I$4:$I$1503,0))="","",INDEX('Registro'!$A$4:$A$1503,MATCH(8,'Registro'!$I$4:$I$1503,0))),"") | B23: =IFERROR(IF(INDEX('Registro'!$C$4:$C$1503,MATCH(8,'Registro'!$I$4:$I$1503,0))="","",INDEX('Registro'!$C$4:$C$1503,MATCH(8,'Registro'!$I$4:$I$1503,0))),"") | C23: =IFERROR(IF(INDEX('Registro'!$D$4:$D$1503,MATCH(8,'Registro'!$I$4:$I$1503,0))="","",INDEX('Registro'!$D$4:$D$1503,MATCH(8,'Registro'!$I$4:$I$1503,0))),"") | D23: =IFERROR(IF(INDEX('Registro'!$E$4:$E$1503,MATCH(8,'Registro'!$I$4:$I$1503,0))="","",INDEX('Registro'!$E$4:$E$1503,MATCH(8,'Registro'!$I$4:$I$1503,0))),"") | E23: =IFERROR(IF(INDEX('Registro'!$G$4:$G$1503,MATCH(8,'Registro'!$I$4:$I$1503,0))="","",INDEX('Registro'!$G$4:$G$1503,MATCH(8,'Registro'!$I$4:$I$1503,0))),"") | F23: =IF($A23="","",$B$8+SUMIFS('Registro'!$G$4:$G$1503,'Registro'!$B$4:$B$1503,$B$3,'Registro'!$A$4:$A$1503,"<="&$A23)) | G23: =IFERROR(IF(INDEX('Registro'!$F$4:$F$1503,MATCH(8,'Registro'!$I$4:$I$1503,0))="","",INDEX('Registro'!$F$4:$F$1503,MATCH(8,'Registro'!$I$4:$I$1503,0))),"")
A24: =IFERROR(IF(INDEX('Registro'!$A$4:$A$1503,MATCH(9,'Registro'!$I$4:$I$1503,0))="","",INDEX('Registro'!$A$4:$A$1503,MATCH(9,'Registro'!$I$4:$I$1503,0))),"") | B24: =IFERROR(IF(INDEX('Registro'!$C$4:$C$1503,MATCH(9,'Registro'!$I$4:$I$1503,0))="","",INDEX('Registro'!$C$4:$C$1503,MATCH(9,'Registro'!$I$4:$I$1503,0))),"") | C24: =IFERROR(IF(INDEX('Registro'!$D$4:$D$1503,MATCH(9,'Registro'!$I$4:$I$1503,0))="","",INDEX('Registro'!$D$4:$D$1503,MATCH(9,'Registro'!$I$4:$I$1503,0))),"") | D24: =IFERROR(IF(INDEX('Registro'!$E$4:$E$1503,MATCH(9,'Registro'!$I$4:$I$1503,0))="","",INDEX('Registro'!$E$4:$E$1503,MATCH(9,'Registro'!$I$4:$I$1503,0))),"") | E24: =IFERROR(IF(INDEX('Registro'!$G$4:$G$1503,MATCH(9,'Registro'!$I$4:$I$1503,0))="","",INDEX('Registro'!$G$4:$G$1503,MATCH(9,'Registro'!$I$4:$I$1503,0))),"") | F24: =IF($A24="","",$B$8+SUMIFS('Registro'!$G$4:$G$1503,'Registro'!$B$4:$B$1503,$B$3,'Registro'!$A$4:$A$1503,"<="&$A24)) | G24: =IFERROR(IF(INDEX('Registro'!$F$4:$F$1503,MATCH(9,'Registro'!$I$4:$I$1503,0))="","",INDEX('Registro'!$F$4:$F$1503,MATCH(9,'Registro'!$I$4:$I$1503,0))),"")
A25: =IFERROR(IF(INDEX('Registro'!$A$4:$A$1503,MATCH(10,'Registro'!$I$4:$I$1503,0))="","",INDEX('Registro'!$A$4:$A$1503,MATCH(10,'Registro'!$I$4:$I$1503,0))),"") | B25: =IFERROR(IF(INDEX('Registro'!$C$4:$C$1503,MATCH(10,'Registro'!$I$4:$I$1503,0))="","",INDEX('Registro'!$C$4:$C$1503,MATCH(10,'Registro'!$I$4:$I$1503,0))),"") | C25: =IFERROR(IF(INDEX('Registro'!$D$4:$D$1503,MATCH(10,'Registro'!$I$4:$I$1503,0))="","",INDEX('Registro'!$D$4:$D$1503,MATCH(10,'Registro'!$I$4:$I$1503,0))),"") | D25: =IFERROR(IF(INDEX('Registro'!$E$4:$E$1503,MATCH(10,'Registro'!$I$4:$I$1503,0))="","",INDEX('Registro'!$E$4:$E$1503,MATCH(10,'Registro'!$I$4:$I$1503,0))),"") | E25: =IFERROR(IF(INDEX('Registro'!$G$4:$G$1503,MATCH(10,'Registro'!$I$4:$I$1503,0))="","",INDEX('Registro'!$G$4:$G$1503,MATCH(10,'Registro'!$I$4:$I$1503,0))),"") | F25: =IF($A25="","",$B$8+SUMIFS('Registro'!$G$4:$G$1503,'Registro'!$B$4:$B$1503,$B$3,'Registro'!$A$4:$A$1503,"<="&$A25)) | G25: =IFERROR(IF(INDEX('Registro'!$F$4:$F$1503,MATCH(10,'Registro'!$I$4:$I$1503,0))="","",INDEX('Registro'!$F$4:$F$1503,MATCH(10,'Registro'!$I$4:$I$1503,0))),"")
A26: =IFERROR(IF(INDEX('Registro'!$A$4:$A$1503,MATCH(11,'Registro'!$I$4:$I$1503,0))="","",INDEX('Registro'!$A$4:$A$1503,MATCH(11,'Registro'!$I$4:$I$1503,0))),"") | B26: =IFERROR(IF(INDEX('Registro'!$C$4:$C$1503,MATCH(11,'Registro'!$I$4:$I$1503,0))="","",INDEX('Registro'!$C$4:$C$1503,MATCH(11,'Registro'!$I$4:$I$1503,0))),"") | C26: =IFERROR(IF(INDEX('Registro'!$D$4:$D$1503,MATCH(11,'Registro'!$I$4:$I$1503,0))="","",INDEX('Registro'!$D$4:$D$1503,MATCH(11,'Registro'!$I$4:$I$1503,0))),"") | D26: =IFERROR(IF(INDEX('Registro'!$E$4:$E$1503,MATCH(11,'Registro'!$I$4:$I$1503,0))="","",INDEX('Registro'!$E$4:$E$1503,MATCH(11,'Registro'!$I$4:$I$1503,0))),"") | E26: =IFERROR(IF(INDEX('Registro'!$G$4:$G$1503,MATCH(11,'Registro'!$I$4:$I$1503,0))="","",INDEX('Registro'!$G$4:$G$1503,MATCH(11,'Registro'!$I$4:$I$1503,0))),"") | F26: =IF($A26="","",$B$8+SUMIFS('Registro'!$G$4:$G$1503,'Registro'!$B$4:$B$1503,$B$3,'Registro'!$A$4:$A$1503,"<="&$A26)) | G26: =IFERROR(IF(INDEX('Registro'!$F$4:$F$1503,MATCH(11,'Registro'!$I$4:$I$1503,0))="","",INDEX('Registro'!$F$4:$F$1503,MATCH(11,'Registro'!$I$4:$I$1503,0))),"")
A27: =IFERROR(IF(INDEX('Registro'!$A$4:$A$1503,MATCH(12,'Registro'!$I$4:$I$1503,0))="","",INDEX('Registro'!$A$4:$A$1503,MATCH(12,'Registro'!$I$4:$I$1503,0))),"") | B27: =IFERROR(IF(INDEX('Registro'!$C$4:$C$1503,MATCH(12,'Registro'!$I$4:$I$1503,0))="","",INDEX('Registro'!$C$4:$C$1503,MATCH(12,'Registro'!$I$4:$I$1503,0))),"") | C27: =IFERROR(IF(INDEX('Registro'!$D$4:$D$1503,MATCH(12,'Registro'!$I$4:$I$1503,0))="","",INDEX('Registro'!$D$4:$D$1503,MATCH(12,'Registro'!$I$4:$I$1503,0))),"") | D27: =IFERROR(IF(INDEX('Registro'!$E$4:$E$1503,MATCH(12,'Registro'!$I$4:$I$1503,0))="","",INDEX('Registro'!$E$4:$E$1503,MATCH(12,'Registro'!$I$4:$I$1503,0))),"") | E27: =IFERROR(IF(INDEX('Registro'!$G$4:$G$1503,MATCH(12,'Registro'!$I$4:$I$1503,0))="","",INDEX('Registro'!$G$4:$G$1503,MATCH(12,'Registro'!$I$4:$I$1503,0))),"") | F27: =IF($A27="","",$B$8+SUMIFS('Registro'!$G$4:$G$1503,'Registro'!$B$4:$B$1503,$B$3,'Registro'!$A$4:$A$1503,"<="&$A27)) | G27: =IFERROR(IF(INDEX('Registro'!$F$4:$F$1503,MATCH(12,'Registro'!$I$4:$I$1503,0))="","",INDEX('Registro'!$F$4:$F$1503,MATCH(12,'Registro'!$I$4:$I$1503,0))),"")
A28: =IFERROR(IF(INDEX('Registro'!$A$4:$A$1503,MATCH(13,'Registro'!$I$4:$I$1503,0))="","",INDEX('Registro'!$A$4:$A$1503,MATCH(13,'Registro'!$I$4:$I$1503,0))),"") | B28: =IFERROR(IF(INDEX('Registro'!$C$4:$C$1503,MATCH(13,'Registro'!$I$4:$I$1503,0))="","",INDEX('Registro'!$C$4:$C$1503,MATCH(13,'Registro'!$I$4:$I$1503,0))),"") | C28: =IFERROR(IF(INDEX('Registro'!$D$4:$D$1503,MATCH(13,'Registro'!$I$4:$I$1503,0))="","",INDEX('Registro'!$D$4:$D$1503,MATCH(13,'Registro'!$I$4:$I$1503,0))),"") | D28: =IFERROR(IF(INDEX('Registro'!$E$4:$E$1503,MATCH(13,'Registro'!$I$4:$I$1503,0))="","",INDEX('Registro'!$E$4:$E$1503,MATCH(13,'Registro'!$I$4:$I$1503,0))),"") | E28: =IFERROR(IF(INDEX('Registro'!$G$4:$G$1503,MATCH(13,'Registro'!$I$4:$I$1503,0))="","",INDEX('Registro'!$G$4:$G$1503,MATCH(13,'Registro'!$I$4:$I$1503,0))),"") | F28: =IF($A28="","",$B$8+SUMIFS('Registro'!$G$4:$G$1503,'Registro'!$B$4:$B$1503,$B$3,'Registro'!$A$4:$A$1503,"<="&$A28)) | G28: =IFERROR(IF(INDEX('Registro'!$F$4:$F$1503,MATCH(13,'Registro'!$I$4:$I$1503,0))="","",INDEX('Registro'!$F$4:$F$1503,MATCH(13,'Registro'!$I$4:$I$1503,0))),"")
A29: =IFERROR(IF(INDEX('Registro'!$A$4:$A$1503,MATCH(14,'Registro'!$I$4:$I$1503,0))="","",INDEX('Registro'!$A$4:$A$1503,MATCH(14,'Registro'!$I$4:$I$1503,0))),"") | B29: =IFERROR(IF(INDEX('Registro'!$C$4:$C$1503,MATCH(14,'Registro'!$I$4:$I$1503,0))="","",INDEX('Registro'!$C$4:$C$1503,MATCH(14,'Registro'!$I$4:$I$1503,0))),"") | C29: =IFERROR(IF(INDEX('Registro'!$D$4:$D$1503,MATCH(14,'Registro'!$I$4:$I$1503,0))="","",INDEX('Registro'!$D$4:$D$1503,MATCH(14,'Registro'!$I$4:$I$1503,0))),"") | D29: =IFERROR(IF(INDEX('Registro'!$E$4:$E$1503,MATCH(14,'Registro'!$I$4:$I$1503,0))="","",INDEX('Registro'!$E$4:$E$1503,MATCH(14,'Registro'!$I$4:$I$1503,0))),"") | E29: =IFERROR(IF(INDEX('Registro'!$G$4:$G$1503,MATCH(14,'Registro'!$I$4:$I$1503,0))="","",INDEX('Registro'!$G$4:$G$1503,MATCH(14,'Registro'!$I$4:$I$1503,0))),"") | F29: =IF($A29="","",$B$8+SUMIFS('Registro'!$G$4:$G$1503,'Registro'!$B$4:$B$1503,$B$3,'Registro'!$A$4:$A$1503,"<="&$A29)) | G29: =IFERROR(IF(INDEX('Registro'!$F$4:$F$1503,MATCH(14,'Registro'!$I$4:$I$1503,0))="","",INDEX('Registro'!$F$4:$F$1503,MATCH(14,'Registro'!$I$4:$I$1503,0))),"")
A30: =IFERROR(IF(INDEX('Registro'!$A$4:$A$1503,MATCH(15,'Registro'!$I$4:$I$1503,0))="","",INDEX('Registro'!$A$4:$A$1503,MATCH(15,'Registro'!$I$4:$I$1503,0))),"") | B30: =IFERROR(IF(INDEX('Registro'!$C$4:$C$1503,MATCH(15,'Registro'!$I$4:$I$1503,0))="","",INDEX('Registro'!$C$4:$C$1503,MATCH(15,'Registro'!$I$4:$I$1503,0))),"") | C30: =IFERROR(IF(INDEX('Registro'!$D$4:$D$1503,MATCH(15,'Registro'!$I$4:$I$1503,0))="","",INDEX('Registro'!$D$4:$D$1503,MATCH(15,'Registro'!$I$4:$I$1503,0))),"") | D30: =IFERROR(IF(INDEX('Registro'!$E$4:$E$1503,MATCH(15,'Registro'!$I$4:$I$1503,0))="","",INDEX('Registro'!$E$4:$E$1503,MATCH(15,'Registro'!$I$4:$I$1503,0))),"") | E30: =IFERROR(IF(INDEX('Registro'!$G$4:$G$1503,MATCH(15,'Registro'!$I$4:$I$1503,0))="","",INDEX('Registro'!$G$4:$G$1503,MATCH(15,'Registro'!$I$4:$I$1503,0))),"") | F30: =IF($A30="","",$B$8+SUMIFS('Registro'!$G$4:$G$1503,'Registro'!$B$4:$B$1503,$B$3,'Registro'!$A$4:$A$1503,"<="&$A30)) | G30: =IFERROR(IF(INDEX('Registro'!$F$4:$F$1503,MATCH(15,'Registro'!$I$4:$I$1503,0))="","",INDEX('Registro'!$F$4:$F$1503,MATCH(15,'Registro'!$I$4:$I$1503,0))),"")
A31: =IFERROR(IF(INDEX('Registro'!$A$4:$A$1503,MATCH(16,'Registro'!$I$4:$I$1503,0))="","",INDEX('Registro'!$A$4:$A$1503,MATCH(16,'Registro'!$I$4:$I$1503,0))),"") | B31: =IFERROR(IF(INDEX('Registro'!$C$4:$C$1503,MATCH(16,'Registro'!$I$4:$I$1503,0))="","",INDEX('Registro'!$C$4:$C$1503,MATCH(16,'Registro'!$I$4:$I$1503,0))),"") | C31: =IFERROR(IF(INDEX('Registro'!$D$4:$D$1503,MATCH(16,'Registro'!$I$4:$I$1503,0))="","",INDEX('Registro'!$D$4:$D$1503,MATCH(16,'Registro'!$I$4:$I$1503,0))),"") | D31: =IFERROR(IF(INDEX('Registro'!$E$4:$E$1503,MATCH(16,'Registro'!$I$4:$I$1503,0))="","",INDEX('Registro'!$E$4:$E$1503,MATCH(16,'Registro'!$I$4:$I$1503,0))),"") | E31: =IFERROR(IF(INDEX('Registro'!$G$4:$G$1503,MATCH(16,'Registro'!$I$4:$I$1503,0))="","",INDEX('Registro'!$G$4:$G$1503,MATCH(16,'Registro'!$I$4:$I$1503,0))),"") | F31: =IF($A31="","",$B$8+SUMIFS('Registro'!$G$4:$G$1503,'Registro'!$B$4:$B$1503,$B$3,'Registro'!$A$4:$A$1503,"<="&$A31)) | G31: =IFERROR(IF(INDEX('Registro'!$F$4:$F$1503,MATCH(16,'Registro'!$I$4:$I$1503,0))="","",INDEX('Registro'!$F$4:$F$1503,MATCH(16,'Registro'!$I$4:$I$1503,0))),"")
A32: =IFERROR(IF(INDEX('Registro'!$A$4:$A$1503,MATCH(17,'Registro'!$I$4:$I$1503,0))="","",INDEX('Registro'!$A$4:$A$1503,MATCH(17,'Registro'!$I$4:$I$1503,0))),"") | B32: =IFERROR(IF(INDEX('Registro'!$C$4:$C$1503,MATCH(17,'Registro'!$I$4:$I$1503,0))="","",INDEX('Registro'!$C$4:$C$1503,MATCH(17,'Registro'!$I$4:$I$1503,0))),"") | C32: =IFERROR(IF(INDEX('Registro'!$D$4:$D$1503,MATCH(17,'Registro'!$I$4:$I$1503,0))="","",INDEX('Registro'!$D$4:$D$1503,MATCH(17,'Registro'!$I$4:$I$1503,0))),"") | D32: =IFERROR(IF(INDEX('Registro'!$E$4:$E$1503,MATCH(17,'Registro'!$I$4:$I$1503,0))="","",INDEX('Registro'!$E$4:$E$1503,MATCH(17,'Registro'!$I$4:$I$1503,0))),"") | E32: =IFERROR(IF(INDEX('Registro'!$G$4:$G$1503,MATCH(17,'Registro'!$I$4:$I$1503,0))="","",INDEX('Registro'!$G$4:$G$1503,MATCH(17,'Registro'!$I$4:$I$1503,0))),"") | F32: =IF($A32="","",$B$8+SUMIFS('Registro'!$G$4:$G$1503,'Registro'!$B$4:$B$1503,$B$3,'Registro'!$A$4:$A$1503,"<="&$A32)) | G32: =IFERROR(IF(INDEX('Registro'!$F$4:$F$1503,MATCH(17,'Registro'!$I$4:$I$1503,0))="","",INDEX('Registro'!$F$4:$F$1503,MATCH(17,'Registro'!$I$4:$I$1503,0))),"")
A33: =IFERROR(IF(INDEX('Registro'!$A$4:$A$1503,MATCH(18,'Registro'!$I$4:$I$1503,0))="","",INDEX('Registro'!$A$4:$A$1503,MATCH(18,'Registro'!$I$4:$I$1503,0))),"") | B33: =IFERROR(IF(INDEX('Registro'!$C$4:$C$1503,MATCH(18,'Registro'!$I$4:$I$1503,0))="","",INDEX('Registro'!$C$4:$C$1503,MATCH(18,'Registro'!$I$4:$I$1503,0))),"") | C33: =IFERROR(IF(INDEX('Registro'!$D$4:$D$1503,MATCH(18,'Registro'!$I$4:$I$1503,0))="","",INDEX('Registro'!$D$4:$D$1503,MATCH(18,'Registro'!$I$4:$I$1503,0))),"") | D33: =IFERROR(IF(INDEX('Registro'!$E$4:$E$1503,MATCH(18,'Registro'!$I$4:$I$1503,0))="","",INDEX('Registro'!$E$4:$E$1503,MATCH(18,'Registro'!$I$4:$I$1503,0))),"") | E33: =IFERROR(IF(INDEX('Registro'!$G$4:$G$1503,MATCH(18,'Registro'!$I$4:$I$1503,0))="","",INDEX('Registro'!$G$4:$G$1503,MATCH(18,'Registro'!$I$4:$I$1503,0))),"") | F33: =IF($A33="","",$B$8+SUMIFS('Registro'!$G$4:$G$1503,'Registro'!$B$4:$B$1503,$B$3,'Registro'!$A$4:$A$1503,"<="&$A33)) | G33: =IFERROR(IF(INDEX('Registro'!$F$4:$F$1503,MATCH(18,'Registro'!$I$4:$I$1503,0))="","",INDEX('Registro'!$F$4:$F$1503,MATCH(18,'Registro'!$I$4:$I$1503,0))),"")
A34: =IFERROR(IF(INDEX('Registro'!$A$4:$A$1503,MATCH(19,'Registro'!$I$4:$I$1503,0))="","",INDEX('Registro'!$A$4:$A$1503,MATCH(19,'Registro'!$I$4:$I$1503,0))),"") | B34: =IFERROR(IF(INDEX('Registro'!$C$4:$C$1503,MATCH(19,'Registro'!$I$4:$I$1503,0))="","",INDEX('Registro'!$C$4:$C$1503,MATCH(19,'Registro'!$I$4:$I$1503,0))),"") | C34: =IFERROR(IF(INDEX('Registro'!$D$4:$D$1503,MATCH(19,'Registro'!$I$4:$I$1503,0))="","",INDEX('Registro'!$D$4:$D$1503,MATCH(19,'Registro'!$I$4:$I$1503,0))),"") | D34: =IFERROR(IF(INDEX('Registro'!$E$4:$E$1503,MATCH(19,'Registro'!$I$4:$I$1503,0))="","",INDEX('Registro'!$E$4:$E$1503,MATCH(19,'Registro'!$I$4:$I$1503,0))),"") | E34: =IFERROR(IF(INDEX('Registro'!$G$4:$G$1503,MATCH(19,'Registro'!$I$4:$I$1503,0))="","",INDEX('Registro'!$G$4:$G$1503,MATCH(19,'Registro'!$I$4:$I$1503,0))),"") | F34: =IF($A34="","",$B$8+SUMIFS('Registro'!$G$4:$G$1503,'Registro'!$B$4:$B$1503,$B$3,'Registro'!$A$4:$A$1503,"<="&$A34)) | G34: =IFERROR(IF(INDEX('Registro'!$F$4:$F$1503,MATCH(19,'Registro'!$I$4:$I$1503,0))="","",INDEX('Registro'!$F$4:$F$1503,MATCH(19,'Registro'!$I$4:$I$1503,0))),"")
A35: =IFERROR(IF(INDEX('Registro'!$A$4:$A$1503,MATCH(20,'Registro'!$I$4:$I$1503,0))="","",INDEX('Registro'!$A$4:$A$1503,MATCH(20,'Registro'!$I$4:$I$1503,0))),"") | B35: =IFERROR(IF(INDEX('Registro'!$C$4:$C$1503,MATCH(20,'Registro'!$I$4:$I$1503,0))="","",INDEX('Registro'!$C$4:$C$1503,MATCH(20,'Registro'!$I$4:$I$1503,0))),"") | C35: =IFERROR(IF(INDEX('Registro'!$D$4:$D$1503,MATCH(20,'Registro'!$I$4:$I$1503,0))="","",INDEX('Registro'!$D$4:$D$1503,MATCH(20,'Registro'!$I$4:$I$1503,0))),"") | D35: =IFERROR(IF(INDEX('Registro'!$E$4:$E$1503,MATCH(20,'Registro'!$I$4:$I$1503,0))="","",INDEX('Registro'!$E$4:$E$1503,MATCH(20,'Registro'!$I$4:$I$1503,0))),"") | E35: =IFERROR(IF(INDEX('Registro'!$G$4:$G$1503,MATCH(20,'Registro'!$I$4:$I$1503,0))="","",INDEX('Registro'!$G$4:$G$1503,MATCH(20,'Registro'!$I$4:$I$1503,0))),"") | F35: =IF($A35="","",$B$8+SUMIFS('Registro'!$G$4:$G$1503,'Registro'!$B$4:$B$1503,$B$3,'Registro'!$A$4:$A$1503,"<="&$A35)) | G35: =IFERROR(IF(INDEX('Registro'!$F$4:$F$1503,MATCH(20,'Registro'!$I$4:$I$1503,0))="","",INDEX('Registro'!$F$4:$F$1503,MATCH(20,'Registro'!$I$4:$I$1503,0))),"")
A36: =IFERROR(IF(INDEX('Registro'!$A$4:$A$1503,MATCH(21,'Registro'!$I$4:$I$1503,0))="","",INDEX('Registro'!$A$4:$A$1503,MATCH(21,'Registro'!$I$4:$I$1503,0))),"") | B36: =IFERROR(IF(INDEX('Registro'!$C$4:$C$1503,MATCH(21,'Registro'!$I$4:$I$1503,0))="","",INDEX('Registro'!$C$4:$C$1503,MATCH(21,'Registro'!$I$4:$I$1503,0))),"") | C36: =IFERROR(IF(INDEX('Registro'!$D$4:$D$1503,MATCH(21,'Registro'!$I$4:$I$1503,0))="","",INDEX('Registro'!$D$4:$D$1503,MATCH(21,'Registro'!$I$4:$I$1503,0))),"") | D36: =IFERROR(IF(INDEX('Registro'!$E$4:$E$1503,MATCH(21,'Registro'!$I$4:$I$1503,0))="","",INDEX('Registro'!$E$4:$E$1503,MATCH(21,'Registro'!$I$4:$I$1503,0))),"") | E36: =IFERROR(IF(INDEX('Registro'!$G$4:$G$1503,MATCH(21,'Registro'!$I$4:$I$1503,0))="","",INDEX('Registro'!$G$4:$G$1503,MATCH(21,'Registro'!$I$4:$I$1503,0))),"") | F36: =IF($A36="","",$B$8+SUMIFS('Registro'!$G$4:$G$1503,'Registro'!$B$4:$B$1503,$B$3,'Registro'!$A$4:$A$1503,"<="&$A36)) | G36: =IFERROR(IF(INDEX('Registro'!$F$4:$F$1503,MATCH(21,'Registro'!$I$4:$I$1503,0))="","",INDEX('Registro'!$F$4:$F$1503,MATCH(21,'Registro'!$I$4:$I$1503,0))),"")
A37: =IFERROR(IF(INDEX('Registro'!$A$4:$A$1503,MATCH(22,'Registro'!$I$4:$I$1503,0))="","",INDEX('Registro'!$A$4:$A$1503,MATCH(22,'Registro'!$I$4:$I$1503,0))),"") | B37: =IFERROR(IF(INDEX('Registro'!$C$4:$C$1503,MATCH(22,'Registro'!$I$4:$I$1503,0))="","",INDEX('Registro'!$C$4:$C$1503,MATCH(22,'Registro'!$I$4:$I$1503,0))),"") | C37: =IFERROR(IF(INDEX('Registro'!$D$4:$D$1503,MATCH(22,'Registro'!$I$4:$I$1503,0))="","",INDEX('Registro'!$D$4:$D$1503,MATCH(22,'Registro'!$I$4:$I$1503,0))),"") | D37: =IFERROR(IF(INDEX('Registro'!$E$4:$E$1503,MATCH(22,'Registro'!$I$4:$I$1503,0))="","",INDEX('Registro'!$E$4:$E$1503,MATCH(22,'Registro'!$I$4:$I$1503,0))),"") | E37: =IFERROR(IF(INDEX('Registro'!$G$4:$G$1503,MATCH(22,'Registro'!$I$4:$I$1503,0))="","",INDEX('Registro'!$G$4:$G$1503,MATCH(22,'Registro'!$I$4:$I$1503,0))),"") | F37: =IF($A37="","",$B$8+SUMIFS('Registro'!$G$4:$G$1503,'Registro'!$B$4:$B$1503,$B$3,'Registro'!$A$4:$A$1503,"<="&$A37)) | G37: =IFERROR(IF(INDEX('Registro'!$F$4:$F$1503,MATCH(22,'Registro'!$I$4:$I$1503,0))="","",INDEX('Registro'!$F$4:$F$1503,MATCH(22,'Registro'!$I$4:$I$1503,0))),"")
A38: =IFERROR(IF(INDEX('Registro'!$A$4:$A$1503,MATCH(23,'Registro'!$I$4:$I$1503,0))="","",INDEX('Registro'!$A$4:$A$1503,MATCH(23,'Registro'!$I$4:$I$1503,0))),"") | B38: =IFERROR(IF(INDEX('Registro'!$C$4:$C$1503,MATCH(23,'Registro'!$I$4:$I$1503,0))="","",INDEX('Registro'!$C$4:$C$1503,MATCH(23,'Registro'!$I$4:$I$1503,0))),"") | C38: =IFERROR(IF(INDEX('Registro'!$D$4:$D$1503,MATCH(23,'Registro'!$I$4:$I$1503,0))="","",INDEX('Registro'!$D$4:$D$1503,MATCH(23,'Registro'!$I$4:$I$1503,0))),"") | D38: =IFERROR(IF(INDEX('Registro'!$E$4:$E$1503,MATCH(23,'Registro'!$I$4:$I$1503,0))="","",INDEX('Registro'!$E$4:$E$1503,MATCH(23,'Registro'!$I$4:$I$1503,0))),"") | E38: =IFERROR(IF(INDEX('Registro'!$G$4:$G$1503,MATCH(23,'Registro'!$I$4:$I$1503,0))="","",INDEX('Registro'!$G$4:$G$1503,MATCH(23,'Registro'!$I$4:$I$1503,0))),"") | F38: =IF($A38="","",$B$8+SUMIFS('Registro'!$G$4:$G$1503,'Registro'!$B$4:$B$1503,$B$3,'Registro'!$A$4:$A$1503,"<="&$A38)) | G38: =IFERROR(IF(INDEX('Registro'!$F$4:$F$1503,MATCH(23,'Registro'!$I$4:$I$1503,0))="","",INDEX('Registro'!$F$4:$F$1503,MATCH(23,'Registro'!$I$4:$I$1503,0))),"")
A39: =IFERROR(IF(INDEX('Registro'!$A$4:$A$1503,MATCH(24,'Registro'!$I$4:$I$1503,0))="","",INDEX('Registro'!$A$4:$A$1503,MATCH(24,'Registro'!$I$4:$I$1503,0))),"") | B39: =IFERROR(IF(INDEX('Registro'!$C$4:$C$1503,MATCH(24,'Registro'!$I$4:$I$1503,0))="","",INDEX('Registro'!$C$4:$C$1503,MATCH(24,'Registro'!$I$4:$I$1503,0))),"") | C39: =IFERROR(IF(INDEX('Registro'!$D$4:$D$1503,MATCH(24,'Registro'!$I$4:$I$1503,0))="","",INDEX('Registro'!$D$4:$D$1503,MATCH(24,'Registro'!$I$4:$I$1503,0))),"") | D39: =IFERROR(IF(INDEX('Registro'!$E$4:$E$1503,MATCH(24,'Registro'!$I$4:$I$1503,0))="","",INDEX('Registro'!$E$4:$E$1503,MATCH(24,'Registro'!$I$4:$I$1503,0))),"") | E39: =IFERROR(IF(INDEX('Registro'!$G$4:$G$1503,MATCH(24,'Registro'!$I$4:$I$1503,0))="","",INDEX('Registro'!$G$4:$G$1503,MATCH(24,'Registro'!$I$4:$I$1503,0))),"") | F39: =IF($A39="","",$B$8+SUMIFS('Registro'!$G$4:$G$1503,'Registro'!$B$4:$B$1503,$B$3,'Registro'!$A$4:$A$1503,"<="&$A39)) | G39: =IFERROR(IF(INDEX('Registro'!$F$4:$F$1503,MATCH(24,'Registro'!$I$4:$I$1503,0))="","",INDEX('Registro'!$F$4:$F$1503,MATCH(24,'Registro'!$I$4:$I$1503,0))),"")
A40: =IFERROR(IF(INDEX('Registro'!$A$4:$A$1503,MATCH(25,'Registro'!$I$4:$I$1503,0))="","",INDEX('Registro'!$A$4:$A$1503,MATCH(25,'Registro'!$I$4:$I$1503,0))),"") | B40: =IFERROR(IF(INDEX('Registro'!$C$4:$C$1503,MATCH(25,'Registro'!$I$4:$I$1503,0))="","",INDEX('Registro'!$C$4:$C$1503,MATCH(25,'Registro'!$I$4:$I$1503,0))),"") | C40: =IFERROR(IF(INDEX('Registro'!$D$4:$D$1503,MATCH(25,'Registro'!$I$4:$I$1503,0))="","",INDEX('Registro'!$D$4:$D$1503,MATCH(25,'Registro'!$I$4:$I$1503,0))),"") | D40: =IFERROR(IF(INDEX('Registro'!$E$4:$E$1503,MATCH(25,'Registro'!$I$4:$I$1503,0))="","",INDEX('Registro'!$E$4:$E$1503,MATCH(25,'Registro'!$I$4:$I$1503,0))),"") | E40: =IFERROR(IF(INDEX('Registro'!$G$4:$G$1503,MATCH(25,'Registro'!$I$4:$I$1503,0))="","",INDEX('Registro'!$G$4:$G$1503,MATCH(25,'Registro'!$I$4:$I$1503,0))),"") | F40: =IF($A40="","",$B$8+SUMIFS('Registro'!$G$4:$G$1503,'Registro'!$B$4:$B$1503,$B$3,'Registro'!$A$4:$A$1503,"<="&$A40)) | G40: =IFERROR(IF(INDEX('Registro'!$F$4:$F$1503,MATCH(25,'Registro'!$I$4:$I$1503,0))="","",INDEX('Registro'!$F$4:$F$1503,MATCH(25,'Registro'!$I$4:$I$1503,0))),"")
A41: =IFERROR(IF(INDEX('Registro'!$A$4:$A$1503,MATCH(26,'Registro'!$I$4:$I$1503,0))="","",INDEX('Registro'!$A$4:$A$1503,MATCH(26,'Registro'!$I$4:$I$1503,0))),"") | B41: =IFERROR(IF(INDEX('Registro'!$C$4:$C$1503,MATCH(26,'Registro'!$I$4:$I$1503,0))="","",INDEX('Registro'!$C$4:$C$1503,MATCH(26,'Registro'!$I$4:$I$1503,0))),"") | C41: =IFERROR(IF(INDEX('Registro'!$D$4:$D$1503,MATCH(26,'Registro'!$I$4:$I$1503,0))="","",INDEX('Registro'!$D$4:$D$1503,MATCH(26,'Registro'!$I$4:$I$1503,0))),"") | D41: =IFERROR(IF(INDEX('Registro'!$E$4:$E$1503,MATCH(26,'Registro'!$I$4:$I$1503,0))="","",INDEX('Registro'!$E$4:$E$1503,MATCH(26,'Registro'!$I$4:$I$1503,0))),"") | E41: =IFERROR(IF(INDEX('Registro'!$G$4:$G$1503,MATCH(26,'Registro'!$I$4:$I$1503,0))="","",INDEX('Registro'!$G$4:$G$1503,MATCH(26,'Registro'!$I$4:$I$1503,0))),"") | F41: =IF($A41="","",$B$8+SUMIFS('Registro'!$G$4:$G$1503,'Registro'!$B$4:$B$1503,$B$3,'Registro'!$A$4:$A$1503,"<="&$A41)) | G41: =IFERROR(IF(INDEX('Registro'!$F$4:$F$1503,MATCH(26,'Registro'!$I$4:$I$1503,0))="","",INDEX('Registro'!$F$4:$F$1503,MATCH(26,'Registro'!$I$4:$I$1503,0))),"")
A42: =IFERROR(IF(INDEX('Registro'!$A$4:$A$1503,MATCH(27,'Registro'!$I$4:$I$1503,0))="","",INDEX('Registro'!$A$4:$A$1503,MATCH(27,'Registro'!$I$4:$I$1503,0))),"") | B42: =IFERROR(IF(INDEX('Registro'!$C$4:$C$1503,MATCH(27,'Registro'!$I$4:$I$1503,0))="","",INDEX('Registro'!$C$4:$C$1503,MATCH(27,'Registro'!$I$4:$I$1503,0))),"") | C42: =IFERROR(IF(INDEX('Registro'!$D$4:$D$1503,MATCH(27,'Registro'!$I$4:$I$1503,0))="","",INDEX('Registro'!$D$4:$D$1503,MATCH(27,'Registro'!$I$4:$I$1503,0))),"") | D42: =IFERROR(IF(INDEX('Registro'!$E$4:$E$1503,MATCH(27,'Registro'!$I$4:$I$1503,0))="","",INDEX('Registro'!$E$4:$E$1503,MATCH(27,'Registro'!$I$4:$I$1503,0))),"") | E42: =IFERROR(IF(INDEX('Registro'!$G$4:$G$1503,MATCH(27,'Registro'!$I$4:$I$1503,0))="","",INDEX('Registro'!$G$4:$G$1503,MATCH(27,'Registro'!$I$4:$I$1503,0))),"") | F42: =IF($A42="","",$B$8+SUMIFS('Registro'!$G$4:$G$1503,'Registro'!$B$4:$B$1503,$B$3,'Registro'!$A$4:$A$1503,"<="&$A42)) | G42: =IFERROR(IF(INDEX('Registro'!$F$4:$F$1503,MATCH(27,'Registro'!$I$4:$I$1503,0))="","",INDEX('Registro'!$F$4:$F$1503,MATCH(27,'Registro'!$I$4:$I$1503,0))),"")
A43: =IFERROR(IF(INDEX('Registro'!$A$4:$A$1503,MATCH(28,'Registro'!$I$4:$I$1503,0))="","",INDEX('Registro'!$A$4:$A$1503,MATCH(28,'Registro'!$I$4:$I$1503,0))),"") | B43: =IFERROR(IF(INDEX('Registro'!$C$4:$C$1503,MATCH(28,'Registro'!$I$4:$I$1503,0))="","",INDEX('Registro'!$C$4:$C$1503,MATCH(28,'Registro'!$I$4:$I$1503,0))),"") | C43: =IFERROR(IF(INDEX('Registro'!$D$4:$D$1503,MATCH(28,'Registro'!$I$4:$I$1503,0))="","",INDEX('Registro'!$D$4:$D$1503,MATCH(28,'Registro'!$I$4:$I$1503,0))),"") | D43: =IFERROR(IF(INDEX('Registro'!$E$4:$E$1503,MATCH(28,'Registro'!$I$4:$I$1503,0))="","",INDEX('Registro'!$E$4:$E$1503,MATCH(28,'Registro'!$I$4:$I$1503,0))),"") | E43: =IFERROR(IF(INDEX('Registro'!$G$4:$G$1503,MATCH(28,'Registro'!$I$4:$I$1503,0))="","",INDEX('Registro'!$G$4:$G$1503,MATCH(28,'Registro'!$I$4:$I$1503,0))),"") | F43: =IF($A43="","",$B$8+SUMIFS('Registro'!$G$4:$G$1503,'Registro'!$B$4:$B$1503,$B$3,'Registro'!$A$4:$A$1503,"<="&$A43)) | G43: =IFERROR(IF(INDEX('Registro'!$F$4:$F$1503,MATCH(28,'Registro'!$I$4:$I$1503,0))="","",INDEX('Registro'!$F$4:$F$1503,MATCH(28,'Registro'!$I$4:$I$1503,0))),"")
...

Sheet Registro
A1: Registro
A2: Una fila por movimiento. Horas o días: completá el que uses.
A3: Fecha | B3: Persona | C3: Tipo | D3: Horas | E3: Días | F3: Nota | G3: Horas acreditadas | H3: Días de vacaciones | I3: #
A4: 46268 | B4: Lucía Fernández | C4: Horas extra trabajadas | D4: 3 | F4: Cierre de mes | G4: =IFERROR(IF(OR($B4="",$C4=""),"",IF(MATCH($C4,'Ajustes'!$A$5:$A$8,0)<=2,$D4*INDEX('Ajustes'!$C$5:$C$6,MATCH($C4,'Ajustes'!$A$5:$A$8,0)),IF(MATCH($C4,'Ajustes'!$A$5:$A$8,0)=3,-($D4+$E4*INDEX('Equipo'!$B$5:$B$29,MATCH($B4,'Equipo'!$A$5:$A$29,0))),0))),"") | H4: =IFERROR(IF(OR($B4="",$C4=""),"",IF(MATCH($C4,'Ajustes'!$A$5:$A$8,0)=4,$D4/INDEX('Equipo'!$B$5:$B$29,MATCH($B4,'Equipo'!$A$5:$A$29,0))+$E4,0)),"") | I4: =IF($B4='Perfil'!$B$3,COUNTIF($B$4:$B4,'Perfil'!$B$3),"") | K4: ← filas de ejemplo: pisalas o borralas
A5: 46275 | B5: Lucía Fernández | C5: Horas extra trabajadas | D5: 2 | G5: =IFERROR(IF(OR($B5="",$C5=""),"",IF(MATCH($C5,'Ajustes'!$A$5:$A$8,0)<=2,$D5*INDEX('Ajustes'!$C$5:$C$6,MATCH($C5,'Ajustes'!$A$5:$A$8,0)),IF(MATCH($C5,'Ajustes'!$A$5:$A$8,0)=3,-($D5+$E5*INDEX('Equipo'!$B$5:$B$29,MATCH($B5,'Equipo'!$A$5:$A$29,0))),0))),"") | H5: =IFERROR(IF(OR($B5="",$C5=""),"",IF(MATCH($C5,'Ajustes'!$A$5:$A$8,0)=4,$D5/INDEX('Equipo'!$B$5:$B$29,MATCH($B5,'Equipo'!$A$5:$A$29,0))+$E5,0)),"") | I5: =IF($B5='Perfil'!$B$3,COUNTIF($B$4:$B5,'Perfil'!$B$3),"")
A6: 46279 | B6: Martín Gómez | C6: Trabajo en feriado / franco | D6: 4 | F6: Trabajó en feriado | G6: =IFERROR(IF(OR($B6="",$C6=""),"",IF(MATCH($C6,'Ajustes'!$A$5:$A$8,0)<=2,$D6*INDEX('Ajustes'!$C$5:$C$6,MATCH($C6,'Ajustes'!$A$5:$A$8,0)),IF(MATCH($C6,'Ajustes'!$A$5:$A$8,0)=3,-($D6+$E6*INDEX('Equipo'!$B$5:$B$29,MATCH($B6,'Equipo'!$A$5:$A$29,0))),0))),"") | H6: =IFERROR(IF(OR($B6="",$C6=""),"",IF(MATCH($C6,'Ajustes'!$A$5:$A$8,0)=4,$D6/INDEX('Equipo'!$B$5:$B$29,MATCH($B6,'Equipo'!$A$5:$A$29,0))+$E6,0)),"") | I6: =IF($B6='Perfil'!$B$3,COUNTIF($B$4:$B6,'Perfil'!$B$3),"")
A7: 46284 | B7: Martín Gómez | C7: Horas extra trabajadas | D7: 3 | F7: Inventario | G7: =IFERROR(IF(OR($B7="",$C7=""),"",IF(MATCH($C7,'Ajustes'!$A$5:$A$8,0)<=2,$D7*INDEX('Ajustes'!$C$5:$C$6,MATCH($C7,'Ajustes'!$A$5:$A$8,0)),IF(MATCH($C7,'Ajustes'!$A$5:$A$8,0)=3,-($D7+$E7*INDEX('Equipo'!$B$5:$B$29,MATCH($B7,'Equipo'!$A$5:$A$29,0))),0))),"") | H7: =IFERROR(IF(OR($B7="",$C7=""),"",IF(MATCH($C7,'Ajustes'!$A$5:$A$8,0)=4,$D7/INDEX('Equipo'!$B$5:$B$29,MATCH($B7,'Equipo'!$A$5:$A$29,0))+$E7,0)),"") | I7: =IF($B7='Perfil'!$B$3,COUNTIF($B$4:$B7,'Perfil'!$B$3),"")
A8: 46286 | B8: Lucía Fernández | C8: Franco compensatorio tomado | D8: 3 | F8: Tarde libre | G8: =IFERROR(IF(OR($B8="",$C8=""),"",IF(MATCH($C8,'Ajustes'!$A$5:$A$8,0)<=2,$D8*INDEX('Ajustes'!$C$5:$C$6,MATCH($C8,'Ajustes'!$A$5:$A$8,0)),IF(MATCH($C8,'Ajustes'!$A$5:$A$8,0)=3,-($D8+$E8*INDEX('Equipo'!$B$5:$B$29,MATCH($B8,'Equipo'!$A$5:$A$29,0))),0))),"") | H8: =IFERROR(IF(OR($B8="",$C8=""),"",IF(MATCH($C8,'Ajustes'!$A$5:$A$8,0)=4,$D8/INDEX('Equipo'!$B$5:$B$29,MATCH($B8,'Equipo'!$A$5:$A$29,0))+$E8,0)),"") | I8: =IF($B8='Perfil'!$B$3,COUNTIF($B$4:$B8,'Perfil'!$B$3),"")
A9: 46291 | B9: Sofía Ruiz | C9: Horas extra trabajadas | D9: 3 | G9: =IFERROR(IF(OR($B9="",$C9=""),"",IF(MATCH($C9,'Ajustes'!$A$5:$A$8,0)<=2,$D9*INDEX('Ajustes'!$C$5:$C$6,MATCH($C9,'Ajustes'!$A$5:$A$8,0)),IF(MATCH($C9,'Ajustes'!$A$5:$A$8,0)=3,-($D9+$E9*INDEX('Equipo'!$B$5:$B$29,MATCH($B9,'Equipo'!$A$5:$A$29,0))),0))),"") | H9: =IFERROR(IF(OR($B9="",$C9=""),"",IF(MATCH($C9,'Ajustes'!$A$5:$A$8,0)=4,$D9/INDEX('Equipo'!$B$5:$B$29,MATCH($B9,'Equipo'!$A$5:$A$29,0))+$E9,0)),"") | I9: =IF($B9='Perfil'!$B$3,COUNTIF($B$4:$B9,'Perfil'!$B$3),"")
A10: 46297 | B10: Martín Gómez | C10: Franco compensatorio tomado | E10: 0.5 | F10: Medio día | G10: =IFERROR(IF(OR($B10="",$C10=""),"",IF(MATCH($C10,'Ajustes'!$A$5:$A$8,0)<=2,$D10*INDEX('Ajustes'!$C$5:$C$6,MATCH($C10,'Ajustes'!$A$5:$A$8,0)),IF(MATCH($C10,'Ajustes'!$A$5:$A$8,0)=3,-($D10+$E10*INDEX('Equipo'!$B$5:$B$29,MATCH($B10,'Equipo'!$A$5:$A$29,0))),0))),"") | H10: =IFERROR(IF(OR($B10="",$C10=""),"",IF(MATCH($C10,'Ajustes'!$A$5:$A$8,0)=4,$D10/INDEX('Equipo'!$B$5:$B$29,MATCH($B10,'Equipo'!$A$5:$A$29,0))+$E10,0)),"") | I10: =IF($B10='Perfil'!$B$3,COUNTIF($B$4:$B10,'Perfil'!$B$3),"")
A11: 46307 | B11: Sofía Ruiz | C11: Horas extra trabajadas | D11: 2 | G11: =IFERROR(IF(OR($B11="",$C11=""),"",IF(MATCH($C11,'Ajustes'!$A$5:$A$8,0)<=2,$D11*INDEX('Ajustes'!$C$5:$C$6,MATCH($C11,'Ajustes'!$A$5:$A$8,0)),IF(MATCH($C11,'Ajustes'!$A$5:$A$8,0)=3,-($D11+$E11*INDEX('Equipo'!$B$5:$B$29,MATCH($B11,'Equipo'!$A$5:$A$29,0))),0))),"") | H11: =IFERROR(IF(OR($B11="",$C11=""),"",IF(MATCH($C11,'Ajustes'!$A$5:$A$8,0)=4,$D11/INDEX('Equipo'!$B$5:$B$29,MATCH($B11,'Equipo'!$A$5:$A$29,0))+$E11,0)),"") | I11: =IF($B11='Perfil'!$B$3,COUNTIF($B$4:$B11,'Perfil'!$B$3),"")
A12: 46314 | B12: Lucía Fernández | C12: Vacaciones / licencia oficial | E12: 5 | F12: Receso | G12: =IFERROR(IF(OR($B12="",$C12=""),"",IF(MATCH($C12,'Ajustes'!$A$5:$A$8,0)<=2,$D12*INDEX('Ajustes'!$C$5:$C$6,MATCH($C12,'Ajustes'!$A$5:$A$8,0)),IF(MATCH($C12,'Ajustes'!$A$5:$A$8,0)=3,-($D12+$E12*INDEX('Equipo'!$B$5:$B$29,MATCH($B12,'Equipo'!$A$5:$A$29,0))),0))),"") | H12: =IFERROR(IF(OR($B12="",$C12=""),"",IF(MATCH($C12,'Ajustes'!$A$5:$A$8,0)=4,$D12/INDEX('Equipo'!$B$5:$B$29,MATCH($B12,'Equipo'!$A$5:$A$29,0))+$E12,0)),"") | I12: =IF($B12='Perfil'!$B$3,COUNTIF($B$4:$B12,'Perfil'!$B$3),"")
A13: 46317 | B13: Martín Gómez | C13: Horas extra trabajadas | D13: 3.5 | G13: =IFERROR(IF(OR($B13="",$C13=""),"",IF(MATCH($C13,'Ajustes'!$A$5:$A$8,0)<=2,$D13*INDEX('Ajustes'!$C$5:$C$6,MATCH($C13,'Ajustes'!$A$5:$A$8,0)),IF(MATCH($C13,'Ajustes'!$A$5:$A$8,0)=3,-($D13+$E13*INDEX('Equipo'!$B$5:$B$29,MATCH($B13,'Equipo'!$A$5:$A$29,0))),0))),"") | H13: =IFERROR(IF(OR($B13="",$C13=""),"",IF(MATCH($C13,'Ajustes'!$A$5:$A$8,0)=4,$D13/INDEX('Equipo'!$B$5:$B$29,MATCH($B13,'Equipo'!$A$5:$A$29,0))+$E13,0)),"") | I13: =IF($B13='Perfil'!$B$3,COUNTIF($B$4:$B13,'Perfil'!$B$3),"")
G14: =IFERROR(IF(OR($B14="",$C14=""),"",IF(MATCH($C14,'Ajustes'!$A$5:$A$8,0)<=2,$D14*INDEX('Ajustes'!$C$5:$C$6,MATCH($C14,'Ajustes'!$A$5:$A$8,0)),IF(MATCH($C14,'Ajustes'!$A$5:$A$8,0)=3,-($D14+$E14*INDEX('Equipo'!$B$5:$B$29,MATCH($B14,'Equipo'!$A$5:$A$29,0))),0))),"") | H14: =IFERROR(IF(OR($B14="",$C14=""),"",IF(MATCH($C14,'Ajustes'!$A$5:$A$8,0)=4,$D14/INDEX('Equipo'!$B$5:$B$29,MATCH($B14,'Equipo'!$A$5:$A$29,0))+$E14,0)),"") | I14: =IF($B14='Perfil'!$B$3,COUNTIF($B$4:$B14,'Perfil'!$B$3),"")
G15: =IFERROR(IF(OR($B15="",$C15=""),"",IF(MATCH($C15,'Ajustes'!$A$5:$A$8,0)<=2,$D15*INDEX('Ajustes'!$C$5:$C$6,MATCH($C15,'Ajustes'!$A$5:$A$8,0)),IF(MATCH($C15,'Ajustes'!$A$5:$A$8,0)=3,-($D15+$E15*INDEX('Equipo'!$B$5:$B$29,MATCH($B15,'Equipo'!$A$5:$A$29,0))),0))),"") | H15: =IFERROR(IF(OR($B15="",$C15=""),"",IF(MATCH($C15,'Ajustes'!$A$5:$A$8,0)=4,$D15/INDEX('Equipo'!$B$5:$B$29,MATCH($B15,'Equipo'!$A$5:$A$29,0))+$E15,0)),"") | I15: =IF($B15='Perfil'!$B$3,COUNTIF($B$4:$B15,'Perfil'!$B$3),"")
G16: =IFERROR(IF(OR($B16="",$C16=""),"",IF(MATCH($C16,'Ajustes'!$A$5:$A$8,0)<=2,$D16*INDEX('Ajustes'!$C$5:$C$6,MATCH($C16,'Ajustes'!$A$5:$A$8,0)),IF(MATCH($C16,'Ajustes'!$A$5:$A$8,0)=3,-($D16+$E16*INDEX('Equipo'!$B$5:$B$29,MATCH($B16,'Equipo'!$A$5:$A$29,0))),0))),"") | H16: =IFERROR(IF(OR($B16="",$C16=""),"",IF(MATCH($C16,'Ajustes'!$A$5:$A$8,0)=4,$D16/INDEX('Equipo'!$B$5:$B$29,MATCH($B16,'Equipo'!$A$5:$A$29,0))+$E16,0)),"") | I16: =IF($B16='Perfil'!$B$3,COUNTIF($B$4:$B16,'Perfil'!$B$3),"")
G17: =IFERROR(IF(OR($B17="",$C17=""),"",IF(MATCH($C17,'Ajustes'!$A$5:$A$8,0)<=2,$D17*INDEX('Ajustes'!$C$5:$C$6,MATCH($C17,'Ajustes'!$A$5:$A$8,0)),IF(MATCH($C17,'Ajustes'!$A$5:$A$8,0)=3,-($D17+$E17*INDEX('Equipo'!$B$5:$B$29,MATCH($B17,'Equipo'!$A$5:$A$29,0))),0))),"") | H17: =IFERROR(IF(OR($B17="",$C17=""),"",IF(MATCH($C17,'Ajustes'!$A$5:$A$8,0)=4,$D17/INDEX('Equipo'!$B$5:$B$29,MATCH($B17,'Equipo'!$A$5:$A$29,0))+$E17,0)),"") | I17: =IF($B17='Perfil'!$B$3,COUNTIF($B$4:$B17,'Perfil'!$B$3),"")
G18: =IFERROR(IF(OR($B18="",$C18=""),"",IF(MATCH($C18,'Ajustes'!$A$5:$A$8,0)<=2,$D18*INDEX('Ajustes'!$C$5:$C$6,MATCH($C18,'Ajustes'!$A$5:$A$8,0)),IF(MATCH($C18,'Ajustes'!$A$5:$A$8,0)=3,-($D18+$E18*INDEX('Equipo'!$B$5:$B$29,MATCH($B18,'Equipo'!$A$5:$A$29,0))),0))),"") | H18: =IFERROR(IF(OR($B18="",$C18=""),"",IF(MATCH($C18,'Ajustes'!$A$5:$A$8,0)=4,$D18/INDEX('Equipo'!$B$5:$B$29,MATCH($B18,'Equipo'!$A$5:$A$29,0))+$E18,0)),"") | I18: =IF($B18='Perfil'!$B$3,COUNTIF($B$4:$B18,'Perfil'!$B$3),"")
G19: =IFERROR(IF(OR($B19="",$C19=""),"",IF(MATCH($C19,'Ajustes'!$A$5:$A$8,0)<=2,$D19*INDEX('Ajustes'!$C$5:$C$6,MATCH($C19,'Ajustes'!$A$5:$A$8,0)),IF(MATCH($C19,'Ajustes'!$A$5:$A$8,0)=3,-($D19+$E19*INDEX('Equipo'!$B$5:$B$29,MATCH($B19,'Equipo'!$A$5:$A$29,0))),0))),"") | H19: =IFERROR(IF(OR($B19="",$C19=""),"",IF(MATCH($C19,'Ajustes'!$A$5:$A$8,0)=4,$D19/INDEX('Equipo'!$B$5:$B$29,MATCH($B19,'Equipo'!$A$5:$A$29,0))+$E19,0)),"") | I19: =IF($B19='Perfil'!$B$3,COUNTIF($B$4:$B19,'Perfil'!$B$3),"")
G20: =IFERROR(IF(OR($B20="",$C20=""),"",IF(MATCH($C20,'Ajustes'!$A$5:$A$8,0)<=2,$D20*INDEX('Ajustes'!$C$5:$C$6,MATCH($C20,'Ajustes'!$A$5:$A$8,0)),IF(MATCH($C20,'Ajustes'!$A$5:$A$8,0)=3,-($D20+$E20*INDEX('Equipo'!$B$5:$B$29,MATCH($B20,'Equipo'!$A$5:$A$29,0))),0))),"") | H20: =IFERROR(IF(OR($B20="",$C20=""),"",IF(MATCH($C20,'Ajustes'!$A$5:$A$8,0)=4,$D20/INDEX('Equipo'!$B$5:$B$29,MATCH($B20,'Equipo'!$A$5:$A$29,0))+$E20,0)),"") | I20: =IF($B20='Perfil'!$B$3,COUNTIF($B$4:$B20,'Perfil'!$B$3),"")
G21: =IFERROR(IF(OR($B21="",$C21=""),"",IF(MATCH($C21,'Ajustes'!$A$5:$A$8,0)<=2,$D21*INDEX('Ajustes'!$C$5:$C$6,MATCH($C21,'Ajustes'!$A$5:$A$8,0)),IF(MATCH($C21,'Ajustes'!$A$5:$A$8,0)=3,-($D21+$E21*INDEX('Equipo'!$B$5:$B$29,MATCH($B21,'Equipo'!$A$5:$A$29,0))),0))),"") | H21: =IFERROR(IF(OR($B21="",$C21=""),"",IF(MATCH($C21,'Ajustes'!$A$5:$A$8,0)=4,$D21/INDEX('Equipo'!$B$5:$B$29,MATCH($B21,'Equipo'!$A$5:$A$29,0))+$E21,0)),"") | I21: =IF($B21='Perfil'!$B$3,COUNTIF($B$4:$B21,'Perfil'!$B$3),"")
G22: =IFERROR(IF(OR($B22="",$C22=""),"",IF(MATCH($C22,'Ajustes'!$A$5:$A$8,0)<=2,$D22*INDEX('Ajustes'!$C$5:$C$6,MATCH($C22,'Ajustes'!$A$5:$A$8,0)),IF(MATCH($C22,'Ajustes'!$A$5:$A$8,0)=3,-($D22+$E22*INDEX('Equipo'!$B$5:$B$29,MATCH($B22,'Equipo'!$A$5:$A$29,0))),0))),"") | H22: =IFERROR(IF(OR($B22="",$C22=""),"",IF(MATCH($C22,'Ajustes'!$A$5:$A$8,0)=4,$D22/INDEX('Equipo'!$B$5:$B$29,MATCH($B22,'Equipo'!$A$5:$A$29,0))+$E22,0)),"") | I22: =IF($B22='Perfil'!$B$3,COUNTIF($B$4:$B22,'Perfil'!$B$3),"")
G23: =IFERROR(IF(OR($B23="",$C23=""),"",IF(MATCH($C23,'Ajustes'!$A$5:$A$8,0)<=2,$D23*INDEX('Ajustes'!$C$5:$C$6,MATCH($C23,'Ajustes'!$A$5:$A$8,0)),IF(MATCH($C23,'Ajustes'!$A$5:$A$8,0)=3,-($D23+$E23*INDEX('Equipo'!$B$5:$B$29,MATCH($B23,'Equipo'!$A$5:$A$29,0))),0))),"") | H23: =IFERROR(IF(OR($B23="",$C23=""),"",IF(MATCH($C23,'Ajustes'!$A$5:$A$8,0)=4,$D23/INDEX('Equipo'!$B$5:$B$29,MATCH($B23,'Equipo'!$A$5:$A$29,0))+$E23,0)),"") | I23: =IF($B23='Perfil'!$B$3,COUNTIF($B$4:$B23,'Perfil'!$B$3),"")
G24: =IFERROR(IF(OR($B24="",$C24=""),"",IF(MATCH($C24,'Ajustes'!$A$5:$A$8,0)<=2,$D24*INDEX('Ajustes'!$C$5:$C$6,MATCH($C24,'Ajustes'!$A$5:$A$8,0)),IF(MATCH($C24,'Ajustes'!$A$5:$A$8,0)=3,-($D24+$E24*INDEX('Equipo'!$B$5:$B$29,MATCH($B24,'Equipo'!$A$5:$A$29,0))),0))),"") | H24: =IFERROR(IF(OR($B24="",$C24=""),"",IF(MATCH($C24,'Ajustes'!$A$5:$A$8,0)=4,$D24/INDEX('Equipo'!$B$5:$B$29,MATCH($B24,'Equipo'!$A$5:$A$29,0))+$E24,0)),"") | I24: =IF($B24='Perfil'!$B$3,COUNTIF($B$4:$B24,'Perfil'!$B$3),"")
G25: =IFERROR(IF(OR($B25="",$C25=""),"",IF(MATCH($C25,'Ajustes'!$A$5:$A$8,0)<=2,$D25*INDEX('Ajustes'!$C$5:$C$6,MATCH($C25,'Ajustes'!$A$5:$A$8,0)),IF(MATCH($C25,'Ajustes'!$A$5:$A$8,0)=3,-($D25+$E25*INDEX('Equipo'!$B$5:$B$29,MATCH($B25,'Equipo'!$A$5:$A$29,0))),0))),"") | H25: =IFERROR(IF(OR($B25="",$C25=""),"",IF(MATCH($C25,'Ajustes'!$A$5:$A$8,0)=4,$D25/INDEX('Equipo'!$B$5:$B$29,MATCH($B25,'Equipo'!$A$5:$A$29,0))+$E25,0)),"") | I25: =IF($B25='Perfil'!$B$3,COUNTIF($B$4:$B25,'Perfil'!$B$3),"")
... G1503: =IFERROR(IF(OR($B1503="",$C1503=""),"",IF(MATCH($C1503,'Ajustes'!$A$5:$A$8,0)<=2,$D1503*INDEX('Ajustes'!$C$5:$C$6,MATCH($C1503,'Ajustes'!$A$5:$A$8,0)),IF(MATCH($C1503,'Ajustes'!$A$5:$A$8,0)=3,-($D1503+$E1503*INDEX('Equipo'!$B$5:$B$29,MATCH($B1503,'Equipo'!$A$5:$A$29,0))),0))),"") | H1503: =IFERROR(IF(OR($B1503="",$C1503=""),"",IF(MATCH($C1503,'Ajustes'!$A$5:$A$8,0)=4,$D1503/INDEX('Equipo'!$B$5:$B$29,MATCH($B1503,'Equipo'!$A$5:$A$29,0))+$E1503,0)),"") | I1503: =IF($B1503='Perfil'!$B$3,COUNTIF($B$4:$B1503,'Perfil'!$B$3),"")

Sheet Equipo
A1: Equipo
A2: Una fila por persona. Las celdas amarillas son tuyas.
A4: Nombre | B4: Horas de la jornada | C4: Saldo inicial (horas) | D4: Días de vacaciones por año
A5: Lucía Fernández | B5: 8 | C5: 0 | D5: 14 | F5: ← personas de ejemplo: pisalas o borralas
A6: Martín Gómez | B6: 8 | C6: 4 | D6: 14
A7: Sofía Ruiz | B7: 6 | C7: 0 | D7: 21

Sheet Resumen
A1: Resumen
A2: El saldo de todos de un vistazo. Acá no hay nada que escribir.
A4: Persona | B4: Horas extra acreditadas | C4: Francos tomados (h) | D4: Saldo inicial (h) | E4: Saldo (horas) | F4: Saldo (días) | G4: Vacaciones usadas (días) | H4: Vacaciones restantes (días) | I4: Estado
A5: =IF('Equipo'!A5="","",'Equipo'!A5) | B5: =IF($A5="","",SUMIFS('Registro'!$G$4:$G$1503,'Registro'!$B$4:$B$1503,$A5,'Registro'!$G$4:$G$1503,">0")) | C5: =IF($A5="","",-SUMIFS('Registro'!$G$4:$G$1503,'Registro'!$B$4:$B$1503,$A5,'Registro'!$G$4:$G$1503,"<0")) | D5: =IF($A5="","",'Equipo'!C5) | E5: =IF($A5="","",D5+B5-C5) | F5: =IF($A5="","",IF('Equipo'!B5>0,E5/'Equipo'!B5,0)) | G5: =IF($A5="","",SUMIFS('Registro'!$H$4:$H$1503,'Registro'!$B$4:$B$1503,$A5,'Registro'!$A$4:$A$1503,">="&DATE('Ajustes'!$A$12,1,1),'Registro'!$A$4:$A$1503,"<="&DATE('Ajustes'!$A$12,12,31))) | H5: =IF($A5="","",'Equipo'!D5-G5) | I5: =IF($A5="","",IF(E5>0.0001,"Francos a tomar",IF(E5<-0.0001,"Tomó de más","Al día")))
A6: =IF('Equipo'!A6="","",'Equipo'!A6) | B6: =IF($A6="","",SUMIFS('Registro'!$G$4:$G$1503,'Registro'!$B$4:$B$1503,$A6,'Registro'!$G$4:$G$1503,">0")) | C6: =IF($A6="","",-SUMIFS('Registro'!$G$4:$G$1503,'Registro'!$B$4:$B$1503,$A6,'Registro'!$G$4:$G$1503,"<0")) | D6: =IF($A6="","",'Equipo'!C6) | E6: =IF($A6="","",D6+B6-C6) | F6: =IF($A6="","",IF('Equipo'!B6>0,E6/'Equipo'!B6,0)) | G6: =IF($A6="","",SUMIFS('Registro'!$H$4:$H$1503,'Registro'!$B$4:$B$1503,$A6,'Registro'!$A$4:$A$1503,">="&DATE('Ajustes'!$A$12,1,1),'Registro'!$A$4:$A$1503,"<="&DATE('Ajustes'!$A$12,12,31))) | H6: =IF($A6="","",'Equipo'!D6-G6) | I6: =IF($A6="","",IF(E6>0.0001,"Francos a tomar",IF(E6<-0.0001,"Tomó de más","Al día")))
A7: =IF('Equipo'!A7="","",'Equipo'!A7) | B7: =IF($A7="","",SUMIFS('Registro'!$G$4:$G$1503,'Registro'!$B$4:$B$1503,$A7,'Registro'!$G$4:$G$1503,">0")) | C7: =IF($A7="","",-SUMIFS('Registro'!$G$4:$G$1503,'Registro'!$B$4:$B$1503,$A7,'Registro'!$G$4:$G$1503,"<0")) | D7: =IF($A7="","",'Equipo'!C7) | E7: =IF($A7="","",D7+B7-C7) | F7: =IF($A7="","",IF('Equipo'!B7>0,E7/'Equipo'!B7,0)) | G7: =IF($A7="","",SUMIFS('Registro'!$H$4:$H$1503,'Registro'!$B$4:$B$1503,$A7,'Registro'!$A$4:$A$1503,">="&DATE('Ajustes'!$A$12,1,1),'Registro'!$A$4:$A$1503,"<="&DATE('Ajustes'!$A$12,12,31))) | H7: =IF($A7="","",'Equipo'!D7-G7) | I7: =IF($A7="","",IF(E7>0.0001,"Francos a tomar",IF(E7<-0.0001,"Tomó de más","Al día")))
A8: =IF('Equipo'!A8="","",'Equipo'!A8) | B8: =IF($A8="","",SUMIFS('Registro'!$G$4:$G$1503,'Registro'!$B$4:$B$1503,$A8,'Registro'!$G$4:$G$1503,">0")) | C8: =IF($A8="","",-SUMIFS('Registro'!$G$4:$G$1503,'Registro'!$B$4:$B$1503,$A8,'Registro'!$G$4:$G$1503,"<0")) | D8: =IF($A8="","",'Equipo'!C8) | E8: =IF($A8="","",D8+B8-C8) | F8: =IF($A8="","",IF('Equipo'!B8>0,E8/'Equipo'!B8,0)) | G8: =IF($A8="","",SUMIFS('Registro'!$H$4:$H$1503,'Registro'!$B$4:$B$1503,$A8,'Registro'!$A$4:$A$1503,">="&DATE('Ajustes'!$A$12,1,1),'Registro'!$A$4:$A$1503,"<="&DATE('Ajustes'!$A$12,12,31))) | H8: =IF($A8="","",'Equipo'!D8-G8) | I8: =IF($A8="","",IF(E8>0.0001,"Francos a tomar",IF(E8<-0.0001,"Tomó de más","Al día")))
A9: =IF('Equipo'!A9="","",'Equipo'!A9) | B9: =IF($A9="","",SUMIFS('Registro'!$G$4:$G$1503,'Registro'!$B$4:$B$1503,$A9,'Registro'!$G$4:$G$1503,">0")) | C9: =IF($A9="","",-SUMIFS('Registro'!$G$4:$G$1503,'Registro'!$B$4:$B$1503,$A9,'Registro'!$G$4:$G$1503,"<0")) | D9: =IF($A9="","",'Equipo'!C9) | E9: =IF($A9="","",D9+B9-C9) | F9: =IF($A9="","",IF('Equipo'!B9>0,E9/'Equipo'!B9,0)) | G9: =IF($A9="","",SUMIFS('Registro'!$H$4:$H$1503,'Registro'!$B$4:$B$1503,$A9,'Registro'!$A$4:$A$1503,">="&DATE('Ajustes'!$A$12,1,1),'Registro'!$A$4:$A$1503,"<="&DATE('Ajustes'!$A$12,12,31))) | H9: =IF($A9="","",'Equipo'!D9-G9) | I9: =IF($A9="","",IF(E9>0.0001,"Francos a tomar",IF(E9<-0.0001,"Tomó de más","Al día")))
A10: =IF('Equipo'!A10="","",'Equipo'!A10) | B10: =IF($A10="","",SUMIFS('Registro'!$G$4:$G$1503,'Registro'!$B$4:$B$1503,$A10,'Registro'!$G$4:$G$1503,">0")) | C10: =IF($A10="","",-SUMIFS('Registro'!$G$4:$G$1503,'Registro'!$B$4:$B$1503,$A10,'Registro'!$G$4:$G$1503,"<0")) | D10: =IF($A10="","",'Equipo'!C10) | E10: =IF($A10="","",D10+B10-C10) | F10: =IF($A10="","",IF('Equipo'!B10>0,E10/'Equipo'!B10,0)) | G10: =IF($A10="","",SUMIFS('Registro'!$H$4:$H$1503,'Registro'!$B$4:$B$1503,$A10,'Registro'!$A$4:$A$1503,">="&DATE('Ajustes'!$A$12,1,1),'Registro'!$A$4:$A$1503,"<="&DATE('Ajustes'!$A$12,12,31))) | H10: =IF($A10="","",'Equipo'!D10-G10) | I10: =IF($A10="","",IF(E10>0.0001,"Francos a tomar",IF(E10<-0.0001,"Tomó de más","Al día")))
A11: =IF('Equipo'!A11="","",'Equipo'!A11) | B11: =IF($A11="","",SUMIFS('Registro'!$G$4:$G$1503,'Registro'!$B$4:$B$1503,$A11,'Registro'!$G$4:$G$1503,">0")) | C11: =IF($A11="","",-SUMIFS('Registro'!$G$4:$G$1503,'Registro'!$B$4:$B$1503,$A11,'Registro'!$G$4:$G$1503,"<0")) | D11: =IF($A11="","",'Equipo'!C11) | E11: =IF($A11="","",D11+B11-C11) | F11: =IF($A11="","",IF('Equipo'!B11>0,E11/'Equipo'!B11,0)) | G11: =IF($A11="","",SUMIFS('Registro'!$H$4:$H$1503,'Registro'!$B$4:$B$1503,$A11,'Registro'!$A$4:$A$1503,">="&DATE('Ajustes'!$A$12,1,1),'Registro'!$A$4:$A$1503,"<="&DATE('Ajustes'!$A$12,12,31))) | H11: =IF($A11="","",'Equipo'!D11-G11) | I11: =IF($A11="","",IF(E11>0.0001,"Francos a tomar",IF(E11<-0.0001,"Tomó de más","Al día")))
A12: =IF('Equipo'!A12="","",'Equipo'!A12) | B12: =IF($A12="","",SUMIFS('Registro'!$G$4:$G$1503,'Registro'!$B$4:$B$1503,$A12,'Registro'!$G$4:$G$1503,">0")) | C12: =IF($A12="","",-SUMIFS('Registro'!$G$4:$G$1503,'Registro'!$B$4:$B$1503,$A12,'Registro'!$G$4:$G$1503,"<0")) | D12: =IF($A12="","",'Equipo'!C12) | E12: =IF($A12="","",D12+B12-C12) | F12: =IF($A12="","",IF('Equipo'!B12>0,E12/'Equipo'!B12,0)) | G12: =IF($A12="","",SUMIFS('Registro'!$H$4:$H$1503,'Registro'!$B$4:$B$1503,$A12,'Registro'!$A$4:$A$1503,">="&DATE('Ajustes'!$A$12,1,1),'Registro'!$A$4:$A$1503,"<="&DATE('Ajustes'!$A$12,12,31))) | H12: =IF($A12="","",'Equipo'!D12-G12) | I12: =IF($A12="","",IF(E12>0.0001,"Francos a tomar",IF(E12<-0.0001,"Tomó de más","Al día")))
A13: =IF('Equipo'!A13="","",'Equipo'!A13) | B13: =IF($A13="","",SUMIFS('Registro'!$G$4:$G$1503,'Registro'!$B$4:$B$1503,$A13,'Registro'!$G$4:$G$1503,">0")) | C13: =IF($A13="","",-SUMIFS('Registro'!$G$4:$G$1503,'Registro'!$B$4:$B$1503,$A13,'Registro'!$G$4:$G$1503,"<0")) | D13: =IF($A13="","",'Equipo'!C13) | E13: =IF($A13="","",D13+B13-C13) | F13: =IF($A13="","",IF('Equipo'!B13>0,E13/'Equipo'!B13,0)) | G13: =IF($A13="","",SUMIFS('Registro'!$H$4:$H$1503,'Registro'!$B$4:$B$1503,$A13,'Registro'!$A$4:$A$1503,">="&DATE('Ajustes'!$A$12,1,1),'Registro'!$A$4:$A$1503,"<="&DATE('Ajustes'!$A$12,12,31))) | H13: =IF($A13="","",'Equipo'!D13-G13) | I13: =IF($A13="","",IF(E13>0.0001,"Francos a tomar",IF(E13<-0.0001,"Tomó de más","Al día")))
A14: =IF('Equipo'!A14="","",'Equipo'!A14) | B14: =IF($A14="","",SUMIFS('Registro'!$G$4:$G$1503,'Registro'!$B$4:$B$1503,$A14,'Registro'!$G$4:$G$1503,">0")) | C14: =IF($A14="","",-SUMIFS('Registro'!$G$4:$G$1503,'Registro'!$B$4:$B$1503,$A14,'Registro'!$G$4:$G$1503,"<0")) | D14: =IF($A14="","",'Equipo'!C14) | E14: =IF($A14="","",D14+B14-C14) | F14: =IF($A14="","",IF('Equipo'!B14>0,E14/'Equipo'!B14,0)) | G14: =IF($A14="","",SUMIFS('Registro'!$H$4:$H$1503,'Registro'!$B$4:$B$1503,$A14,'Registro'!$A$4:$A$1503,">="&DATE('Ajustes'!$A$12,1,1),'Registro'!$A$4:$A$1503,"<="&DATE('Ajustes'!$A$12,12,31))) | H14: =IF($A14="","",'Equipo'!D14-G14) | I14: =IF($A14="","",IF(E14>0.0001,"Francos a tomar",IF(E14<-0.0001,"Tomó de más","Al día")))
A15: =IF('Equipo'!A15="","",'Equipo'!A15) | B15: =IF($A15="","",SUMIFS('Registro'!$G$4:$G$1503,'Registro'!$B$4:$B$1503,$A15,'Registro'!$G$4:$G$1503,">0")) | C15: =IF($A15="","",-SUMIFS('Registro'!$G$4:$G$1503,'Registro'!$B$4:$B$1503,$A15,'Registro'!$G$4:$G$1503,"<0")) | D15: =IF($A15="","",'Equipo'!C15) | E15: =IF($A15="","",D15+B15-C15) | F15: =IF($A15="","",IF('Equipo'!B15>0,E15/'Equipo'!B15,0)) | G15: =IF($A15="","",SUMIFS('Registro'!$H$4:$H$1503,'Registro'!$B$4:$B$1503,$A15,'Registro'!$A$4:$A$1503,">="&DATE('Ajustes'!$A$12,1,1),'Registro'!$A$4:$A$1503,"<="&DATE('Ajustes'!$A$12,12,31))) | H15: =IF($A15="","",'Equipo'!D15-G15) | I15: =IF($A15="","",IF(E15>0.0001,"Francos a tomar",IF(E15<-0.0001,"Tomó de más","Al día")))
A16: =IF('Equipo'!A16="","",'Equipo'!A16) | B16: =IF($A16="","",SUMIFS('Registro'!$G$4:$G$1503,'Registro'!$B$4:$B$1503,$A16,'Registro'!$G$4:$G$1503,">0")) | C16: =IF($A16="","",-SUMIFS('Registro'!$G$4:$G$1503,'Registro'!$B$4:$B$1503,$A16,'Registro'!$G$4:$G$1503,"<0")) | D16: =IF($A16="","",'Equipo'!C16) | E16: =IF($A16="","",D16+B16-C16) | F16: =IF($A16="","",IF('Equipo'!B16>0,E16/'Equipo'!B16,0)) | G16: =IF($A16="","",SUMIFS('Registro'!$H$4:$H$1503,'Registro'!$B$4:$B$1503,$A16,'Registro'!$A$4:$A$1503,">="&DATE('Ajustes'!$A$12,1,1),'Registro'!$A$4:$A$1503,"<="&DATE('Ajustes'!$A$12,12,31))) | H16: =IF($A16="","",'Equipo'!D16-G16) | I16: =IF($A16="","",IF(E16>0.0001,"Francos a tomar",IF(E16<-0.0001,"Tomó de más","Al día")))
... A29: =IF('Equipo'!A29="","",'Equipo'!A29) | B29: =IF($A29="","",SUMIFS('Registro'!$G$4:$G$1503,'Registro'!$B$4:$B$1503,$A29,'Registro'!$G$4:$G$1503,">0")) | C29: =IF($A29="","",-SUMIFS('Registro'!$G$4:$G$1503,'Registro'!$B$4:$B$1503,$A29,'Registro'!$G$4:$G$1503,"<0")) | D29: =IF($A29="","",'Equipo'!C29) | E29: =IF($A29="","",D29+B29-C29) | F29: =IF($A29="","",IF('Equipo'!B29>0,E29/'Equipo'!B29,0)) | G29: =IF($A29="","",SUMIFS('Registro'!$H$4:$H$1503,'Registro'!$B$4:$B$1503,$A29,'Registro'!$A$4:$A$1503,">="&DATE('Ajustes'!$A$12,1,1),'Registro'!$A$4:$A$1503,"<="&DATE('Ajustes'!$A$12,12,31))) | H29: =IF($A29="","",'Equipo'!D29-G29) | I29: =IF($A29="","",IF(E29>0.0001,"Francos a tomar",IF(E29<-0.0001,"Tomó de más","Al día")))
A30: Total del equipo | B30: =SUM(B5:B29) | C30: =SUM(C5:C29) | D30: =SUM(D5:D29) | E30: =SUM(E5:E29) | F30: =SUM(F5:F29) | G30: =SUM(G5:G29) | H30: =SUM(H5:H29)
A51: El gráfico muestra las primeras 12 personas.

Sheet Ajustes
A1: Ajustes
A2: Tipos de movimiento y cuánto vale cada hora.
A4: Tipo | B4: Qué hace | C4: Coeficiente
A5: Horas extra trabajadas | B5: Suma al saldo | C5: 1
A6: Trabajo en feriado / franco | B6: Suma al saldo | C6: 1
A7: Franco compensatorio tomado | B7: Resta del saldo | C7: –
A8: Vacaciones / licencia oficial | B8: Aparte: vacaciones oficiales | C8: –
A11: Año de vacaciones
A12: 2026
A14: Los tipos 1 y 2 suman al saldo (por el coeficiente), el 3 resta y el 4 son vacaciones oficiales, que se cuentan aparte.
