Workbook

Sheet Inicio
A1: Checklist de Viaje por Plazos y Equipaje
A2: Cargá la fecha de salida y el tipo de viaje. La planilla calcula qué hacer y para cuándo, marca lo atrasado e imprime tu lista de equipaje.
A4: CÓMO USARLA
A5: 1. Datos del viaje: escribí el nombre del viaje, la fecha de salida, la duración y la cantidad de viajeros, y elegí tipo de viaje, transporte, chicos, mascotas, visa y clima (celdas amarillas).
A6: 2. Checklist: cada tarea tiene una fecha límite contada hacia atrás desde la salida y un estado: Atrasada, Pronto o Al día. Marcá como Hecho las que terminaste. Las tareas que no corresponden a tu viaje se ven en gris.
A7: 3. Cambiá el número de 'Días antes' de cualquier tarea a tu medida, o usá las filas vacías del final para tus propias tareas.
A8: 4. Resumen: tu avance, cuántos días faltan y las próximas tareas en orden.
A9: 5. Equipaje: los ítems que corresponden a tu viaje, con cantidades para todos los viajeros. Tildá lo que ya guardaste. Lista para imprimir te da una lista limpia para imprimir.
A10: ¿Usás también el Planificador de Presupuesto de Viaje? Datos del viaje tiene las mismas celdas de nombre (B5), viajeros (B10), fecha de inicio (B11) y duración (B12): copialas de una a otra.
A12: COLORES
A13: Las celdas amarillas son para completar. Las verdes se calculan solas, no las pises. Las filas grises no corresponden a este viaje.
A15: FUENTES OFICIALES
... A19: Ayuda de planificación con plazos habituales; no es asesoramiento legal, migratorio ni médico. 'Atrasada' no siempre significa que lo perdiste: si reservaste tarde, marcá lo hecho e ignorá el resto. Solo para uso personal; no se permite su reventa ni redistribución.

Sheet Resumen
A1: Resumen
A2: ='Datos del viaje'!$B$5&" · "&TEXT('Datos del viaje'!$B$11,"yyyy-mm-dd")&" · "&'Datos del viaje'!$B$10&" viajero(s)"
A4: AVANCE | F4: POR ETAPA
A5: Días hasta la salida | B5: ='Datos del viaje'!$B$11-'Datos del viaje'!$B$18 | F5: Etapa | G5: Tareas | H5: Hechas
A6: Tareas que aplican a este viaje | B6: =SUM('Checklist'!$I$5:$I$80) | F6: 6 meses o más antes | G6: =COUNTIFS('Checklist'!$A$5:$A$80,F6,'Checklist'!$I$5:$I$80,1) | H6: =COUNTIFS('Checklist'!$A$5:$A$80,F6,'Checklist'!$I$5:$I$80,1,'Checklist'!$F$5:$F$80,"Hecho")
A7: Hechas | B7: =COUNTIFS('Checklist'!$I$5:$I$80,1,'Checklist'!$F$5:$F$80,"Hecho") | F7: 3 a 6 meses antes | G7: =COUNTIFS('Checklist'!$A$5:$A$80,F7,'Checklist'!$I$5:$I$80,1) | H7: =COUNTIFS('Checklist'!$A$5:$A$80,F7,'Checklist'!$I$5:$I$80,1,'Checklist'!$F$5:$F$80,"Hecho")
A8: Completado | B8: =IF(B6=0,0,B7/B6) | F8: 1 a 3 meses antes | G8: =COUNTIFS('Checklist'!$A$5:$A$80,F8,'Checklist'!$I$5:$I$80,1) | H8: =COUNTIFS('Checklist'!$A$5:$A$80,F8,'Checklist'!$I$5:$I$80,1,'Checklist'!$F$5:$F$80,"Hecho")
A9: Atrasadas | B9: =COUNTIF('Checklist'!$G$5:$G$80,"Atrasada") | F9: 2 a 4 semanas antes | G9: =COUNTIFS('Checklist'!$A$5:$A$80,F9,'Checklist'!$I$5:$I$80,1) | H9: =COUNTIFS('Checklist'!$A$5:$A$80,F9,'Checklist'!$I$5:$I$80,1,'Checklist'!$F$5:$F$80,"Hecho")
A10: Pronto | B10: =COUNTIF('Checklist'!$G$5:$G$80,"Pronto") | F10: 1 a 2 semanas antes | G10: =COUNTIFS('Checklist'!$A$5:$A$80,F10,'Checklist'!$I$5:$I$80,1) | H10: =COUNTIFS('Checklist'!$A$5:$A$80,F10,'Checklist'!$I$5:$I$80,1,'Checklist'!$F$5:$F$80,"Hecho")
A11: Al día | B11: =COUNTIF('Checklist'!$G$5:$G$80,"Al día") | F11: Últimos días | G11: =COUNTIFS('Checklist'!$A$5:$A$80,F11,'Checklist'!$I$5:$I$80,1) | H11: =COUNTIFS('Checklist'!$A$5:$A$80,F11,'Checklist'!$I$5:$I$80,1,'Checklist'!$F$5:$F$80,"Hecho")
F12: Día anterior | G12: =COUNTIFS('Checklist'!$A$5:$A$80,F12,'Checklist'!$I$5:$I$80,1) | H12: =COUNTIFS('Checklist'!$A$5:$A$80,F12,'Checklist'!$I$5:$I$80,1,'Checklist'!$F$5:$F$80,"Hecho")
A13: PRÓXIMAS TAREAS | F13: Día de salida | G13: =COUNTIFS('Checklist'!$A$5:$A$80,F13,'Checklist'!$I$5:$I$80,1) | H13: =COUNTIFS('Checklist'!$A$5:$A$80,F13,'Checklist'!$I$5:$I$80,1,'Checklist'!$F$5:$F$80,"Hecho")
A14: Tarea | B14: Fecha límite | C14: Estado | F14: Después del viaje | G14: =COUNTIFS('Checklist'!$A$5:$A$80,F14,'Checklist'!$I$5:$I$80,1) | H14: =COUNTIFS('Checklist'!$A$5:$A$80,F14,'Checklist'!$I$5:$I$80,1,'Checklist'!$F$5:$F$80,"Hecho")
A15: =IF(E15="","",INDEX('Checklist'!$B$5:$B$80,E15)) | B15: =IF(E15="","",INDEX('Checklist'!$E$5:$E$80,E15)) | C15: =IF(E15="","",INDEX('Checklist'!$G$5:$G$80,E15)) | E15: =IFERROR(MATCH(SMALL('Checklist'!$J$5:$J$80,1),'Checklist'!$J$5:$J$80,0),"")
A16: =IF(E16="","",INDEX('Checklist'!$B$5:$B$80,E16)) | B16: =IF(E16="","",INDEX('Checklist'!$E$5:$E$80,E16)) | C16: =IF(E16="","",INDEX('Checklist'!$G$5:$G$80,E16)) | E16: =IFERROR(MATCH(SMALL('Checklist'!$J$5:$J$80,2),'Checklist'!$J$5:$J$80,0),"")
A17: =IF(E17="","",INDEX('Checklist'!$B$5:$B$80,E17)) | B17: =IF(E17="","",INDEX('Checklist'!$E$5:$E$80,E17)) | C17: =IF(E17="","",INDEX('Checklist'!$G$5:$G$80,E17)) | E17: =IFERROR(MATCH(SMALL('Checklist'!$J$5:$J$80,3),'Checklist'!$J$5:$J$80,0),"")
A18: =IF(E18="","",INDEX('Checklist'!$B$5:$B$80,E18)) | B18: =IF(E18="","",INDEX('Checklist'!$E$5:$E$80,E18)) | C18: =IF(E18="","",INDEX('Checklist'!$G$5:$G$80,E18)) | E18: =IFERROR(MATCH(SMALL('Checklist'!$J$5:$J$80,4),'Checklist'!$J$5:$J$80,0),"")
A19: =IF(E19="","",INDEX('Checklist'!$B$5:$B$80,E19)) | B19: =IF(E19="","",INDEX('Checklist'!$E$5:$E$80,E19)) | C19: =IF(E19="","",INDEX('Checklist'!$G$5:$G$80,E19)) | E19: =IFERROR(MATCH(SMALL('Checklist'!$J$5:$J$80,5),'Checklist'!$J$5:$J$80,0),"")
A20: =IF(E20="","",INDEX('Checklist'!$B$5:$B$80,E20)) | B20: =IF(E20="","",INDEX('Checklist'!$E$5:$E$80,E20)) | C20: =IF(E20="","",INDEX('Checklist'!$G$5:$G$80,E20)) | E20: =IFERROR(MATCH(SMALL('Checklist'!$J$5:$J$80,6),'Checklist'!$J$5:$J$80,0),"")
A21: =IF(E21="","",INDEX('Checklist'!$B$5:$B$80,E21)) | B21: =IF(E21="","",INDEX('Checklist'!$E$5:$E$80,E21)) | C21: =IF(E21="","",INDEX('Checklist'!$G$5:$G$80,E21)) | E21: =IFERROR(MATCH(SMALL('Checklist'!$J$5:$J$80,7),'Checklist'!$J$5:$J$80,0),"")
A22: =IF(E22="","",INDEX('Checklist'!$B$5:$B$80,E22)) | B22: =IF(E22="","",INDEX('Checklist'!$E$5:$E$80,E22)) | C22: =IF(E22="","",INDEX('Checklist'!$G$5:$G$80,E22)) | E22: =IFERROR(MATCH(SMALL('Checklist'!$J$5:$J$80,8),'Checklist'!$J$5:$J$80,0),"")
A23: =IF(E23="","",INDEX('Checklist'!$B$5:$B$80,E23)) | B23: =IF(E23="","",INDEX('Checklist'!$E$5:$E$80,E23)) | C23: =IF(E23="","",INDEX('Checklist'!$G$5:$G$80,E23)) | E23: =IFERROR(MATCH(SMALL('Checklist'!$J$5:$J$80,9),'Checklist'!$J$5:$J$80,0),"")
A24: =IF(E24="","",INDEX('Checklist'!$B$5:$B$80,E24)) | B24: =IF(E24="","",INDEX('Checklist'!$E$5:$E$80,E24)) | C24: =IF(E24="","",INDEX('Checklist'!$G$5:$G$80,E24)) | E24: =IFERROR(MATCH(SMALL('Checklist'!$J$5:$J$80,10),'Checklist'!$J$5:$J$80,0),"")

Sheet Datos del viaje
A1: Datos del viaje
A2: Completá primero las celdas amarillas.
A4: Dato | B4: Valor | D4: Aplica cuando | E4: ¿En este viaje?
A5: Nombre del viaje | B5: Lisboa en marzo | D5: Siempre | E5: =1
A6: Tipo de viaje | B6: Exterior | D6: Exterior | E6: =IF($B$6="Exterior",1,0)
A7: Transporte principal | B7: Avión | D7: Dentro del país | E7: =IF($B$6="Dentro del país",1,0)
A8: ¿Viajan chicos? | B8: No | D8: Avión | E8: =IF($B$7="Avión",1,0)
A9: ¿Viajan mascotas? | B9: No | D9: Auto | E9: =IF($B$7="Auto",1,0)
A10: Viajeros | B10: 2 | D10: Tren o micro | E10: =IF($B$7="Tren o micro",1,0)
A11: Fecha de salida | B11: 46458 | D11: Con chicos | E11: =IF($B$8="Sí",1,0)
A12: Duración (días) | B12: 10 | D12: Mascotas | E12: =IF($B$9="Sí",1,0)
A13: ¿Hace falta visa o permiso? | B13: No sé | D13: Con visa | E13: =IF(AND($B$6="Exterior",OR($B$13="Sí",$B$13="No sé")),1,0)
A14: Clima en el destino | B14: Templado | D14: Clima frío | E14: =IF($B$14="Frío",1,0)
A15: Aviso 'Pronto' (días) | B15: 14 | D15: Clima cálido | E15: =IF($B$14="Cálido",1,0)
A16: Simular que hoy es (opcional) | D16: Viaje largo (8+ días) | E16: =IF($B$12>=8,1,0)
A17: Fecha de regreso | B17: =IF(B11="","",B11+B12-1)
A18: Hoy | B18: =IF(B16="",TODAY(),B16) | D18: 1 = sí, 0 = no. Se calcula sola, no la edites.

Sheet Checklist
A1: Checklist
A2: Fecha límite = salida menos 'Días antes'. Marcá las tareas terminadas como Hecho.
A4: Etapa | B4: Tarea | C4: Aplica cuando | D4: Días antes | E4: Fecha límite | F4: ¿Hecho? | G4: Estado | H4: Notas
A5: =IF(D5="","",IF(D5>=180,"6 meses o más antes",IF(D5>=90,"3 a 6 meses antes",IF(D5>=30,"1 a 3 meses antes",IF(D5>=14,"2 a 4 semanas antes",IF(D5>=7,"1 a 2 semanas antes",IF(D5>=2,"Últimos días",IF(D5>=1,"Día anterior",IF(D5>=0,"Día de salida","Después del viaje"))))))))) | B5: Revisá el vencimiento del pasaporte de cada viajero. Si está cerca de las fechas del viaje, empezá la renovación ya | C5: Exterior | D5: 240 | E5: =IF(OR(B5="",D5="",'Datos del viaje'!$B$11=""),"",'Datos del viaje'!$B$11-D5) | G5: =IF(I5=0,"",IF(F5="Hecho","Hecho",IF(E5="","",IF(E5<'Datos del viaje'!$B$18,"Atrasada",IF(E5-'Datos del viaje'!$B$18<='Datos del viaje'!$B$15,"Pronto","Al día"))))) | I5: =IF(B5="",0,IFERROR(INDEX('Datos del viaje'!$E$5:$E$16,MATCH(C5,'Datos del viaje'!$D$5:$D$16,0)),0)) | J5: =IF(OR(I5=0,F5="Hecho",E5=""),"",E5+ROW()/100000)
A6: =IF(D6="","",IF(D6>=180,"6 meses o más antes",IF(D6>=90,"3 a 6 meses antes",IF(D6>=30,"1 a 3 meses antes",IF(D6>=14,"2 a 4 semanas antes",IF(D6>=7,"1 a 2 semanas antes",IF(D6>=2,"Últimos días",IF(D6>=1,"Día anterior",IF(D6>=0,"Día de salida","Después del viaje"))))))))) | B6: Averiguá los requisitos de ingreso al destino en fuentes oficiales (vigencia del pasaporte, visa, sanidad) | C6: Exterior | D6: 200 | E6: =IF(OR(B6="",D6="",'Datos del viaje'!$B$11=""),"",'Datos del viaje'!$B$11-D6) | G6: =IF(I6=0,"",IF(F6="Hecho","Hecho",IF(E6="","",IF(E6<'Datos del viaje'!$B$18,"Atrasada",IF(E6-'Datos del viaje'!$B$18<='Datos del viaje'!$B$15,"Pronto","Al día"))))) | I6: =IF(B6="",0,IFERROR(INDEX('Datos del viaje'!$E$5:$E$16,MATCH(C6,'Datos del viaje'!$D$5:$D$16,0)),0)) | J6: =IF(OR(I6=0,F6="Hecho",E6=""),"",E6+ROW()/100000)
A7: =IF(D7="","",IF(D7>=180,"6 meses o más antes",IF(D7>=90,"3 a 6 meses antes",IF(D7>=30,"1 a 3 meses antes",IF(D7>=14,"2 a 4 semanas antes",IF(D7>=7,"1 a 2 semanas antes",IF(D7>=2,"Últimos días",IF(D7>=1,"Día anterior",IF(D7>=0,"Día de salida","Después del viaje"))))))))) | B7: Revisá que el documento o pasaporte de cada chico esté vigente y leé las reglas oficiales para menores que viajan | C7: Con chicos | D7: 200 | E7: =IF(OR(B7="",D7="",'Datos del viaje'!$B$11=""),"",'Datos del viaje'!$B$11-D7) | G7: =IF(I7=0,"",IF(F7="Hecho","Hecho",IF(E7="","",IF(E7<'Datos del viaje'!$B$18,"Atrasada",IF(E7-'Datos del viaje'!$B$18<='Datos del viaje'!$B$15,"Pronto","Al día"))))) | I7: =IF(B7="",0,IFERROR(INDEX('Datos del viaje'!$E$5:$E$16,MATCH(C7,'Datos del viaje'!$D$5:$D$16,0)),0)) | J7: =IF(OR(I7=0,F7="Hecho",E7=""),"",E7+ROW()/100000)
A8: =IF(D8="","",IF(D8>=180,"6 meses o más antes",IF(D8>=90,"3 a 6 meses antes",IF(D8>=30,"1 a 3 meses antes",IF(D8>=14,"2 a 4 semanas antes",IF(D8>=7,"1 a 2 semanas antes",IF(D8>=2,"Últimos días",IF(D8>=1,"Día anterior",IF(D8>=0,"Día de salida","Después del viaje"))))))))) | B8: Elegí destino y fechas aproximadas y acordalas con quienes viajan con vos | C8: Siempre | D8: 180 | E8: =IF(OR(B8="",D8="",'Datos del viaje'!$B$11=""),"",'Datos del viaje'!$B$11-D8) | G8: =IF(I8=0,"",IF(F8="Hecho","Hecho",IF(E8="","",IF(E8<'Datos del viaje'!$B$18,"Atrasada",IF(E8-'Datos del viaje'!$B$18<='Datos del viaje'!$B$15,"Pronto","Al día"))))) | I8: =IF(B8="",0,IFERROR(INDEX('Datos del viaje'!$E$5:$E$16,MATCH(C8,'Datos del viaje'!$D$5:$D$16,0)),0)) | J8: =IF(OR(I8=0,F8="Hecho",E8=""),"",E8+ROW()/100000)
A9: =IF(D9="","",IF(D9>=180,"6 meses o más antes",IF(D9>=90,"3 a 6 meses antes",IF(D9>=30,"1 a 3 meses antes",IF(D9>=14,"2 a 4 semanas antes",IF(D9>=7,"1 a 2 semanas antes",IF(D9>=2,"Últimos días",IF(D9>=1,"Día anterior",IF(D9>=0,"Día de salida","Después del viaje"))))))))) | B9: Pedí los días en el trabajo o el colegio | C9: Siempre | D9: 150 | E9: =IF(OR(B9="",D9="",'Datos del viaje'!$B$11=""),"",'Datos del viaje'!$B$11-D9) | G9: =IF(I9=0,"",IF(F9="Hecho","Hecho",IF(E9="","",IF(E9<'Datos del viaje'!$B$18,"Atrasada",IF(E9-'Datos del viaje'!$B$18<='Datos del viaje'!$B$15,"Pronto","Al día"))))) | I9: =IF(B9="",0,IFERROR(INDEX('Datos del viaje'!$E$5:$E$16,MATCH(C9,'Datos del viaje'!$D$5:$D$16,0)),0)) | J9: =IF(OR(I9=0,F9="Hecho",E9=""),"",E9+ROW()/100000)
A10: =IF(D10="","",IF(D10>=180,"6 meses o más antes",IF(D10>=90,"3 a 6 meses antes",IF(D10>=30,"1 a 3 meses antes",IF(D10>=14,"2 a 4 semanas antes",IF(D10>=7,"1 a 2 semanas antes",IF(D10>=2,"Últimos días",IF(D10>=1,"Día anterior",IF(D10>=0,"Día de salida","Después del viaje"))))))))) | B10: Definí el presupuesto total del viaje (usá el Planificador de Presupuesto si lo tenés) | C10: Siempre | D10: 150 | E10: =IF(OR(B10="",D10="",'Datos del viaje'!$B$11=""),"",'Datos del viaje'!$B$11-D10) | G10: =IF(I10=0,"",IF(F10="Hecho","Hecho",IF(E10="","",IF(E10<'Datos del viaje'!$B$18,"Atrasada",IF(E10-'Datos del viaje'!$B$18<='Datos del viaje'!$B$15,"Pronto","Al día"))))) | I10: =IF(B10="",0,IFERROR(INDEX('Datos del viaje'!$E$5:$E$16,MATCH(C10,'Datos del viaje'!$D$5:$D$16,0)),0)) | J10: =IF(OR(I10=0,F10="Hecho",E10=""),"",E10+ROW()/100000)
A11: =IF(D11="","",IF(D11>=180,"6 meses o más antes",IF(D11>=90,"3 a 6 meses antes",IF(D11>=30,"1 a 3 meses antes",IF(D11>=14,"2 a 4 semanas antes",IF(D11>=7,"1 a 2 semanas antes",IF(D11>=2,"Últimos días",IF(D11>=1,"Día anterior",IF(D11>=0,"Día de salida","Después del viaje"))))))))) | B11: Iniciá el trámite de visa o permiso de ingreso por el canal oficial | C11: Con visa | D11: 120 | E11: =IF(OR(B11="",D11="",'Datos del viaje'!$B$11=""),"",'Datos del viaje'!$B$11-D11) | G11: =IF(I11=0,"",IF(F11="Hecho","Hecho",IF(E11="","",IF(E11<'Datos del viaje'!$B$18,"Atrasada",IF(E11-'Datos del viaje'!$B$18<='Datos del viaje'!$B$15,"Pronto","Al día"))))) | I11: =IF(B11="",0,IFERROR(INDEX('Datos del viaje'!$E$5:$E$16,MATCH(C11,'Datos del viaje'!$D$5:$D$16,0)),0)) | J11: =IF(OR(I11=0,F11="Hecho",E11=""),"",E11+ROW()/100000)
A12: =IF(D12="","",IF(D12>=180,"6 meses o más antes",IF(D12>=90,"3 a 6 meses antes",IF(D12>=30,"1 a 3 meses antes",IF(D12>=14,"2 a 4 semanas antes",IF(D12>=7,"1 a 2 semanas antes",IF(D12>=2,"Últimos días",IF(D12>=1,"Día anterior",IF(D12>=0,"Día de salida","Después del viaje"))))))))) | B12: Averiguá en fuentes oficiales qué documentos necesita un menor (autorización, adulto acompañante) | C12: Con chicos | D12: 120 | E12: =IF(OR(B12="",D12="",'Datos del viaje'!$B$11=""),"",'Datos del viaje'!$B$11-D12) | G12: =IF(I12=0,"",IF(F12="Hecho","Hecho",IF(E12="","",IF(E12<'Datos del viaje'!$B$18,"Atrasada",IF(E12-'Datos del viaje'!$B$18<='Datos del viaje'!$B$15,"Pronto","Al día"))))) | I12: =IF(B12="",0,IFERROR(INDEX('Datos del viaje'!$E$5:$E$16,MATCH(C12,'Datos del viaje'!$D$5:$D$16,0)),0)) | J12: =IF(OR(I12=0,F12="Hecho",E12=""),"",E12+ROW()/100000)
A13: =IF(D13="","",IF(D13>=180,"6 meses o más antes",IF(D13>=90,"3 a 6 meses antes",IF(D13>=30,"1 a 3 meses antes",IF(D13>=14,"2 a 4 semanas antes",IF(D13>=7,"1 a 2 semanas antes",IF(D13>=2,"Últimos días",IF(D13>=1,"Día anterior",IF(D13>=0,"Día de salida","Después del viaje"))))))))) | B13: Averiguá las reglas para viajar con mascotas en la autoridad sanitaria animal oficial y en la empresa de transporte (en Argentina, SENASA) | C13: Mascotas | D13: 120 | E13: =IF(OR(B13="",D13="",'Datos del viaje'!$B$11=""),"",'Datos del viaje'!$B$11-D13) | G13: =IF(I13=0,"",IF(F13="Hecho","Hecho",IF(E13="","",IF(E13<'Datos del viaje'!$B$18,"Atrasada",IF(E13-'Datos del viaje'!$B$18<='Datos del viaje'!$B$15,"Pronto","Al día"))))) | I13: =IF(B13="",0,IFERROR(INDEX('Datos del viaje'!$E$5:$E$16,MATCH(C13,'Datos del viaje'!$D$5:$D$16,0)),0)) | J13: =IF(OR(I13=0,F13="Hecho",E13=""),"",E13+ROW()/100000)
A14: =IF(D14="","",IF(D14>=180,"6 meses o más antes",IF(D14>=90,"3 a 6 meses antes",IF(D14>=30,"1 a 3 meses antes",IF(D14>=14,"2 a 4 semanas antes",IF(D14>=7,"1 a 2 semanas antes",IF(D14>=2,"Últimos días",IF(D14>=1,"Día anterior",IF(D14>=0,"Día de salida","Después del viaje"))))))))) | B14: Reservá los vuelos: compará precios y leé las reglas de equipaje | C14: Avión | D14: 90 | E14: =IF(OR(B14="",D14="",'Datos del viaje'!$B$11=""),"",'Datos del viaje'!$B$11-D14) | G14: =IF(I14=0,"",IF(F14="Hecho","Hecho",IF(E14="","",IF(E14<'Datos del viaje'!$B$18,"Atrasada",IF(E14-'Datos del viaje'!$B$18<='Datos del viaje'!$B$15,"Pronto","Al día"))))) | I14: =IF(B14="",0,IFERROR(INDEX('Datos del viaje'!$E$5:$E$16,MATCH(C14,'Datos del viaje'!$D$5:$D$16,0)),0)) | J14: =IF(OR(I14=0,F14="Hecho",E14=""),"",E14+ROW()/100000)
A15: =IF(D15="","",IF(D15>=180,"6 meses o más antes",IF(D15>=90,"3 a 6 meses antes",IF(D15>=30,"1 a 3 meses antes",IF(D15>=14,"2 a 4 semanas antes",IF(D15>=7,"1 a 2 semanas antes",IF(D15>=2,"Últimos días",IF(D15>=1,"Día anterior",IF(D15>=0,"Día de salida","Después del viaje"))))))))) | B15: Reservá el alojamiento (revisá la política de cancelación) | C15: Siempre | D15: 75 | E15: =IF(OR(B15="",D15="",'Datos del viaje'!$B$11=""),"",'Datos del viaje'!$B$11-D15) | G15: =IF(I15=0,"",IF(F15="Hecho","Hecho",IF(E15="","",IF(E15<'Datos del viaje'!$B$18,"Atrasada",IF(E15-'Datos del viaje'!$B$18<='Datos del viaje'!$B$15,"Pronto","Al día"))))) | I15: =IF(B15="",0,IFERROR(INDEX('Datos del viaje'!$E$5:$E$16,MATCH(C15,'Datos del viaje'!$D$5:$D$16,0)),0)) | J15: =IF(OR(I15=0,F15="Hecho",E15=""),"",E15+ROW()/100000)
A16: =IF(D16="","",IF(D16>=180,"6 meses o más antes",IF(D16>=90,"3 a 6 meses antes",IF(D16>=30,"1 a 3 meses antes",IF(D16>=14,"2 a 4 semanas antes",IF(D16>=7,"1 a 2 semanas antes",IF(D16>=2,"Últimos días",IF(D16>=1,"Día anterior",IF(D16>=0,"Día de salida","Después del viaje"))))))))) | B16: Reservá alojamiento que acepte mascotas y confirmalo por escrito | C16: Mascotas | D16: 75 | E16: =IF(OR(B16="",D16="",'Datos del viaje'!$B$11=""),"",'Datos del viaje'!$B$11-D16) | G16: =IF(I16=0,"",IF(F16="Hecho","Hecho",IF(E16="","",IF(E16<'Datos del viaje'!$B$18,"Atrasada",IF(E16-'Datos del viaje'!$B$18<='Datos del viaje'!$B$15,"Pronto","Al día"))))) | I16: =IF(B16="",0,IFERROR(INDEX('Datos del viaje'!$E$5:$E$16,MATCH(C16,'Datos del viaje'!$D$5:$D$16,0)),0)) | J16: =IF(OR(I16=0,F16="Hecho",E16=""),"",E16+ROW()/100000)
... A68: =IF(D68="","",IF(D68>=180,"6 meses o más antes",IF(D68>=90,"3 a 6 meses antes",IF(D68>=30,"1 a 3 meses antes",IF(D68>=14,"2 a 4 semanas antes",IF(D68>=7,"1 a 2 semanas antes",IF(D68>=2,"Últimos días",IF(D68>=1,"Día anterior",IF(D68>=0,"Día de salida","Después del viaje"))))))))) | B68: Presentá el reclamo al seguro, si corresponde, con tus comprobantes | C68: Exterior | D68: -7 | E68: =IF(OR(B68="",D68="",'Datos del viaje'!$B$11=""),"",'Datos del viaje'!$B$11-D68) | G68: =IF(I68=0,"",IF(F68="Hecho","Hecho",IF(E68="","",IF(E68<'Datos del viaje'!$B$18,"Atrasada",IF(E68-'Datos del viaje'!$B$18<='Datos del viaje'!$B$15,"Pronto","Al día"))))) | I68: =IF(B68="",0,IFERROR(INDEX('Datos del viaje'!$E$5:$E$16,MATCH(C68,'Datos del viaje'!$D$5:$D$16,0)),0)) | J68: =IF(OR(I68=0,F68="Hecho",E68=""),"",E68+ROW()/100000)
A69: =IF(D69="","",IF(D69>=180,"6 meses o más antes",IF(D69>=90,"3 a 6 meses antes",IF(D69>=30,"1 a 3 meses antes",IF(D69>=14,"2 a 4 semanas antes",IF(D69>=7,"1 a 2 semanas antes",IF(D69>=2,"Últimos días",IF(D69>=1,"Día anterior",IF(D69>=0,"Día de salida","Después del viaje"))))))))) | E69: =IF(OR(B69="",D69="",'Datos del viaje'!$B$11=""),"",'Datos del viaje'!$B$11-D69) | G69: =IF(I69=0,"",IF(F69="Hecho","Hecho",IF(E69="","",IF(E69<'Datos del viaje'!$B$18,"Atrasada",IF(E69-'Datos del viaje'!$B$18<='Datos del viaje'!$B$15,"Pronto","Al día"))))) | I69: =IF(B69="",0,IFERROR(INDEX('Datos del viaje'!$E$5:$E$16,MATCH(C69,'Datos del viaje'!$D$5:$D$16,0)),0)) | J69: =IF(OR(I69=0,F69="Hecho",E69=""),"",E69+ROW()/100000)
A70: =IF(D70="","",IF(D70>=180,"6 meses o más antes",IF(D70>=90,"3 a 6 meses antes",IF(D70>=30,"1 a 3 meses antes",IF(D70>=14,"2 a 4 semanas antes",IF(D70>=7,"1 a 2 semanas antes",IF(D70>=2,"Últimos días",IF(D70>=1,"Día anterior",IF(D70>=0,"Día de salida","Después del viaje"))))))))) | E70: =IF(OR(B70="",D70="",'Datos del viaje'!$B$11=""),"",'Datos del viaje'!$B$11-D70) | G70: =IF(I70=0,"",IF(F70="Hecho","Hecho",IF(E70="","",IF(E70<'Datos del viaje'!$B$18,"Atrasada",IF(E70-'Datos del viaje'!$B$18<='Datos del viaje'!$B$15,"Pronto","Al día"))))) | I70: =IF(B70="",0,IFERROR(INDEX('Datos del viaje'!$E$5:$E$16,MATCH(C70,'Datos del viaje'!$D$5:$D$16,0)),0)) | J70: =IF(OR(I70=0,F70="Hecho",E70=""),"",E70+ROW()/100000)
A71: =IF(D71="","",IF(D71>=180,"6 meses o más antes",IF(D71>=90,"3 a 6 meses antes",IF(D71>=30,"1 a 3 meses antes",IF(D71>=14,"2 a 4 semanas antes",IF(D71>=7,"1 a 2 semanas antes",IF(D71>=2,"Últimos días",IF(D71>=1,"Día anterior",IF(D71>=0,"Día de salida","Después del viaje"))))))))) | E71: =IF(OR(B71="",D71="",'Datos del viaje'!$B$11=""),"",'Datos del viaje'!$B$11-D71) | G71: =IF(I71=0,"",IF(F71="Hecho","Hecho",IF(E71="","",IF(E71<'Datos del viaje'!$B$18,"Atrasada",IF(E71-'Datos del viaje'!$B$18<='Datos del viaje'!$B$15,"Pronto","Al día"))))) | I71: =IF(B71="",0,IFERROR(INDEX('Datos del viaje'!$E$5:$E$16,MATCH(C71,'Datos del viaje'!$D$5:$D$16,0)),0)) | J71: =IF(OR(I71=0,F71="Hecho",E71=""),"",E71+ROW()/100000)
A72: =IF(D72="","",IF(D72>=180,"6 meses o más antes",IF(D72>=90,"3 a 6 meses antes",IF(D72>=30,"1 a 3 meses antes",IF(D72>=14,"2 a 4 semanas antes",IF(D72>=7,"1 a 2 semanas antes",IF(D72>=2,"Últimos días",IF(D72>=1,"Día anterior",IF(D72>=0,"Día de salida","Después del viaje"))))))))) | E72: =IF(OR(B72="",D72="",'Datos del viaje'!$B$11=""),"",'Datos del viaje'!$B$11-D72) | G72: =IF(I72=0,"",IF(F72="Hecho","Hecho",IF(E72="","",IF(E72<'Datos del viaje'!$B$18,"Atrasada",IF(E72-'Datos del viaje'!$B$18<='Datos del viaje'!$B$15,"Pronto","Al día"))))) | I72: =IF(B72="",0,IFERROR(INDEX('Datos del viaje'!$E$5:$E$16,MATCH(C72,'Datos del viaje'!$D$5:$D$16,0)),0)) | J72: =IF(OR(I72=0,F72="Hecho",E72=""),"",E72+ROW()/100000)
A73: =IF(D73="","",IF(D73>=180,"6 meses o más antes",IF(D73>=90,"3 a 6 meses antes",IF(D73>=30,"1 a 3 meses antes",IF(D73>=14,"2 a 4 semanas antes",IF(D73>=7,"1 a 2 semanas antes",IF(D73>=2,"Últimos días",IF(D73>=1,"Día anterior",IF(D73>=0,"Día de salida","Después del viaje"))))))))) | E73: =IF(OR(B73="",D73="",'Datos del viaje'!$B$11=""),"",'Datos del viaje'!$B$11-D73) | G73: =IF(I73=0,"",IF(F73="Hecho","Hecho",IF(E73="","",IF(E73<'Datos del viaje'!$B$18,"Atrasada",IF(E73-'Datos del viaje'!$B$18<='Datos del viaje'!$B$15,"Pronto","Al día"))))) | I73: =IF(B73="",0,IFERROR(INDEX('Datos del viaje'!$E$5:$E$16,MATCH(C73,'Datos del viaje'!$D$5:$D$16,0)),0)) | J73: =IF(OR(I73=0,F73="Hecho",E73=""),"",E73+ROW()/100000)
A74: =IF(D74="","",IF(D74>=180,"6 meses o más antes",IF(D74>=90,"3 a 6 meses antes",IF(D74>=30,"1 a 3 meses antes",IF(D74>=14,"2 a 4 semanas antes",IF(D74>=7,"1 a 2 semanas antes",IF(D74>=2,"Últimos días",IF(D74>=1,"Día anterior",IF(D74>=0,"Día de salida","Después del viaje"))))))))) | E74: =IF(OR(B74="",D74="",'Datos del viaje'!$B$11=""),"",'Datos del viaje'!$B$11-D74) | G74: =IF(I74=0,"",IF(F74="Hecho","Hecho",IF(E74="","",IF(E74<'Datos del viaje'!$B$18,"Atrasada",IF(E74-'Datos del viaje'!$B$18<='Datos del viaje'!$B$15,"Pronto","Al día"))))) | I74: =IF(B74="",0,IFERROR(INDEX('Datos del viaje'!$E$5:$E$16,MATCH(C74,'Datos del viaje'!$D$5:$D$16,0)),0)) | J74: =IF(OR(I74=0,F74="Hecho",E74=""),"",E74+ROW()/100000)
A75: =IF(D75="","",IF(D75>=180,"6 meses o más antes",IF(D75>=90,"3 a 6 meses antes",IF(D75>=30,"1 a 3 meses antes",IF(D75>=14,"2 a 4 semanas antes",IF(D75>=7,"1 a 2 semanas antes",IF(D75>=2,"Últimos días",IF(D75>=1,"Día anterior",IF(D75>=0,"Día de salida","Después del viaje"))))))))) | E75: =IF(OR(B75="",D75="",'Datos del viaje'!$B$11=""),"",'Datos del viaje'!$B$11-D75) | G75: =IF(I75=0,"",IF(F75="Hecho","Hecho",IF(E75="","",IF(E75<'Datos del viaje'!$B$18,"Atrasada",IF(E75-'Datos del viaje'!$B$18<='Datos del viaje'!$B$15,"Pronto","Al día"))))) | I75: =IF(B75="",0,IFERROR(INDEX('Datos del viaje'!$E$5:$E$16,MATCH(C75,'Datos del viaje'!$D$5:$D$16,0)),0)) | J75: =IF(OR(I75=0,F75="Hecho",E75=""),"",E75+ROW()/100000)
A76: =IF(D76="","",IF(D76>=180,"6 meses o más antes",IF(D76>=90,"3 a 6 meses antes",IF(D76>=30,"1 a 3 meses antes",IF(D76>=14,"2 a 4 semanas antes",IF(D76>=7,"1 a 2 semanas antes",IF(D76>=2,"Últimos días",IF(D76>=1,"Día anterior",IF(D76>=0,"Día de salida","Después del viaje"))))))))) | E76: =IF(OR(B76="",D76="",'Datos del viaje'!$B$11=""),"",'Datos del viaje'!$B$11-D76) | G76: =IF(I76=0,"",IF(F76="Hecho","Hecho",IF(E76="","",IF(E76<'Datos del viaje'!$B$18,"Atrasada",IF(E76-'Datos del viaje'!$B$18<='Datos del viaje'!$B$15,"Pronto","Al día"))))) | I76: =IF(B76="",0,IFERROR(INDEX('Datos del viaje'!$E$5:$E$16,MATCH(C76,'Datos del viaje'!$D$5:$D$16,0)),0)) | J76: =IF(OR(I76=0,F76="Hecho",E76=""),"",E76+ROW()/100000)
A77: =IF(D77="","",IF(D77>=180,"6 meses o más antes",IF(D77>=90,"3 a 6 meses antes",IF(D77>=30,"1 a 3 meses antes",IF(D77>=14,"2 a 4 semanas antes",IF(D77>=7,"1 a 2 semanas antes",IF(D77>=2,"Últimos días",IF(D77>=1,"Día anterior",IF(D77>=0,"Día de salida","Después del viaje"))))))))) | E77: =IF(OR(B77="",D77="",'Datos del viaje'!$B$11=""),"",'Datos del viaje'!$B$11-D77) | G77: =IF(I77=0,"",IF(F77="Hecho","Hecho",IF(E77="","",IF(E77<'Datos del viaje'!$B$18,"Atrasada",IF(E77-'Datos del viaje'!$B$18<='Datos del viaje'!$B$15,"Pronto","Al día"))))) | I77: =IF(B77="",0,IFERROR(INDEX('Datos del viaje'!$E$5:$E$16,MATCH(C77,'Datos del viaje'!$D$5:$D$16,0)),0)) | J77: =IF(OR(I77=0,F77="Hecho",E77=""),"",E77+ROW()/100000)
A78: =IF(D78="","",IF(D78>=180,"6 meses o más antes",IF(D78>=90,"3 a 6 meses antes",IF(D78>=30,"1 a 3 meses antes",IF(D78>=14,"2 a 4 semanas antes",IF(D78>=7,"1 a 2 semanas antes",IF(D78>=2,"Últimos días",IF(D78>=1,"Día anterior",IF(D78>=0,"Día de salida","Después del viaje"))))))))) | E78: =IF(OR(B78="",D78="",'Datos del viaje'!$B$11=""),"",'Datos del viaje'!$B$11-D78) | G78: =IF(I78=0,"",IF(F78="Hecho","Hecho",IF(E78="","",IF(E78<'Datos del viaje'!$B$18,"Atrasada",IF(E78-'Datos del viaje'!$B$18<='Datos del viaje'!$B$15,"Pronto","Al día"))))) | I78: =IF(B78="",0,IFERROR(INDEX('Datos del viaje'!$E$5:$E$16,MATCH(C78,'Datos del viaje'!$D$5:$D$16,0)),0)) | J78: =IF(OR(I78=0,F78="Hecho",E78=""),"",E78+ROW()/100000)
A79: =IF(D79="","",IF(D79>=180,"6 meses o más antes",IF(D79>=90,"3 a 6 meses antes",IF(D79>=30,"1 a 3 meses antes",IF(D79>=14,"2 a 4 semanas antes",IF(D79>=7,"1 a 2 semanas antes",IF(D79>=2,"Últimos días",IF(D79>=1,"Día anterior",IF(D79>=0,"Día de salida","Después del viaje"))))))))) | E79: =IF(OR(B79="",D79="",'Datos del viaje'!$B$11=""),"",'Datos del viaje'!$B$11-D79) | G79: =IF(I79=0,"",IF(F79="Hecho","Hecho",IF(E79="","",IF(E79<'Datos del viaje'!$B$18,"Atrasada",IF(E79-'Datos del viaje'!$B$18<='Datos del viaje'!$B$15,"Pronto","Al día"))))) | I79: =IF(B79="",0,IFERROR(INDEX('Datos del viaje'!$E$5:$E$16,MATCH(C79,'Datos del viaje'!$D$5:$D$16,0)),0)) | J79: =IF(OR(I79=0,F79="Hecho",E79=""),"",E79+ROW()/100000)
A80: =IF(D80="","",IF(D80>=180,"6 meses o más antes",IF(D80>=90,"3 a 6 meses antes",IF(D80>=30,"1 a 3 meses antes",IF(D80>=14,"2 a 4 semanas antes",IF(D80>=7,"1 a 2 semanas antes",IF(D80>=2,"Últimos días",IF(D80>=1,"Día anterior",IF(D80>=0,"Día de salida","Después del viaje"))))))))) | E80: =IF(OR(B80="",D80="",'Datos del viaje'!$B$11=""),"",'Datos del viaje'!$B$11-D80) | G80: =IF(I80=0,"",IF(F80="Hecho","Hecho",IF(E80="","",IF(E80<'Datos del viaje'!$B$18,"Atrasada",IF(E80-'Datos del viaje'!$B$18<='Datos del viaje'!$B$15,"Pronto","Al día"))))) | I80: =IF(B80="",0,IFERROR(INDEX('Datos del viaje'!$E$5:$E$16,MATCH(C80,'Datos del viaje'!$D$5:$D$16,0)),0)) | J80: =IF(OR(I80=0,F80="Hecho",E80=""),"",E80+ROW()/100000)

Sheet Equipaje
A1: Equipaje
A2: Las cantidades son para todos los viajeros. Cambiá cualquier cantidad o sumá tus ítems en las filas vacías.
A4: Categoría | B4: Ítem | C4: Aplica cuando | D4: Por | E4: Cant. | F4: Total | H4: ¿Guardado?
A5: Documentos y dinero | B5: Pasaporte | C5: Exterior | D5: Persona | E5: 1 | F5: =IF(G5=1,IF(D5="Persona",E5*'Datos del viaje'!$B$10,E5),"") | G5: =IF(B5="",0,IFERROR(INDEX('Datos del viaje'!$E$5:$E$16,MATCH(C5,'Datos del viaje'!$D$5:$D$16,0)),0)) | I5: =IF(G5=1,SUM(G$5:G5),"")
A6: Documentos y dinero | B6: Documento de identidad o licencia de conducir | C6: Siempre | D6: Persona | E6: 1 | F6: =IF(G6=1,IF(D6="Persona",E6*'Datos del viaje'!$B$10,E6),"") | G6: =IF(B6="",0,IFERROR(INDEX('Datos del viaje'!$E$5:$E$16,MATCH(C6,'Datos del viaje'!$D$5:$D$16,0)),0)) | I6: =IF(G6=1,SUM(G$5:G6),"")
A7: Documentos y dinero | B7: Visa o permiso de ingreso (impreso y en el celular) | C7: Con visa | D7: Persona | E7: 1 | F7: =IF(G7=1,IF(D7="Persona",E7*'Datos del viaje'!$B$10,E7),"") | G7: =IF(B7="",0,IFERROR(INDEX('Datos del viaje'!$E$5:$E$16,MATCH(C7,'Datos del viaje'!$D$5:$D$16,0)),0)) | I7: =IF(G7=1,SUM(G$5:G7),"")
A8: Documentos y dinero | B8: Pasajes, tarjetas de embarque y confirmaciones de reservas | C8: Siempre | D8: Viaje | E8: 1 | F8: =IF(G8=1,IF(D8="Persona",E8*'Datos del viaje'!$B$10,E8),"") | G8: =IF(B8="",0,IFERROR(INDEX('Datos del viaje'!$E$5:$E$16,MATCH(C8,'Datos del viaje'!$D$5:$D$16,0)),0)) | I8: =IF(G8=1,SUM(G$5:G8),"")
A9: Documentos y dinero | B9: Póliza del seguro de viaje y teléfono de emergencias | C9: Exterior | D9: Viaje | E9: 1 | F9: =IF(G9=1,IF(D9="Persona",E9*'Datos del viaje'!$B$10,E9),"") | G9: =IF(B9="",0,IFERROR(INDEX('Datos del viaje'!$E$5:$E$16,MATCH(C9,'Datos del viaje'!$D$5:$D$16,0)),0)) | I9: =IF(G9=1,SUM(G$5:G9),"")
A10: Documentos y dinero | B10: Credencial de cobertura médica | C10: Siempre | D10: Persona | E10: 1 | F10: =IF(G10=1,IF(D10="Persona",E10*'Datos del viaje'!$B$10,E10),"") | G10: =IF(B10="",0,IFERROR(INDEX('Datos del viaje'!$E$5:$E$16,MATCH(C10,'Datos del viaje'!$D$5:$D$16,0)),0)) | I10: =IF(G10=1,SUM(G$5:G10),"")
A11: Documentos y dinero | B11: Tarjetas de pago (llevá dos, guardadas por separado) | C11: Siempre | D11: Viaje | E11: 2 | F11: =IF(G11=1,IF(D11="Persona",E11*'Datos del viaje'!$B$10,E11),"") | G11: =IF(B11="",0,IFERROR(INDEX('Datos del viaje'!$E$5:$E$16,MATCH(C11,'Datos del viaje'!$D$5:$D$16,0)),0)) | I11: =IF(G11=1,SUM(G$5:G11),"")
A12: Documentos y dinero | B12: Algo de efectivo | C12: Siempre | D12: Viaje | E12: 1 | F12: =IF(G12=1,IF(D12="Persona",E12*'Datos del viaje'!$B$10,E12),"") | G12: =IF(B12="",0,IFERROR(INDEX('Datos del viaje'!$E$5:$E$16,MATCH(C12,'Datos del viaje'!$D$5:$D$16,0)),0)) | I12: =IF(G12=1,SUM(G$5:G12),"")
A13: Documentos y dinero | B13: Moneda local | C13: Exterior | D13: Viaje | E13: 1 | F13: =IF(G13=1,IF(D13="Persona",E13*'Datos del viaje'!$B$10,E13),"") | G13: =IF(B13="",0,IFERROR(INDEX('Datos del viaje'!$E$5:$E$16,MATCH(C13,'Datos del viaje'!$D$5:$D$16,0)),0)) | I13: =IF(G13=1,SUM(G$5:G13),"")
A14: Documentos y dinero | B14: Copias de documentos (papel y digitales) | C14: Siempre | D14: Viaje | E14: 1 | F14: =IF(G14=1,IF(D14="Persona",E14*'Datos del viaje'!$B$10,E14),"") | G14: =IF(B14="",0,IFERROR(INDEX('Datos del viaje'!$E$5:$E$16,MATCH(C14,'Datos del viaje'!$D$5:$D$16,0)),0)) | I14: =IF(G14=1,SUM(G$5:G14),"")
A15: Documentos y dinero | B15: Direcciones de los alojamientos | C15: Siempre | D15: Viaje | E15: 1 | F15: =IF(G15=1,IF(D15="Persona",E15*'Datos del viaje'!$B$10,E15),"") | G15: =IF(B15="",0,IFERROR(INDEX('Datos del viaje'!$E$5:$E$16,MATCH(C15,'Datos del viaje'!$D$5:$D$16,0)),0)) | I15: =IF(G15=1,SUM(G$5:G15),"")
A16: Documentos y dinero | B16: Licencia de conducir, documentación y seguro del vehículo | C16: Auto | D16: Viaje | E16: 1 | F16: =IF(G16=1,IF(D16="Persona",E16*'Datos del viaje'!$B$10,E16),"") | G16: =IF(B16="",0,IFERROR(INDEX('Datos del viaje'!$E$5:$E$16,MATCH(C16,'Datos del viaje'!$D$5:$D$16,0)),0)) | I16: =IF(G16=1,SUM(G$5:G16),"")
A17: Ropa | B17: Ropa interior | C17: Siempre | D17: Persona | E17: =MIN('Datos del viaje'!$B$12+1,8) | F17: =IF(G17=1,IF(D17="Persona",E17*'Datos del viaje'!$B$10,E17),"") | G17: =IF(B17="",0,IFERROR(INDEX('Datos del viaje'!$E$5:$E$16,MATCH(C17,'Datos del viaje'!$D$5:$D$16,0)),0)) | I17: =IF(G17=1,SUM(G$5:G17),"")
A18: Ropa | B18: Medias | C18: Siempre | D18: Persona | E18: =MIN('Datos del viaje'!$B$12+1,8) | F18: =IF(G18=1,IF(D18="Persona",E18*'Datos del viaje'!$B$10,E18),"") | G18: =IF(B18="",0,IFERROR(INDEX('Datos del viaje'!$E$5:$E$16,MATCH(C18,'Datos del viaje'!$D$5:$D$16,0)),0)) | I18: =IF(G18=1,SUM(G$5:G18),"")
A19: Ropa | B19: Remeras o tops | C19: Siempre | D19: Persona | E19: =MAX(2,MIN('Datos del viaje'!$B$12,7)) | F19: =IF(G19=1,IF(D19="Persona",E19*'Datos del viaje'!$B$10,E19),"") | G19: =IF(B19="",0,IFERROR(INDEX('Datos del viaje'!$E$5:$E$16,MATCH(C19,'Datos del viaje'!$D$5:$D$16,0)),0)) | I19: =IF(G19=1,SUM(G$5:G19),"")
A20: Ropa | B20: Pantalones, polleras o shorts | C20: Siempre | D20: Persona | E20: =MAX(2,MIN(ROUNDUP('Datos del viaje'!$B$12/3,0),4)) | F20: =IF(G20=1,IF(D20="Persona",E20*'Datos del viaje'!$B$10,E20),"") | G20: =IF(B20="",0,IFERROR(INDEX('Datos del viaje'!$E$5:$E$16,MATCH(C20,'Datos del viaje'!$D$5:$D$16,0)),0)) | I20: =IF(G20=1,SUM(G$5:G20),"")
A21: Ropa | B21: Ropa para dormir | C21: Siempre | D21: Persona | E21: 1 | F21: =IF(G21=1,IF(D21="Persona",E21*'Datos del viaje'!$B$10,E21),"") | G21: =IF(B21="",0,IFERROR(INDEX('Datos del viaje'!$E$5:$E$16,MATCH(C21,'Datos del viaje'!$D$5:$D$16,0)),0)) | I21: =IF(G21=1,SUM(G$5:G21),"")
A22: Ropa | B22: Calzado cómodo para caminar | C22: Siempre | D22: Persona | E22: 1 | F22: =IF(G22=1,IF(D22="Persona",E22*'Datos del viaje'!$B$10,E22),"") | G22: =IF(B22="",0,IFERROR(INDEX('Datos del viaje'!$E$5:$E$16,MATCH(C22,'Datos del viaje'!$D$5:$D$16,0)),0)) | I22: =IF(G22=1,SUM(G$5:G22),"")
A23: Ropa | B23: Campera liviana o buzo | C23: Siempre | D23: Persona | E23: 1 | F23: =IF(G23=1,IF(D23="Persona",E23*'Datos del viaje'!$B$10,E23),"") | G23: =IF(B23="",0,IFERROR(INDEX('Datos del viaje'!$E$5:$E$16,MATCH(C23,'Datos del viaje'!$D$5:$D$16,0)),0)) | I23: =IF(G23=1,SUM(G$5:G23),"")
A24: Ropa | B24: Paraguas compacto o piloto | C24: Siempre | D24: Viaje | E24: 1 | F24: =IF(G24=1,IF(D24="Persona",E24*'Datos del viaje'!$B$10,E24),"") | G24: =IF(B24="",0,IFERROR(INDEX('Datos del viaje'!$E$5:$E$16,MATCH(C24,'Datos del viaje'!$D$5:$D$16,0)),0)) | I24: =IF(G24=1,SUM(G$5:G24),"")
A25: Ropa | B25: Traje de baño | C25: Clima cálido | D25: Persona | E25: 1 | F25: =IF(G25=1,IF(D25="Persona",E25*'Datos del viaje'!$B$10,E25),"") | G25: =IF(B25="",0,IFERROR(INDEX('Datos del viaje'!$E$5:$E$16,MATCH(C25,'Datos del viaje'!$D$5:$D$16,0)),0)) | I25: =IF(G25=1,SUM(G$5:G25),"")
A26: Ropa | B26: Sandalias | C26: Clima cálido | D26: Persona | E26: 1 | F26: =IF(G26=1,IF(D26="Persona",E26*'Datos del viaje'!$B$10,E26),"") | G26: =IF(B26="",0,IFERROR(INDEX('Datos del viaje'!$E$5:$E$16,MATCH(C26,'Datos del viaje'!$D$5:$D$16,0)),0)) | I26: =IF(G26=1,SUM(G$5:G26),"")
A27: Ropa | B27: Gorra o sombrero y lentes de sol | C27: Clima cálido | D27: Persona | E27: 1 | F27: =IF(G27=1,IF(D27="Persona",E27*'Datos del viaje'!$B$10,E27),"") | G27: =IF(B27="",0,IFERROR(INDEX('Datos del viaje'!$E$5:$E$16,MATCH(C27,'Datos del viaje'!$D$5:$D$16,0)),0)) | I27: =IF(G27=1,SUM(G$5:G27),"")
A28: Ropa | B28: Abrigo | C28: Clima frío | D28: Persona | E28: 1 | F28: =IF(G28=1,IF(D28="Persona",E28*'Datos del viaje'!$B$10,E28),"") | G28: =IF(B28="",0,IFERROR(INDEX('Datos del viaje'!$E$5:$E$16,MATCH(C28,'Datos del viaje'!$D$5:$D$16,0)),0)) | I28: =IF(G28=1,SUM(G$5:G28),"")
A29: Ropa | B29: Capas térmicas | C29: Clima frío | D29: Persona | E29: 2 | F29: =IF(G29=1,IF(D29="Persona",E29*'Datos del viaje'!$B$10,E29),"") | G29: =IF(B29="",0,IFERROR(INDEX('Datos del viaje'!$E$5:$E$16,MATCH(C29,'Datos del viaje'!$D$5:$D$16,0)),0)) | I29: =IF(G29=1,SUM(G$5:G29),"")
A30: Ropa | B30: Guantes, bufanda y gorro | C30: Clima frío | D30: Persona | E30: 1 | F30: =IF(G30=1,IF(D30="Persona",E30*'Datos del viaje'!$B$10,E30),"") | G30: =IF(B30="",0,IFERROR(INDEX('Datos del viaje'!$E$5:$E$16,MATCH(C30,'Datos del viaje'!$D$5:$D$16,0)),0)) | I30: =IF(G30=1,SUM(G$5:G30),"")
A31: Ropa | B31: Botas abrigadas | C31: Clima frío | D31: Persona | E31: 1 | F31: =IF(G31=1,IF(D31="Persona",E31*'Datos del viaje'!$B$10,E31),"") | G31: =IF(B31="",0,IFERROR(INDEX('Datos del viaje'!$E$5:$E$16,MATCH(C31,'Datos del viaje'!$D$5:$D$16,0)),0)) | I31: =IF(G31=1,SUM(G$5:G31),"")
A32: Ropa | B32: Bolsa para ropa sucia | C32: Viaje largo (8+ días) | D32: Viaje | E32: 1 | F32: =IF(G32=1,IF(D32="Persona",E32*'Datos del viaje'!$B$10,E32),"") | G32: =IF(B32="",0,IFERROR(INDEX('Datos del viaje'!$E$5:$E$16,MATCH(C32,'Datos del viaje'!$D$5:$D$16,0)),0)) | I32: =IF(G32=1,SUM(G$5:G32),"")
... A73: Extras | B73: Lapicera y libreta chica | C73: Siempre | D73: Viaje | E73: 1 | F73: =IF(G73=1,IF(D73="Persona",E73*'Datos del viaje'!$B$10,E73),"") | G73: =IF(B73="",0,IFERROR(INDEX('Datos del viaje'!$E$5:$E$16,MATCH(C73,'Datos del viaje'!$D$5:$D$16,0)),0)) | I73: =IF(G73=1,SUM(G$5:G73),"")
F74: =IF(G74=1,IF(D74="Persona",E74*'Datos del viaje'!$B$10,E74),"") | G74: =IF(B74="",0,IFERROR(INDEX('Datos del viaje'!$E$5:$E$16,MATCH(C74,'Datos del viaje'!$D$5:$D$16,0)),0)) | I74: =IF(G74=1,SUM(G$5:G74),"")
F75: =IF(G75=1,IF(D75="Persona",E75*'Datos del viaje'!$B$10,E75),"") | G75: =IF(B75="",0,IFERROR(INDEX('Datos del viaje'!$E$5:$E$16,MATCH(C75,'Datos del viaje'!$D$5:$D$16,0)),0)) | I75: =IF(G75=1,SUM(G$5:G75),"")
F76: =IF(G76=1,IF(D76="Persona",E76*'Datos del viaje'!$B$10,E76),"") | G76: =IF(B76="",0,IFERROR(INDEX('Datos del viaje'!$E$5:$E$16,MATCH(C76,'Datos del viaje'!$D$5:$D$16,0)),0)) | I76: =IF(G76=1,SUM(G$5:G76),"")
F77: =IF(G77=1,IF(D77="Persona",E77*'Datos del viaje'!$B$10,E77),"") | G77: =IF(B77="",0,IFERROR(INDEX('Datos del viaje'!$E$5:$E$16,MATCH(C77,'Datos del viaje'!$D$5:$D$16,0)),0)) | I77: =IF(G77=1,SUM(G$5:G77),"")
F78: =IF(G78=1,IF(D78="Persona",E78*'Datos del viaje'!$B$10,E78),"") | G78: =IF(B78="",0,IFERROR(INDEX('Datos del viaje'!$E$5:$E$16,MATCH(C78,'Datos del viaje'!$D$5:$D$16,0)),0)) | I78: =IF(G78=1,SUM(G$5:G78),"")
F79: =IF(G79=1,IF(D79="Persona",E79*'Datos del viaje'!$B$10,E79),"") | G79: =IF(B79="",0,IFERROR(INDEX('Datos del viaje'!$E$5:$E$16,MATCH(C79,'Datos del viaje'!$D$5:$D$16,0)),0)) | I79: =IF(G79=1,SUM(G$5:G79),"")
F80: =IF(G80=1,IF(D80="Persona",E80*'Datos del viaje'!$B$10,E80),"") | G80: =IF(B80="",0,IFERROR(INDEX('Datos del viaje'!$E$5:$E$16,MATCH(C80,'Datos del viaje'!$D$5:$D$16,0)),0)) | I80: =IF(G80=1,SUM(G$5:G80),"")
F81: =IF(G81=1,IF(D81="Persona",E81*'Datos del viaje'!$B$10,E81),"") | G81: =IF(B81="",0,IFERROR(INDEX('Datos del viaje'!$E$5:$E$16,MATCH(C81,'Datos del viaje'!$D$5:$D$16,0)),0)) | I81: =IF(G81=1,SUM(G$5:G81),"")
...

Sheet Lista para imprimir
A1: ='Datos del viaje'!$B$5&" · lista de equipaje"
A2: Solo los ítems que aplican a este viaje. Imprimí esta hoja.
B4: Categoría | C4: Ítem | D4: Cant.
A5: =IF(E5="","","☐") | B5: =IF(E5="","",INDEX('Equipaje'!$A$5:$A$85,E5)) | C5: =IF(E5="","",INDEX('Equipaje'!$B$5:$B$85,E5)) | D5: =IF(E5="","",INDEX('Equipaje'!$F$5:$F$85,E5)) | E5: =IFERROR(MATCH(1,'Equipaje'!$I$5:$I$85,0),"")
A6: =IF(E6="","","☐") | B6: =IF(E6="","",INDEX('Equipaje'!$A$5:$A$85,E6)) | C6: =IF(E6="","",INDEX('Equipaje'!$B$5:$B$85,E6)) | D6: =IF(E6="","",INDEX('Equipaje'!$F$5:$F$85,E6)) | E6: =IFERROR(MATCH(2,'Equipaje'!$I$5:$I$85,0),"")
A7: =IF(E7="","","☐") | B7: =IF(E7="","",INDEX('Equipaje'!$A$5:$A$85,E7)) | C7: =IF(E7="","",INDEX('Equipaje'!$B$5:$B$85,E7)) | D7: =IF(E7="","",INDEX('Equipaje'!$F$5:$F$85,E7)) | E7: =IFERROR(MATCH(3,'Equipaje'!$I$5:$I$85,0),"")
A8: =IF(E8="","","☐") | B8: =IF(E8="","",INDEX('Equipaje'!$A$5:$A$85,E8)) | C8: =IF(E8="","",INDEX('Equipaje'!$B$5:$B$85,E8)) | D8: =IF(E8="","",INDEX('Equipaje'!$F$5:$F$85,E8)) | E8: =IFERROR(MATCH(4,'Equipaje'!$I$5:$I$85,0),"")
A9: =IF(E9="","","☐") | B9: =IF(E9="","",INDEX('Equipaje'!$A$5:$A$85,E9)) | C9: =IF(E9="","",INDEX('Equipaje'!$B$5:$B$85,E9)) | D9: =IF(E9="","",INDEX('Equipaje'!$F$5:$F$85,E9)) | E9: =IFERROR(MATCH(5,'Equipaje'!$I$5:$I$85,0),"")
A10: =IF(E10="","","☐") | B10: =IF(E10="","",INDEX('Equipaje'!$A$5:$A$85,E10)) | C10: =IF(E10="","",INDEX('Equipaje'!$B$5:$B$85,E10)) | D10: =IF(E10="","",INDEX('Equipaje'!$F$5:$F$85,E10)) | E10: =IFERROR(MATCH(6,'Equipaje'!$I$5:$I$85,0),"")
A11: =IF(E11="","","☐") | B11: =IF(E11="","",INDEX('Equipaje'!$A$5:$A$85,E11)) | C11: =IF(E11="","",INDEX('Equipaje'!$B$5:$B$85,E11)) | D11: =IF(E11="","",INDEX('Equipaje'!$F$5:$F$85,E11)) | E11: =IFERROR(MATCH(7,'Equipaje'!$I$5:$I$85,0),"")
A12: =IF(E12="","","☐") | B12: =IF(E12="","",INDEX('Equipaje'!$A$5:$A$85,E12)) | C12: =IF(E12="","",INDEX('Equipaje'!$B$5:$B$85,E12)) | D12: =IF(E12="","",INDEX('Equipaje'!$F$5:$F$85,E12)) | E12: =IFERROR(MATCH(8,'Equipaje'!$I$5:$I$85,0),"")
A13: =IF(E13="","","☐") | B13: =IF(E13="","",INDEX('Equipaje'!$A$5:$A$85,E13)) | C13: =IF(E13="","",INDEX('Equipaje'!$B$5:$B$85,E13)) | D13: =IF(E13="","",INDEX('Equipaje'!$F$5:$F$85,E13)) | E13: =IFERROR(MATCH(9,'Equipaje'!$I$5:$I$85,0),"")
A14: =IF(E14="","","☐") | B14: =IF(E14="","",INDEX('Equipaje'!$A$5:$A$85,E14)) | C14: =IF(E14="","",INDEX('Equipaje'!$B$5:$B$85,E14)) | D14: =IF(E14="","",INDEX('Equipaje'!$F$5:$F$85,E14)) | E14: =IFERROR(MATCH(10,'Equipaje'!$I$5:$I$85,0),"")
A15: =IF(E15="","","☐") | B15: =IF(E15="","",INDEX('Equipaje'!$A$5:$A$85,E15)) | C15: =IF(E15="","",INDEX('Equipaje'!$B$5:$B$85,E15)) | D15: =IF(E15="","",INDEX('Equipaje'!$F$5:$F$85,E15)) | E15: =IFERROR(MATCH(11,'Equipaje'!$I$5:$I$85,0),"")
A16: =IF(E16="","","☐") | B16: =IF(E16="","",INDEX('Equipaje'!$A$5:$A$85,E16)) | C16: =IF(E16="","",INDEX('Equipaje'!$B$5:$B$85,E16)) | D16: =IF(E16="","",INDEX('Equipaje'!$F$5:$F$85,E16)) | E16: =IFERROR(MATCH(12,'Equipaje'!$I$5:$I$85,0),"")
A17: =IF(E17="","","☐") | B17: =IF(E17="","",INDEX('Equipaje'!$A$5:$A$85,E17)) | C17: =IF(E17="","",INDEX('Equipaje'!$B$5:$B$85,E17)) | D17: =IF(E17="","",INDEX('Equipaje'!$F$5:$F$85,E17)) | E17: =IFERROR(MATCH(13,'Equipaje'!$I$5:$I$85,0),"")
A18: =IF(E18="","","☐") | B18: =IF(E18="","",INDEX('Equipaje'!$A$5:$A$85,E18)) | C18: =IF(E18="","",INDEX('Equipaje'!$B$5:$B$85,E18)) | D18: =IF(E18="","",INDEX('Equipaje'!$F$5:$F$85,E18)) | E18: =IFERROR(MATCH(14,'Equipaje'!$I$5:$I$85,0),"")
A19: =IF(E19="","","☐") | B19: =IF(E19="","",INDEX('Equipaje'!$A$5:$A$85,E19)) | C19: =IF(E19="","",INDEX('Equipaje'!$B$5:$B$85,E19)) | D19: =IF(E19="","",INDEX('Equipaje'!$F$5:$F$85,E19)) | E19: =IFERROR(MATCH(15,'Equipaje'!$I$5:$I$85,0),"")
A20: =IF(E20="","","☐") | B20: =IF(E20="","",INDEX('Equipaje'!$A$5:$A$85,E20)) | C20: =IF(E20="","",INDEX('Equipaje'!$B$5:$B$85,E20)) | D20: =IF(E20="","",INDEX('Equipaje'!$F$5:$F$85,E20)) | E20: =IFERROR(MATCH(16,'Equipaje'!$I$5:$I$85,0),"")
A21: =IF(E21="","","☐") | B21: =IF(E21="","",INDEX('Equipaje'!$A$5:$A$85,E21)) | C21: =IF(E21="","",INDEX('Equipaje'!$B$5:$B$85,E21)) | D21: =IF(E21="","",INDEX('Equipaje'!$F$5:$F$85,E21)) | E21: =IFERROR(MATCH(17,'Equipaje'!$I$5:$I$85,0),"")
A22: =IF(E22="","","☐") | B22: =IF(E22="","",INDEX('Equipaje'!$A$5:$A$85,E22)) | C22: =IF(E22="","",INDEX('Equipaje'!$B$5:$B$85,E22)) | D22: =IF(E22="","",INDEX('Equipaje'!$F$5:$F$85,E22)) | E22: =IFERROR(MATCH(18,'Equipaje'!$I$5:$I$85,0),"")
A23: =IF(E23="","","☐") | B23: =IF(E23="","",INDEX('Equipaje'!$A$5:$A$85,E23)) | C23: =IF(E23="","",INDEX('Equipaje'!$B$5:$B$85,E23)) | D23: =IF(E23="","",INDEX('Equipaje'!$F$5:$F$85,E23)) | E23: =IFERROR(MATCH(19,'Equipaje'!$I$5:$I$85,0),"")
A24: =IF(E24="","","☐") | B24: =IF(E24="","",INDEX('Equipaje'!$A$5:$A$85,E24)) | C24: =IF(E24="","",INDEX('Equipaje'!$B$5:$B$85,E24)) | D24: =IF(E24="","",INDEX('Equipaje'!$F$5:$F$85,E24)) | E24: =IFERROR(MATCH(20,'Equipaje'!$I$5:$I$85,0),"")
A25: =IF(E25="","","☐") | B25: =IF(E25="","",INDEX('Equipaje'!$A$5:$A$85,E25)) | C25: =IF(E25="","",INDEX('Equipaje'!$B$5:$B$85,E25)) | D25: =IF(E25="","",INDEX('Equipaje'!$F$5:$F$85,E25)) | E25: =IFERROR(MATCH(21,'Equipaje'!$I$5:$I$85,0),"")
A26: =IF(E26="","","☐") | B26: =IF(E26="","",INDEX('Equipaje'!$A$5:$A$85,E26)) | C26: =IF(E26="","",INDEX('Equipaje'!$B$5:$B$85,E26)) | D26: =IF(E26="","",INDEX('Equipaje'!$F$5:$F$85,E26)) | E26: =IFERROR(MATCH(22,'Equipaje'!$I$5:$I$85,0),"")
A27: =IF(E27="","","☐") | B27: =IF(E27="","",INDEX('Equipaje'!$A$5:$A$85,E27)) | C27: =IF(E27="","",INDEX('Equipaje'!$B$5:$B$85,E27)) | D27: =IF(E27="","",INDEX('Equipaje'!$F$5:$F$85,E27)) | E27: =IFERROR(MATCH(23,'Equipaje'!$I$5:$I$85,0),"")
A28: =IF(E28="","","☐") | B28: =IF(E28="","",INDEX('Equipaje'!$A$5:$A$85,E28)) | C28: =IF(E28="","",INDEX('Equipaje'!$B$5:$B$85,E28)) | D28: =IF(E28="","",INDEX('Equipaje'!$F$5:$F$85,E28)) | E28: =IFERROR(MATCH(24,'Equipaje'!$I$5:$I$85,0),"")
A29: =IF(E29="","","☐") | B29: =IF(E29="","",INDEX('Equipaje'!$A$5:$A$85,E29)) | C29: =IF(E29="","",INDEX('Equipaje'!$B$5:$B$85,E29)) | D29: =IF(E29="","",INDEX('Equipaje'!$F$5:$F$85,E29)) | E29: =IFERROR(MATCH(25,'Equipaje'!$I$5:$I$85,0),"")
A30: =IF(E30="","","☐") | B30: =IF(E30="","",INDEX('Equipaje'!$A$5:$A$85,E30)) | C30: =IF(E30="","",INDEX('Equipaje'!$B$5:$B$85,E30)) | D30: =IF(E30="","",INDEX('Equipaje'!$F$5:$F$85,E30)) | E30: =IFERROR(MATCH(26,'Equipaje'!$I$5:$I$85,0),"")
A31: =IF(E31="","","☐") | B31: =IF(E31="","",INDEX('Equipaje'!$A$5:$A$85,E31)) | C31: =IF(E31="","",INDEX('Equipaje'!$B$5:$B$85,E31)) | D31: =IF(E31="","",INDEX('Equipaje'!$F$5:$F$85,E31)) | E31: =IFERROR(MATCH(27,'Equipaje'!$I$5:$I$85,0),"")
A32: =IF(E32="","","☐") | B32: =IF(E32="","",INDEX('Equipaje'!$A$5:$A$85,E32)) | C32: =IF(E32="","",INDEX('Equipaje'!$B$5:$B$85,E32)) | D32: =IF(E32="","",INDEX('Equipaje'!$F$5:$F$85,E32)) | E32: =IFERROR(MATCH(28,'Equipaje'!$I$5:$I$85,0),"")
A33: =IF(E33="","","☐") | B33: =IF(E33="","",INDEX('Equipaje'!$A$5:$A$85,E33)) | C33: =IF(E33="","",INDEX('Equipaje'!$B$5:$B$85,E33)) | D33: =IF(E33="","",INDEX('Equipaje'!$F$5:$F$85,E33)) | E33: =IFERROR(MATCH(29,'Equipaje'!$I$5:$I$85,0),"")
A34: =IF(E34="","","☐") | B34: =IF(E34="","",INDEX('Equipaje'!$A$5:$A$85,E34)) | C34: =IF(E34="","",INDEX('Equipaje'!$B$5:$B$85,E34)) | D34: =IF(E34="","",INDEX('Equipaje'!$F$5:$F$85,E34)) | E34: =IFERROR(MATCH(30,'Equipaje'!$I$5:$I$85,0),"")
A35: =IF(E35="","","☐") | B35: =IF(E35="","",INDEX('Equipaje'!$A$5:$A$85,E35)) | C35: =IF(E35="","",INDEX('Equipaje'!$B$5:$B$85,E35)) | D35: =IF(E35="","",INDEX('Equipaje'!$F$5:$F$85,E35)) | E35: =IFERROR(MATCH(31,'Equipaje'!$I$5:$I$85,0),"")
A36: =IF(E36="","","☐") | B36: =IF(E36="","",INDEX('Equipaje'!$A$5:$A$85,E36)) | C36: =IF(E36="","",INDEX('Equipaje'!$B$5:$B$85,E36)) | D36: =IF(E36="","",INDEX('Equipaje'!$F$5:$F$85,E36)) | E36: =IFERROR(MATCH(32,'Equipaje'!$I$5:$I$85,0),"")
A37: =IF(E37="","","☐") | B37: =IF(E37="","",INDEX('Equipaje'!$A$5:$A$85,E37)) | C37: =IF(E37="","",INDEX('Equipaje'!$B$5:$B$85,E37)) | D37: =IF(E37="","",INDEX('Equipaje'!$F$5:$F$85,E37)) | E37: =IFERROR(MATCH(33,'Equipaje'!$I$5:$I$85,0),"")
A38: =IF(E38="","","☐") | B38: =IF(E38="","",INDEX('Equipaje'!$A$5:$A$85,E38)) | C38: =IF(E38="","",INDEX('Equipaje'!$B$5:$B$85,E38)) | D38: =IF(E38="","",INDEX('Equipaje'!$F$5:$F$85,E38)) | E38: =IFERROR(MATCH(34,'Equipaje'!$I$5:$I$85,0),"")
A39: =IF(E39="","","☐") | B39: =IF(E39="","",INDEX('Equipaje'!$A$5:$A$85,E39)) | C39: =IF(E39="","",INDEX('Equipaje'!$B$5:$B$85,E39)) | D39: =IF(E39="","",INDEX('Equipaje'!$F$5:$F$85,E39)) | E39: =IFERROR(MATCH(35,'Equipaje'!$I$5:$I$85,0),"")
A40: =IF(E40="","","☐") | B40: =IF(E40="","",INDEX('Equipaje'!$A$5:$A$85,E40)) | C40: =IF(E40="","",INDEX('Equipaje'!$B$5:$B$85,E40)) | D40: =IF(E40="","",INDEX('Equipaje'!$F$5:$F$85,E40)) | E40: =IFERROR(MATCH(36,'Equipaje'!$I$5:$I$85,0),"")
A41: =IF(E41="","","☐") | B41: =IF(E41="","",INDEX('Equipaje'!$A$5:$A$85,E41)) | C41: =IF(E41="","",INDEX('Equipaje'!$B$5:$B$85,E41)) | D41: =IF(E41="","",INDEX('Equipaje'!$F$5:$F$85,E41)) | E41: =IFERROR(MATCH(37,'Equipaje'!$I$5:$I$85,0),"")
...
